Workbook

Sheet 饼图
D1: 1月
F2: 自动 | I2: 自动 | J2: 自动 | K2: 自动
C3: 项 目 | D3: 2026年 | E3: 占 比 % | F3: 奉贤 | G3: 占 比 % | H3: 2025年 | I3: 占 比 % | J3: 增减额 | K3: 增减率
C4: 人员经费 | D4: 24327 | E4: 0.34595694 | F4: 6393 | G4: 0.36775196 | H4: 21579 | I4: 0.37453138 | J4: 2748 | K4: 0.12734603 | M4: =E4-I4 -> -0.028574442
C5: 药品费 | D5: 16495 | E5: 0.23457721 | F5: 2771 | G5: 0.15939945 | H5: 13387 | I5: 0.23234865 | J5: 3108 | K5: 0.23216553 | M5: =E5-I5 -> 0.0022285533
C6: 耗材费 | D6: 22400 | E6: 0.31855286 | F6: 6605 | G6: 0.37994708 | H6: 16986 | I6: 0.29481394 | J6: 5414 | K6: 0.31873307 | M6: =E6-I6 -> 0.023738919
C7: 折旧/摊销 | D7: 1120 | E7: 0.015927643 | F7: 178 | G7: 0.010239301 | H7: 1078 | I7: 0.018710081 | J7: 42 | K7: 0.038961039 | M7: =E7-I7 -> -0.0027824375
C8: 风险基金 | D8: 103 | E8: 0.0014647743 | F8: 22 | G8: 0.0012655315 | H8: 77 | I8: 0.0013364343 | J8: 26 | K8: 0.33766234 | L8: 自动 | M8: =E9-I9 -> 0.0052610667
C9: 其他费用 | D9: 5873 | E9: 0.083520578 | F9: 1415 | G9: 0.081396687 | H9: 4509 | I9: 0.078259511 | J9: 1364 | K9: 0.3025061
C10: 医疗成本合计 | D10: 70318 | E10: 1 | F10: 17384 | G10: 1 | H10: 57616 | I10: 1 | J10: 12702 | K10: 0.22045959 | L10: 自动 | M10: =E9-I9 -> 0.0052610667
L13: 自动 | P13: 2025年 | R13: 2024年
K14: 人员经费 | L14: =E4 -> 0.34595694 | O14: 医疗风险基金 | P14: 78 | R14: 78
K15: 药品费 | L15: =E5 -> 0.23457721 | O15: 能源费 | P15: 516 | R15: 472
K16: 耗材费 | L16: =E6 -> 0.31855286 | O16: 物业管理费 | R16: 624
K17: 折旧/摊销 | L17: =E7 -> 0.015927643 | O17: 维修护费 | R17: 1353
K18: 其他费用 | L18: =E9 -> 0.083520578 | O18: 劳务费 | R18: 354
O24: 其他 | P24: =P25-P14-P15-P16-P17-P18-P19-P20-P21-P22-P23 -> 3992 | R24: =R25-R14-R15-R16-R17-R18-R19-R20-R21-R22-R23 -> 1243
C25: 2024年 | D25: 2023年 | F25: 增减额 | H25: 增减率 | O25: 总计 | P25: 4586 | R25: 4124
B26: 项 目 | C26: 1-9月 | D26: 1-9月
C27: 498726 | D27: 451737 | F27: =C27-D27 -> 46989 | H27: =C27/D27-1 -> 0.10401849
B28: 医疗成本 | C28: 143587 | D28: 127531 | F28: =C28-D28 -> 16056 | H28: =C28/D28-1 -> 0.1258988
B29: 其中：工资总额 | C29: 3802 | D29: 3829 | F29: =C29-D29 -> -27 | H29: =C29/D29-1 -> -0.0070514495
B30: 其他费用 | C30: =C27+C29 -> 502528 | D30: =D27+D29 -> 455566 | F30: =C30-D30 -> 46962 | H30: =C30/D30-1 -> 0.10308495
B31: 小 计

Sheet 医疗成本
B3: 项 目 | C3: 2026年 | D3: 占 比% | E3: 奉贤院区 | F3: 占 比% | G3: 2025年 | H3: 占 比% | I3: 增减额 | J3: 增减率 | K3: 46082
C4: 4月 | G4: 4月
B5: 人员经费 | C5: =ROUND(当月附表3!B7/10000,0) -> 24327 | D5: =C5/C$11 -> 0.34595694 | E5: =ROUND(当月奉贤附表3!B7/10000,0) -> 6393 | F5: =E5/E$11 -> 0.36775196 | G5: =ROUND(上年同期附表3!B7/10000,0) -> 21579 | H5: =G5/G$11 -> 0.37453138 | I5: =C5-G5 -> 2748 | J5: =I5/G5 -> 0.12734603 | K5: =ROUND(当月附表3!B7/10000,0) -> 24327
B6: 药品费 | C6: =ROUND(当月附表3!B47/10000,0) -> 16495 | D6: =C6/C$11 -> 0.23457721 | E6: =ROUND(当月奉贤附表3!B47/10000,0) -> 2771 | F6: =E6/E$11 -> 0.15939945 | G6: =ROUND(上年同期附表3!B47/10000,0) -> 13387 | H6: =G6/G$11 -> 0.23234865 | I6: =C6-G6 -> 3108 | J6: =I6/G6 -> 0.23216553 | K6: =ROUND(当月附表3!B47/10000,0) -> 16495
B7: 卫生材料费 | C7: =ROUND(当月附表3!B33/10000,0) -> 22400 | D7: =C7/C$11 -> 0.31855286 | E7: =ROUND(当月奉贤附表3!B33/10000,0) -> 6605 | F7: =E7/E$11 -> 0.37994708 | G7: =ROUND(上年同期附表3!B33/10000,0) -> 16986 | H7: =G7/G$11 -> 0.29481394 | I7: =C7-G7 -> 5414 | J7: =I7/G7 -> 0.31873307 | K7: =ROUND(当月附表3!B33/10000,0) -> 22400
B8: 折旧/摊销 | C8: =C11-C10-C7-C6-C5-C9 -> 1120 | D8: =C8/C$11 -> 0.015927643 | E8: =E11-E10-E7-E6-E5-E9 -> 178 | F8: =E8/E$11 -> 0.010239301 | G8: =G11-G10-G7-G6-G5-G9 -> 1078 | H8: =G8/G$11 -> 0.018710081 | I8: =C8-G8 -> 42 | J8: =I8/G8 -> 0.038961039 | K8: =K11-K10-K7-K6-K5-K9 -> 1120
B9: 医疗风险基金 | C9: =ROUND(当月附表3!B53/10000,0) -> 103 | D9: =C9/C$11 -> 0.0014647743 | E9: =ROUND(当月奉贤附表3!B53/10000,0) -> 22 | F9: =E9/E$11 -> 0.0012655315 | G9: =ROUND(上年同期附表3!B53/10000,0) -> 77 | H9: =G9/G$11 -> 0.0013364343 | I9: =C9-G9 -> 26 | J9: =I9/G9 -> 0.33766234 | K9: =ROUND(当月附表3!B53/10000,0) -> 103
B10: 商品和服务费 | C10: =ROUND(当月附表3!B54/10000,0) -> 5873 | D10: =C10/C$11 -> 0.083520578 | E10: =ROUND(当月奉贤附表3!B54/10000,0) -> 1415 | F10: =E10/E$11 -> 0.081396687 | G10: =ROUND(上年同期附表3!B54/10000,0) -> 4509 | H10: =G10/G$11 -> 0.078259511 | I10: =C10-G10 -> 1364 | J10: =I10/G10 -> 0.3025061 | K10: =ROUND(当月附表3!B54/10000,0) -> 5873
B11: 医疗成本合计 | C11: =ROUND(当月附表3!B6/10000,0) -> 70318 | D11: 1 | E11: =ROUND(当月奉贤附表3!B6/10000,0) -> 17384 | F11: 1 | G11: =ROUND(上年同期附表3!B6/10000,0) -> 57616 | H11: 1 | I11: =C11-G11 -> 12702 | J11: =I11/G11 -> 0.22045959 | K11: =ROUND(当月附表3!B6/10000,0) -> 70318

Sheet 人员经费
B3: 项 目 | C3: 46113 | D3: 其中 | E3: 45748 | F3: 增减额 | G3: 增减率
D4: 奉贤院区
B5: 医疗服务收入 | C5: =ROUND((当年累计数据表!AQ3+当年累计数据表!AX3+当年累计数据表!BZ3+当年累计数据表!CG3)/10000,0) -> 31689 | D5: =ROUND((当年累计数据表奉贤!AQ3+当年累计数据表奉贤!AX3+当年累计数据表奉贤!BZ3+当年累计数据表奉贤!CG3)/10000,0) -> 6304 | E5: =ROUND((去年累计数据表!AQ3+去年累计数据表!AX3+去年累计数据表!BZ3+去年累计数据表!CG3)/10000,0) -> 24331 | F5: =C5-E5 -> 7358 | G5: =F5/E5 -> 0.30241256
B6: 人员经费 | C6: =医疗成本!C5 -> 24327 | D6: =医疗成本!E5 -> 6393 | E6: =医疗成本!G5 -> 21579 | F6: =医疗成本!I5 -> 2748 | G6: =医疗成本!J5 -> 0.12734603
B7: 其中：工资总额 | C7: =ROUND((当月附表3!B9+当月附表3!B10+当月附表3!B11+当月附表3!B12+当月附表3!B13+当月附表3!B20)/10000,0) -> 19440 | D7: =ROUND((当月奉贤附表3!B9+当月奉贤附表3!B10+当月奉贤附表3!B11+当月奉贤附表3!B12+当月奉贤附表3!B13+当月奉贤附表3!B20)/10000,0) -> 5701 | E7: =ROUND((上年同期附表3!B9+上年同期附表3!B10+上年同期附表3!B11+上年同期附表3!B12+上年同期附表3!B13+上年同期附表3!B20)/10000,0) -> 17018 | F7: =C7-E7 -> 2422 | G7: =F7/E7 -> 0.1423199
B8: 其中：基本工资等 | C8: =ROUND((当月附表3!B9+当月附表3!B10+当月附表3!B11+当月附表3!B12+当月附表3!B20)/10000,0) -> 3697 | D8: =ROUND((当月奉贤附表3!B9+当月奉贤附表3!B10+当月奉贤附表3!B11+当月奉贤附表3!B12+当月奉贤附表3!B20)/10000,0) -> 520 | E8: =ROUND((上年同期附表3!B9+上年同期附表3!B10+上年同期附表3!B11+上年同期附表3!B12+上年同期附表3!B20)/10000,0) -> 3848 | F8: =C8-E8 -> -151 | G8: =F8/E8 -> -0.039241164
B9: 绩效工资 | C9: =C7-C8 -> 15743 | D9: =D7-D8 -> 5181 | E9: =E7-E8 -> 13170 | F9: =C9-E9 -> 2573 | G9: =F9/E9 -> 0.19536826
B10: 社保公积金 | C10: =ROUND((当月附表3!B14+当月附表3!B15+当月附表3!B16+当月附表3!B17+当月附表3!B18)/10000,0) -> 4601 | D10: =ROUND((当月奉贤附表3!B14+当月奉贤附表3!B15+当月奉贤附表3!B16+当月奉贤附表3!B17+当月奉贤附表3!B18)/10000,0) -> 692 | E10: =ROUND((上年同期附表3!B14+上年同期附表3!B15+上年同期附表3!B16+上年同期附表3!B17+上年同期附表3!B18)/10000,0) -> 4270 | F10: =C10-E10 -> 331 | G10: =F10/E10 -> 0.077517564

Sheet 水电煤
B2: 项 目 | C2: 46113 | D2: 其中 | E2: 45748 | F2: 增减额 | G2: 增减率
D3: 奉贤院区
B4: 能耗成本 | C4: =C5+C6+C7 -> 461 | D4: =D5+D6+D7 -> 134 | E4: =E5+E6+E7 -> 515 | F4: =C4-E4 -> -54 | G4: =F4/E4 -> -0.10485437
B5: 其中：水费 | C5: =ROUND(当月附表3!B59/10000,0) -> 61 | D5: =ROUND(当月奉贤附表3!B59/10000,0) -> 8 | E5: =ROUND(上年同期附表3!B59/10000,0) -> 58 | F5: =C5-E5 -> 3 | G5: =F5/E5 -> 0.051724138
B6: 电费 | C6: =ROUND(当月附表3!B60/10000,0) -> 338 | D6: =ROUND(当月奉贤附表3!B60/10000,0) -> 95 | E6: =ROUND(上年同期附表3!B60/10000,0) -> 326 | F6: =C6-E6 -> 12 | G6: =F6/E6 -> 0.036809816
B7: 燃气费 | C7: =ROUND(当月附表3!B72/10000,0) -> 62 | D7: =ROUND(当月奉贤附表3!B72/10000,0) -> 31 | E7: =ROUND(上年同期附表3!B72/10000,0) -> 131 | F7: =C7-E7 -> -69 | G7: =F7/E7 -> -0.52671756

Sheet 预算完成情况
B2: 项 目 | C2: 执行率指标 | J2: 年终
C3: 核定数 | D3: 执行数 | E3: 执行率 | F3: 与时间节点比较 | H3: 0.333 | J3: 17532 | K3: =J3*(1-H3) -> 11693.844
B4: 医疗收入 | C4: 750000 | D4: =收支结余!C4 -> 67338 | E4: =D4/C4 -> 0.089784 | F4: =E4-$H$3 -> -0.243216 | K4: =D6-K3 -> 7746.156 | L4: =K4/C6 -> 0.03442736
B5: 医疗成本 | C5: 768743 | D5: =收支结余!C6 -> 70318 | E5: =D5/C5 -> 0.091471402 | F5: =E5-$H$3 -> -0.2415286
B6: 工资总额 | C6: 225000 | D6: =人员经费!C7 -> 19440 | E6: =D6/C6 -> 0.0864 | F6: =E6-$H$3 -> -0.2466

Sheet 收支结余
B2: 项 目 | C2: 46113 | D2: 其中 | E2: 45748 | F2: 增减额 | G2: 增减率
D3: 奉贤院区
B4: 医疗收入 | C4: =ROUND(当年累计数据表!O3/10000,0) -> 67338 | D4: =ROUND(当年累计数据表奉贤!O3/10000,0) -> 14595 | E4: =ROUND(去年累计数据表!O3/10000,0) -> 51336 | F4: =C4-E4 -> 16002 | G4: =F4/E4 -> 0.31171108
B5: 加：财政基本拨款收入 | C5: 2502 | D5: 0 | E5: 2411 | F5: =C5-E5 -> 91 | G5: =F5/E5 -> 0.037743675
B6: 减：医疗成本 | C6: =医疗成本!C11 -> 70318 | D6: =医疗成本!E11 -> 17384 | E6: =医疗成本!G11 -> 57616 | F6: =C6-E6 -> 12702 | G6: =F6/E6 -> 0.22045959
B7: 医疗服务盈余 | C7: =C4+C5-C6 -> -478 | D7: =D4+D5-D6 -> -2789 | E7: =E4+E5-E6 -> -3869 | F7: =C7-E7 -> 3391 | G7: =F7/E7 -> -0.87645386
B8: 其他盈余 | C8: =C9-C7 -> 277 | D8: =D9-D7 -> 116 | E8: =E9-E7 -> 1854 | F8: =C8-E8 -> -1577 | G8: -
B9: 收支结余 | C9: =ROUND(当月附表1!B5/10000,0) -> -201 | D9: =ROUND(当月奉贤附表1!B5/10000,0) -> -2673 | E9: =ROUND(上年同期附表1!B5/10000,0) -> -2015 | F9: =C9-E9 -> 1814 | G9: -
B16: 项 目 | C16: 46113 | D16: 45748 | E16: 增减额 | F16: 增减率
B17: 新华医疗开发公司 | E17: =C17-D17 -> 0 | F17: =E17/D17 -> #DIV/0!

Sheet 商品服务
B2: 项 目 | C2: 46113 | D2: 其中 | E2: 45748 | F2: 增减额 | G2: 增减率
D3: 奉贤院区
B4: 商品服务 | C4: =ROUND(当月附表3!B54/10000,0) -> 5873 | D4: =ROUND(当月奉贤附表3!B54/10000,0) -> 1415 | E4: =ROUND(上年同期附表3!B54/10000,0) -> 4509 | F4: =C4-E4 -> 1364 | G4: =F4/E4 -> 0.3025061
B5: 其中：能源成本 | C5: =水电煤!C4 -> 461 | D5: =水电煤!D4 -> 134 | E5: =水电煤!E4 -> 515 | F5: =C5-E5 -> -54 | G5: =F5/E5 -> -0.10485437
B6: 维修护费 | C6: =ROUND(当月附表3!B66/10000,0) -> 723 | D6: =ROUND(当月奉贤附表3!B66/10000,0) -> 219 | E6: =ROUND(上年同期附表3!B66/10000,0) -> 731 | F6: =C6-E6 -> -8 | G6: =F6/E6 -> -0.010943912
B7: 物业管理费 | C7: =ROUND(当月附表3!B63/10000,0) -> 1046 | D7: =ROUND(当月奉贤附表3!B63/10000,0) -> 367 | E7: =ROUND(上年同期附表3!B63/10000,0) -> 854 | F7: =C7-E7 -> 192 | G7: =F7/E7 -> 0.22482436
B8: 委托业务费 | C8: =ROUND(当月附表3!B74/10000,0) -> 1094 | D8: =ROUND(当月奉贤附表3!B74/10000,0) -> 93 | E8: =ROUND(上年同期附表3!B74/10000,0) -> 840 | F8: =C8-E8 -> 254 | G8: =F8/E8 -> 0.30238095
B9: 劳务费 | C9: =ROUND(当月附表3!B73/10000,0) -> 584 | D9: =ROUND(当月奉贤附表3!B73/10000,0) -> 185 | E9: =ROUND(上年同期附表3!B73/10000,0) -> 358 | F9: =C9-E9 -> 226 | G9: =F9/E9 -> 0.63128492
B10: 专用材料费 | C10: =ROUND(当月附表3!B71/10000,0) -> 149 | D10: =ROUND(当月奉贤附表3!B71/10000,0) -> 30 | E10: =ROUND(上年同期附表3!B71/10000,0) -> 106 | F10: =C10-E10 -> 43 | G10: =F10/E10 -> 0.40566038
B11: 供应室外包成本 | C11: 470 | D11: 104 | E11: 575 | F11: =C11-E11 -> -105 | G11: =F11/E11 -> -0.1826087
B12: 租赁费 | C12: =ROUND(当月附表3!B67/10000,0) -> 372 | D12: =ROUND(当月奉贤附表3!B67/10000,0) -> 95 | E12: =ROUND(上年同期附表3!B67/10000,0) -> 328 | F12: =C12-E12 -> 44 | G12: =F12/E12 -> 0.13414634
B13: 其他 | C13: =C4-C5-C6-C7-C8-C9-C10-C11-C12 -> 974 | D13: =D4-D5-D6-D7-D8-D9-D10-D11-D12 -> 188 | E13: =E4-E5-E6-E7-E8-E9-E10-E11-E12 -> 202 | F13: =C13-E13 -> 772 | G13: =F13/E13 -> 3.8217822
C24: =C11+C13 -> 1444 | D24: =D11+D13 -> 292 | E24: =E11+E13 -> 777 | F24: =F11+F13 -> 667 | G24: =F24/E24 -> 0.85842986

Sheet 物业管理
B3: 项 目 | C3: 46113 | D3: 其中 | E3: 45748 | F3: 增减额 | G3: 增减率 | I3: 项 目 | J3: 46113 | K3: 其中 | L3: 45748 | M3: 增减额 | N3: 增减率
D4: 奉贤院区 | K4: 奉贤院区
B5: 物业管理费 | C5: =商品服务!C7 -> 1046 | D5: =商品服务!D7 -> 367 | E5: =商品服务!E7 -> 854 | F5: =C5-E5 -> 192 | G5: =F5/E5 -> 0.22482436 | I5: 物业管理费 | J5: =商品服务!C7 -> 1046 | K5: =商品服务!D7 -> 367 | L5: =商品服务!E7 -> 854 | M5: =J5-L5 -> 192 | N5: =M5/L5 -> 0.22482436
B6: 其中： 电梯驾驶服务 | C6: -51 | D6: 15 | E6: 0 | F6: =C6-E6 -> -51 | G6: =F6/E6 -> #DIV/0! | I6: 其中： 电梯驾驶服务 | M6: =J6-L6 -> 0 | N6: =M6/L6 -> #DIV/0!
B7: 保安管理 | C7: 180 | D7: 58 | E7: 157 | F7: =C7-E7 -> 23 | G7: =F7/E7 -> 0.14649682 | I7: 保安管理 | J7: 180 | K7: 58 | L7: 157 | M7: =J7-L7 -> 23 | N7: =M7/L7 -> 0.14649682
B8: 运送服务费 | C8: 137 | D8: 74 | E8: 122 | F8: =C8-E8 -> 15 | G8: =F8/E8 -> 0.12295082 | I8: 运送服务费 | J8: 137 | K8: 74 | L8: 122 | M8: =J8-L8 -> 15 | N8: =M8/L8 -> 0.12295082
B9: 保洁服务 | C9: 595 | D9: 123 | E9: 272 | F9: =C9-E9 -> 323 | G9: =F9/E9 -> 1.1875 | I9: 保洁服务 | J9: 595 | K9: 123 | L9: 272 | M9: =J9-L9 -> 323 | N9: =M9/L9 -> 1.1875
B10: 被服洗涤 | C10: 73 | D10: 29 | E10: 58 | F10: =C10-E10 -> 15 | G10: =F10/E10 -> 0.25862069 | I10: 被服洗涤 | J10: 73 | K10: 29 | L10: 58 | M10: =J10-L10 -> 15 | N10: =M10/L10 -> 0.25862069
B11: 会务 | C11: 30 | D11: 20 | E11: 0 | F11: =C11-E11 -> 30 | G11: =F11/E11 -> #DIV/0! | I11: 物业其他 | J11: =J5-J6-J7-J8-J9-J10 -> 61 | K11: =K5-K6-K7-K8-K9-K10 -> 83 | L11: =L5-L6-L7-L8-L9-L10 -> 245 | M11: =J11-L11 -> -184 | N11: =M11/L11 -> -0.75102041
B12: 绿化 | C12: 3 | D12: 0 | E12: 2 | F12: =C12-E12 -> 1 | G12: =F12/E12 -> 0.5
B13: 垃圾清运 | C13: 17 | D13: 2 | E13: 7 | F13: =C13-E13 -> 10 | G13: =F13/E13 -> 1.4285714
B14: 危险废弃物 | C14: 3 | D14: 1 | E14: 124 | F14: =C14-E14 -> -121 | G14: =F14/E14 -> -0.97580645
B15: 医废处置 | C15: 19 | D15: 14 | E15: 0 | F15: =C15-E15 -> 19 | G15: =F15/E15 -> #DIV/0!
B16: 医废收运 | C16: 14 | D16: 7 | E16: 10 | F16: =C16-E16 -> 4 | G16: =F16/E16 -> 0.4
B17: 交通管理服务费 | C17: 6 | D17: 1
B18: 物业管理其他 | C18: =C5-C6-C7-C8-C9-C10-C11-C12-C13-C14-C15-C16-C17 -> 20 | D18: =D5-D6-D7-D8-D9-D10-D11-D12-D13-D14-D15-D16-D17 -> 23 | E18: =E5-E6-E7-E8-E9-E10-E11-E12-E13-E14-E15-E16-E17 -> 102 | F18: =C18-E18 -> -82 | G18: =F18/E18 -> -0.80392157

Sheet 维修护费
B1: 项 目 | C1: 46113 | D1: 其中 | E1: 45748 | F1: 增减额 | G1: 增减率
D2: 奉贤院区 | I2: 柯渡
B3: 维修费 | C3: =商品服务!C6 -> 723 | D3: =商品服务!D6 -> 219 | E3: =商品服务!E6 -> 731 | F3: =C3-E3 -> -8 | G3: =F3/E3 -> -0.010943912
B4: 其中：网络维修 | C4: 6 | D4: 1 | E4: 5 | F4: =C4-E4 -> 1 | G4: =F4/E4 -> 0.2
B5: 设备维修 | C5: 371 | D5: 86 | E5: 228 | F5: =C5-E5 -> 143 | G5: =F5/E5 -> 0.62719298 | H5: 1114 | I5: 100 | J5: 1146
B6: 后勤维修 | C6: 343 | D6: 132 | E6: 492 | F6: =C6-E6 -> -149 | G6: =F6/E6 -> -0.30284553
B7: 房屋维修 | C7: 3 | D7: 0 | E7: 6 | F7: =C7-E7 -> -3 | G7: =F7/E7 -> -0.5

Sheet 后勤维修
C3: 项 目 | D3: 46113 | E3: 其中 | F3: 45748 | G3: 增减额 | H3: 增减率 | K3: 项 目 | L3: 46113 | M3: 其中 | N3: 45748 | O3: 增减额 | P3: 增减率
E4: 奉贤院区 | M4: 奉贤院区
C5: 后勤维修费 | D5: =维修护费!C6 -> 343 | E5: =维修护费!D6 -> 132 | F5: =维修护费!E6 -> 492 | G5: =D5-F5 -> -149 | H5: =G5/F5 -> -0.30284553 | K5: 后勤维修费 | L5: =维修护费!C6 -> 343 | M5: =维修护费!D6 -> 132 | N5: =维修护费!E6 -> 492 | O5: =L5-N5 -> -149 | P5: =O5/N5 -> -0.30284553
C6: 其中：物业维修 | D6: 68 | E6: 32 | F6: 64 | G6: =D6-F6 -> 4 | H6: =G6/F6 -> 0.0625 | K6: 其中：物业维修 | L6: 68 | M6: 32 | N6: 64 | O6: =L6-N6 -> 4 | P6: =O6/N6 -> 0.0625
C7: 电梯运行 | D7: 12 | E7: 2 | F7: 0 | G7: =D7-F7 -> 12 | H7: =G7/F7 -> #DIV/0! | K7: 通用设施设备管理 | L7: 46 | M7: 9 | N7: 244 | O7: =L7-N7 -> -198 | P7: =O7/N7 -> -0.81147541
C8: 通用设施 | D8: 46 | E8: 9 | F8: 244 | G8: =D8-F8 -> -198 | H8: =G8/F8 -> -0.81147541 | K8: 空调运行管理费 | L8: 128 | M8: 30 | N8: 33 | O8: =L8-N8 -> 95 | P8: =O8/N8 -> 2.8787879
C9: 空调运行管理费 | D9: 128 | E9: 30 | F9: 33 | G9: =D9-F9 -> 95 | H9: =G9/F9 -> 2.8787879 | K9: 其他 | L9: =L5-L6-L7-L8 -> 101 | M9: =M5-M6-M7-M8 -> 61 | N9: =N5-N6-N7-N8 -> 151 | O9: =L9-N9 -> -50 | P9: =O9/N9 -> -0.33112583
C10: 电站运行 | D10: 1 | E10: 12 | F10: 9 | G10: =D10-F10 -> -8 | H10: =G10/F10 -> -0.88888889
C11: 给排水锅炉 | D11: 18 | E11: 12 | F11: 0 | G11: =D11-F11 -> 18 | H11: =G11/F11 -> #DIV/0!
C12: 后勤智能化 | D12: 8 | E12: 5 | F12: 0 | G12: =D12-F12 -> 8 | H12: =G12/F12 -> #DIV/0!
C13: 污水处理站 | D13: 27 | E13: 20 | F13: 11 | G13: =D13-F13 -> 16 | H13: =G13/F13 -> 1.4545455
C14: 污水管线 | D14: 2 | E14: 1 | F14: 1 | G14: =D14-F14 -> 1 | H14: =G14/F14 -> 1
C15: 医用气体 | D15: 9 | E15: 5 | F15: 12 | G15: =D15-F15 -> -3 | H15: =G15/F15 -> -0.25
C16: 其他 | D16: =D5-D6-D7-D8-D9-D10-D11-D12-D13-D14-D15 -> 24 | E16: =E5-E6-E7-E8-E9-E10-E11-E12-E13-E14-E15 -> 4 | F16: =F5-F6-F7-F8-F9-F10-F11-F12-F13-F14-F15 -> 118 | G16: =D16-F16 -> -94 | H16: =G16/F16 -> -0.79661017

Sheet 卫生材料
B2: 项 目 | C2: 46113 | D2: 其中 | E2: 45748 | F2: 增减额 | G2: 增减率
D3: 奉贤院区
B4: 卫生材料收入 | C4: =ROUND((当年累计数据表!AJ3+当年累计数据表!BS3)/10000,0) -> 19200 | D4: =ROUND((当年累计数据表奉贤!AJ3+当年累计数据表奉贤!BS3)/10000,0) -> 5553 | E4: =ROUND((去年累计数据表!AJ3+去年累计数据表!BS3)/10000,0) -> 13661 | F4: =C4-E4 -> 5539 | G4: =F4/E4 -> 0.4054608
B5: 卫生材料费 | C5: =医疗成本!C7 -> 22400 | D5: =医疗成本!E7 -> 6605 | E5: =医疗成本!G7 -> 16986 | F5: =C5-E5 -> 5414 | G5: =F5/E5 -> 0.31873307
B6: 其中：可收费 | C6: =C5-C7 -> 18910 | D6: =D5-D7 -> 5891 | E6: =E5-E7 -> 14222 | F6: =C6-E6 -> 4688 | G6: =F6/E6 -> 0.32963015 | I6: 调整
B7: 不可收费 | C7: 3490 | D7: 714 | E7: 2764 | F7: =C7-E7 -> 726 | G7: =F7/E7 -> 0.26266281 | I7: 101
B8: 其中：检验试剂 | C8: 2558 | D8: 567 | E8: 1729 | F8: =C8-E8 -> 829 | G8: =F8/E8 -> 0.4794679
B9: 其他不可收费卫生材料 | C9: =C7-C8 -> 932 | D9: =D7-D8 -> 147 | E9: =E7-E8 -> 1035 | F9: =F7-F8 -> -103 | G9: =F9/E9 -> -0.099516908
B11: 项 目 | C11: 46113 | D11: 其中：奉贤院区 | E11: 45748 | F11: 增减额 | G11: 增减率
B12: 检验试剂成本 | C12: =C8 -> 2558 | D12: =D8 -> 567 | E12: =E8 -> 1729 | F12: =F8 -> 829 | G12: =G8 -> 0.4794679
B13: 其中：医学检验科 | C13: 2059 | D13: 395 | E13: 1373 | F13: =C13-E13 -> 686 | G13: =F13/E13 -> 0.49963583
B14: 化验收入 | C14: =ROUND((当月附表2!B10+当月附表2!B23)/10000,0) -> 8020 | D14: =ROUND((当月奉贤附表2!B10+当月奉贤附表2!B23)/10000,0) -> 1512 | E14: =ROUND((上年同期附表2!B10+上年同期附表2!B23)/10000,0) -> 6132 | F14: =C14-E14 -> 1888 | G14: =F14/E14 -> 0.30789302
B15: 成本收入比重 | C15: =C12/C14 -> 0.31895262 | D15: =D12/D14 -> 0.375 | E15: =E12/E14 -> 0.28196347 | F15: =C15-E15 -> 0.036989148 | G15: -
B16: 门急诊人次 | C16: =ROUND(当年累计数据表!G3/10000,2) -> 46.53 | D16: =ROUND(当年累计数据表奉贤!G3/10000,2) -> 9.69 | E16: =ROUND(去年累计数据表!G3/10000,2) -> 36.18 | F16: =C16-E16 -> 10.35 | G16: =F16/E16 -> 0.28606965
B17: 住院人次 | C17: =ROUND(当年累计数据表!H3/10000,2) -> 1.63 | D17: =ROUND(当年累计数据表奉贤!H3/10000,2) -> 0.36 | E17: =ROUND(去年累计数据表!H3/10000,2) -> 1.35 | F17: =C17-E17 -> 0.28 | G17: =F17/E17 -> 0.20740741

Sheet 当年累计数据表
A1: 日期范围：20260401-20260430 | D1: 25 | O1: 1=2+5=8+43 | P1: 2=3+4 | Q1: 3 | R1: 4 | S1: 5=6+7 | T1: 6 | U1: 7 | V1: 8=9+12=15+22+29+36 | W1: 9=10+11 | X1: 10 | Y1: 11 | Z1: 12=13+14 | AA1: 13 | AB1: 14 | AC1: 15=16+19 | AD1: 16=17+18 | AE1: 17 | AF1: 18 | AG1: 19=20+21 | AH1: 20 | AI1: 21 | AJ1: 22=23+26 | AK1: 23=24+25 | AL1: 24 | AM1: 25 | AN1: 26=27+28 | AO1: 27 | AP1: 28 | AQ1: 29=30+33 | AR1: 30=31+32 | AS1: 31 | AT1: 32 | AU1: 33=34+35 | AV1: 34 | AW1: 35 | AX1: 36=37+40 | AY1: 37=38+39 | AZ1: 38 | BA1: 39 | BB1: 40=41+42 | BC1: 41 | BD1: 42 | BE1: 43=50+57+64+71=44+47 | BF1: 44=45+46 | BG1: 45 | BH1: 46 | BI1: 47=48+49 | BJ1: 48 | BK1: 49 | BL1: 50=51+54 | BM1: 51=52+53 | BN1: 52 | BO1: 53 | BP1: 54=55+56 | BQ1: 55 | BR1: 56 | BS1: 57=58+61 | BT1: 58=59+60 | BU1: 59 | BV1: 60 | BW1: 61=62+63 | BX1: 62 | BY1: 63 | BZ1: 64=65+68 | CA1: 65=66+67 | CB1: 66 | CC1: 67 | CD1: 68=69+70 | CE1: 69 | CF1: 70 | CG1: 71=72+75 | CH1: 72=73+74 | CI1: 73 | CJ1: 74 | CK1: 75=76+77 | CL1: 76 | CM1: 77 | CV1: 78=85+93+100+108+86+101=79+82 | CW1: 79=80+81 | CX1: 80 | CY1: 81 | CZ1: 82=83+84 | DA1: 83 | DB1: 84 | DC1: 85=87+90=78-93-100-108-86-101 | DD1: 86 | DE1: 87=88+89 | DF1: 88 | DG1: 89 | DH1: 90=91+92 | DI1: 91 | DJ1: 92 | DK1: 93=94+97 | DL1: 94=95+96 | DM1: 95 | DN1: 96 | DO1: 97=98+99 | DP1: 98 | DQ1: 99 | DR1: 100=102+105 | DS1: 101 | DT1: 102=103+104 | DU1: 103 | DV1: 104 | DW1: 105=106+107 | DX1: 106 | DY1: 107 | DZ1: 108=109+112 | EA1: 109=110+111 | EB1: 110 | EC1: 111 | ED1: 112=113+114 | EE1: 113 | EF1: 114 | EG1: 115=116+119 | EH1: 116=117+118 | EI1: 117 | EJ1: 118 | EK1: 119=120+121 | EL1: 120 | EM1: 121 | EN1: 122=123+124+125 | EO1: 123 | EP1: 124 | EQ1: 125 | EU1: 126=127+128+129 | EV1: 127 | EW1: 128 | EX1: 129 | EY1: 130=131+132 | EZ1: 131 | FA1: 132 | FB1: 133
A2: 序号 | B2: 科室类别 | C2: 科室名称 | D2: 医疗收入不含药耗 | E2: 门急诊收入不含药耗 | F2: 住院收入不含药耗 | G2: 门急诊人次 | H2: 住院人次 | I2: 门急诊治疗收入 | J2: 门急诊手术收入 | K2: 门诊中药饮片收入 | L2: 住院治疗收入 | M2: 住院手术收入 | N2: 住院中药饮片收入 | O2: 医疗收入 | P2: 其中本地病人医疗收入 | Q2: 其中本地病人医保医疗收入 | R2: 其中本地病人自费医疗收入 | S2: 其中异地病人医疗收入 | T2: 其中异地病人医保医疗收入 | U2: 其中异地病人自费医疗收入 | V2: 门急诊收入 | W2: 其中本地病人医疗收入 | X2: 其中本地病人医保医疗收入 | Y2: 其中本地病人自费医疗收入 | Z2: 其中异地病人医疗收入 | AA2: 其中异地病人医保医疗收入 | AB2: 其中异地病人自费医疗收入 | AC2: 门急诊药品收入 | AD2: 其中本地病人医疗收入 | AE2: 其中本地病人医保医疗收入 | AF2: 其中本地病人自费医疗收入 | AG2: 其中异地病人医疗收入 | AH2: 其中异地病人医保医疗收入 | AI2: 其中异地病人自费医疗收入 | AJ2: 门急诊耗材收入 | AK2: 其中本地病人医疗收入 | AL2: 其中本地病人医保医疗收入 | AM2: 其中本地病人自费医疗收入 | AN2: 其中异地病人医疗收入 | AO2: 其中异地病人医保医疗收入 | AP2: 其中异地病人自费医疗收入 | AQ2: 门急诊检查化验收入 | AR2: 其中本地病人医疗收入 | AS2: 其中本地病人医保医疗收入 | AT2: 其中本地病人自费医疗收入 | AU2: 其中异地病人医疗收入 | AV2: 其中异地病人医保医疗收入 | AW2: 其中异地病人自费医疗收入 | AX2: 门急诊劳务收入 | AY2: 其中本地病人医疗收入 | AZ2: 其中本地病人医保医疗收入 | BA2: 其中本地病人自费医疗收入 | BB2: 其中异地病人医疗收入 | BC2: 其中异地病人医保医疗收入 | BD2: 其中异地病人自费医疗收入 | BE2: 住院收入 | BF2: 其中本地病人医疗收入 | BG2: 其中本地病人医保医疗收入 | BH2: 其中本地病人自费医疗收入 | BI2: 其中异地病人医疗收入 | BJ2: 其中异地病人医保医疗收入 | BK2: 其中异地病人自费医疗收入 | BL2: 住院药品收入 | BM2: 其中本地病人医疗收入 | BN2: 其中本地病人医保医疗收入 | BO2: 其中本地病人自费医疗收入 | BP2: 其中异地病人医疗收入 | BQ2: 其中异地病人医保医疗收入 | BR2: 其中异地病人自费医疗收入 | BS2: 住院耗材收入 | BT2: 其中本地病人医疗收入 | BU2: 其中本地病人医保医疗收入 | BV2: 其中本地病人自费医疗收入 | BW2: 其中异地病人医疗收入 | BX2: 其中异地病人医保医疗收入 | BY2: 其中异地病人自费医疗收入 | BZ2: 住院检查化验收入 | CA2: 其中本地病人医疗收入 | CB2: 其中本地病人医保医疗收入 | CC2: 其中本地病人自费医疗收入 | CD2: 其中异地病人医疗收入 | CE2: 其中异地病人医保医疗收入 | CF2: 其中异地病人自费医疗收入 | CG2: 住院劳务收入 | CH2: 其中本地病人医疗收入 | CI2: 其中本地病人医保医疗收入 | CJ2: 其中本地病人自费医疗收入 | CK2: 其中异地病人医疗收入 | CL2: 其中异地病人医保医疗收入 | CM2: 其中异地病人自费医疗收入 | CN2: 急诊收入 | CO2: 普通门诊收入 | CP2: 专家门诊收入 | CQ2: 专病门诊收入 | CR2: 特需门诊收入 | CS2: MDT门诊收入 | CT2: 镜朗诊疗部收入 | CU2: 特需病房收入 | CV2: 门急诊人次 | CW2: 其中本地病人人次 | CX2: 其中本地病人医保人次 | CY2: 其中本地病人自费人次 | CZ2: 其中异地病人人次 | DA2: 其中异地病人医保人次 | DB2: 其中异地病人自费人次 | DC2: 普通门诊 (普通+专病) | DD2: 互联网普通门诊人次 | DE2: 其中本地病人人次 | DF2: 其中本地病人医保人次 | DG2: 其中本地病人自费人次 | DH2: 其中异地病人人次 | DI2: 其中异地病人医保人次 | DJ2: 其中异地病人自费人次 | DK2: 专家门诊 | DL2: 其中本地病人人次 | DM2: 其中本地病人医保人次 | DN2: 其中本地病人自费人次 | DO2: 其中异地病人人次 | DP2: 其中异地病人医保人次 | DQ2: 其中异地病人自费人次 | DR2: 特需门诊 (特需+MDT) | DS2: 互联网特需门诊人次 | DT2: 其中本地病人人次 | DU2: 其中本地病人医保人次 | DV2: 其中本地病人自费人次 | DW2: 其中异地病人人次 | DX2: 其中异地病人医保人次 | DY2: 其中异地病人自费人次 | DZ2: 急诊人次 | EA2: 其中本地病人人次 | EB2: 其中本地病人医保人次 | EC2: 其中本地病人自费人次 | ED2: 其中异地病人人次 | EE2: 其中异地病人医保人次 | EF2: 其中异地病人自费人次 | EG2: 住院人次 | EH2: 其中本地病人人次 | EI2: 其中本地病人医保人次 | EJ2: 其中本地病人自费人次 | EK2: 其中异地病人人次 | EL2: 其中异地病人医保人次 | EM2: 其中异地病人自费人次 | EN2: 手术人次与操作人次 | EO2: 手术人次 | EP2: 介入人次 | EQ2: 操作人次(治疗+诊断) | ER2: 微创手术人次（手术） | ES2: 微创手术人次（介入） | ET2: 微创手术人次（操作） | EU2: 三级手术 | EV2: 三级手术(手术) | EW2: 三级手术(介入) | EX2: 三级手术(操作) | EY2: 四级手术 | EZ2: 四级手术(手术) | FA2: 四级手术(介入) | FB2: 重点病种人次
A3: 小计： | D3: 3.1689143e+08 | E3: 1.4034284e+08 | F3: 1.7654859e+08 | G3: 465346 | H3: 16313 | I3: 24748353 | J3: 6537395.3 | K3: 2649428.8 | L3: 17414725 | M3: 46022880 | N3: 30481.97 | O3: 6.7337873e+08 | P3: 4.5465716e+08 | Q3: 4.2016861e+08 | R3: 34488555 | S3: 2.1872157e+08 | T3: 1.8332464e+08 | U3: 35396927 | V3: 2.4815185e+08 | W3: 2.0291608e+08 | X3: 1.8635817e+08 | Y3: 16557903 | Z3: 45235777 | AA3: 24023951 | AB3: 21211826 | AC3: 99357344 | AD3: 86868261 | AE3: 83908655 | AF3: 2959606.5 | AG3: 12489082 | AH3: 9125418.1 | AI3: 3363664.3 | AJ3: 8451670.7 | AK3: 7386333.1 | AL3: 6548799.3 | AM3: 837533.73 | AN3: 1065337.6 | AO3: 643343.93 | AP3: 421993.66 | AQ3: 79576300 | AR3: 64896578 | AS3: 59049566 | AT3: 5847011.8 | AU3: 14679722 | AV3: 7721562 | AW3: 6958159.8 | AX3: 60766540 | AY3: 43764904 | AZ3: 36851153 | BA3: 6913750.5 | BB3: 17001636 | BC3: 6533627 | BD3: 10468009 | BE3: 4.2522687e+08 | BF3: 2.5174108e+08 | BG3: 2.3381043e+08 | BH3: 17930653 | BI3: 1.7348579e+08 | BJ3: 1.5930069e+08 | BK3: 14185100 | BL3: 65126079 | BM3: 35808649 | BN3: 34236417 | BO3: 1572232.2 | BP3: 29317430 | BQ3: 27074032 | BR3: 2243398.6 | BS3: 1.8355221e+08 | BT3: 1.1280396e+08 | BU3: 1.0626868e+08 | BV3: 6535286.7 | BW3: 70748244 | BX3: 66595536 | BY3: 4152708.1 | BZ3: 72619444 | CA3: 44602626 | CB3: 41788514 | CC3: 2814112.5 | CD3: 28016817 | CE3: 26268769 | CF3: 1748048 | CG3: 1.0392914e+08 | CH3: 58525846 | CI3: 51516825 | CJ3: 7009021.2 | CK3: 45403297 | CL3: 39362351 | CM3: 6040945.8 | CN3: 29773959 | CO3: 89007270 | CP3: 65220304 | CQ3: 32373823 | CR3: 31494861 | CS3: 279820.57 | CT3: 10791056 | CU3: 0 | CV3: 465346 | CW3: 395943 | CX3: 362249 | CY3: 33694 | CZ3: 69403 | DA3: 36636 | DB3: 32767 | DC3: 255385 | DD3: 5407 | DE3: 224825 | DF3: 209134 | DG3: 15691 | DH3: 30560 | DI3: 17462 | DJ3: 13098 | DK3: 108889 | DL3: 87969 | DM3: 80744 | DN3: 7225 | DO3: 20920 | DP3: 11751 | DQ3: 9169 | DR3: 37467 | DS3: 136 | DT3: 26808 | DU3: 22411 | DV3: 4397 | DW3: 10659 | DX3: 4049 | DY3: 6610 | DZ3: 58062 | EA3: 51845 | EB3: 46370 | EC3: 5475 | ED3: 6217 | EE3: 3342 | EF3: 2875 | EG3: 16313 | EH3: 10149 | EI3: 9379 | EJ3: 770 | EK3: 6164 | EL3: 5572 | EM3: 592 | EN3: 13222 | EO3: 7087 | EP3: 962 | EQ3: 5173 | ER3: 1793 | ES3: 0 | ET3: 122 | EU3: 3463 | EV3: 2798 | EW3: 484 | EX3: 181 | EY3: 2380 | EZ3: 2130 | FA3: 250 | FB3: 5188
A4: 1 | B4: 成人非手术 | C4: 内科 | D4: 210990 | E4: 210990 | F4: 0 | G4: 1084 | H4: 0 | I4: 18 | J4: 0 | K4: 0 | L4: 0 | M4: 0 | N4: 0 | O4: 530057.92 | P4: 491380.33 | Q4: 472210.09 | R4: 19170.24 | S4: 38677.59 | T4: 31098.94 | U4: 7578.65 | V4: 530057.92 | W4: 491380.33 | X4: 472210.09 | Y4: 19170.24 | Z4: 38677.59 | AA4: 31098.94 | AB4: 7578.65 | AC4: 318013.92 | AD4: 303723.33 | AE4: 300395.09 | AF4: 3328.24 | AG4: 14290.59 | AH4: 13595.94 | AI4: 694.65 | AJ4: 1054 | AK4: 882 | AL4: 882 | AM4: 0 | AN4: 172 | AO4: 172 | AP4: 0 | AQ4: 178887 | AR4: 157880 | AS4: 143791 | AT4: 14089 | AU4: 21007 | AV4: 15851 | AW4: 5156 | AX4: 32103 | AY4: 28895 | AZ4: 27142 | BA4: 1753 | BB4: 3208 | BC4: 1480 | BD4: 1728 | BE4: 0 | BF4: 0 | BG4: 0 | BH4: 0 | BI4: 0 | BJ4: 0 | BK4: 0 | BL4: 0 | BM4: 0 | BN4: 0 | BO4: 0 | BP4: 0 | BQ4: 0 | BR4: 0 | BS4: 0 | BT4: 0 | BU4: 0 | BV4: 0 | BW4: 0 | BX4: 0 | BY4: 0 | BZ4: 0 | CA4: 0 | CB4: 0 | CC4: 0 | CD4: 0 | CE4: 0 | CF4: 0 | CG4: 0 | CH4: 0 | CI4: 0 | CJ4: 0 | CK4: 0 | CL4: 0 | CM4: 0 | CN4: 0 | CO4: 295279.04 | CP4: 155014.39 | CQ4: 68454.13 | CR4: 11310.36 | CS4: 0 | CT4: 0 | CU4: 0 | CV4: 1084 | CW4: 1004 | CX4: 970 | CY4: 34 | CZ4: 80 | DA4: 57 | DB4: 23 | DC4: 820 | DD4: 47 | DE4: 773 | DF4: 755 | DG4: 18 | DH4: 47 | DI4: 41 | DJ4: 6 | DK4: 207 | DL4: 190 | DM4: 184 | DN4: 6 | DO4: 17 | DP4: 15 | DQ4: 2 | DR4: 10 | DS4: 0 | DT4: 7 | DU4: 4 | DV4: 3 | DW4: 3 | DX4: 0 | DY4: 3 | DZ4: 0 | EA4: 0 | EB4: 0 | EC4: 0 | ED4: 0 | EE4: 0 | EF4: 0 | EG4: 0 | EH4: 0 | EI4: 0 | EJ4: 0 | EK4: 0 | EL4: 0 | EM4: 0 | EN4: 0 | EO4: 0 | EP4: 0 | EQ4: 0 | ER4: 0 | ES4: 0 | ET4: 0 | EU4: 0 | EV4: 0 | EW4: 0 | EX4: 0 | EY4: 0 | EZ4: 0 | FA4: 0 | FB4: 0
A5: 2 | B5: 成人非手术 | C5: 呼吸内科 | D5: 5743610 | E5: 2473467 | F5: 3270143 | G5: 10858 | H5: 340 | I5: 11502 | J5: 0 | K5: 0 | L5: 201558.5 | M5: 3928 | N5: 0 | O5: 10923919 | P5: 8259203.3 | Q5: 8089892.5 | R5: 169310.85 | S5: 2664715.5 | T5: 2476119.2 | U5: 188596.31 | V5: 5052053 | W5: 4417989.1 | X5: 4280274.5 | Y5: 137714.54 | Z5: 634063.99 | AA5: 460326.47 | AB5: 173737.52 | AC5: 2507130.3 | AD5: 2173417 | AE5: 2129423.4 | AF5: 43993.54 | AG5: 333713.35 | AH5: 255796.83 | AI5: 77916.52 | AJ5: 71455.72 | AK5: 62491.08 | AL5: 60164.08 | AM5: 2327 | AN5: 8964.64 | AO5: 6029.64 | AP5: 2935 | AQ5: 2076910 | AR5: 1837741 | AS5: 1762625 | AT5: 75116 | AU5: 239169 | AV5: 164325 | AW5: 74844 | AX5: 396557 | AY5: 344340 | AZ5: 328062 | BA5: 16278 | BB5: 52217 | BC5: 34175 | BD5: 18042 | BE5: 5871865.8 | BF5: 3841214.2 | BG5: 3809617.9 | BH5: 31596.31 | BI5: 2030651.5 | BJ5: 2015792.7 | BK5: 14858.79 | BL5: 2420489.4 | BM5: 1566584.5 | BN5: 1548759.9 | BO5: 17824.62 | BP5: 853904.9 | BQ5: 853761.81 | BR5: 143.09 | BS5: 181233.37 | BT5: 118209.25 | BU5: 117998.56 | BV5: 210.69 | BW5: 63024.12 | BX5: 61750.42 | BY5: 1273.7 | BZ5: 2557112 | CA5: 1660445 | CB5: 1649058 | CC5: 11387 | CD5: 896667 | CE5: 884599 | CF5: 12068 | CG5: 713031 | CH5: 495975.5 | CI5: 493801.5 | CJ5: 2174 | CK5: 217055.5 | CL5: 215681.5 | CM5: 1374 | CN5: 25 | CO5: 3106612.2 | CP5: 1604478.9 | CQ5: 91788.1 | CR5: 249173.8 | CS5: 0 | CT5: 0 | CU5: 0 | CV5: 10858 | CW5: 9614 | CX5: 9269 | CY5: 345 | CZ5: 1244 | DA5: 854 | DB5: 390 | DC5: 8091 | DD5: 59 | DE5: 7212 | DF5: 6974 | DG5: 238 | DH5: 879 | DI5: 603 | DJ5: 276 | DK5: 2400 | DL5: 2096 | DM5: 2010 | DN5: 86 | DO5: 304 | DP5: 218 | DQ5: 86 | DR5: 307 | DS5: 1 | DT5: 248 | DU5: 229 | DV5: 19 | DW5: 59 | DX5: 33 | DY5: 26 | DZ5: 0 | EA5: 0 | EB5: 0 | EC5: 0 | ED5: 0 | EE5: 0 | EF5: 0 | EG5: 340 | EH5: 225 | EI5: 223 | EJ5: 2 | EK5: 115 | EL5: 114 | EM5: 1 | EN5: 208 | EO5: 3 | EP5: 0 | EQ5: 205 | ER5: 1 | ES5: 0 | ET5: 1 | EU5: 1 | EV5: 1 | EW5: 0 | EX5: 0 | EY5: 0 | EZ5: 0 | FA5: 0 | FB5: 99
A6: 3 | B6: 成人非手术 | C6: 消化内科（内窥镜诊治部） | D6: 11432853 | E6: 6981108 | F6: 4451745 | G6: 23158 | H6: 737 | I6: 472266 | J6: 30900 | K6: 0 | L6: 385759 | M6: 495540 | N6: 1397 | O6: 20840483 | P6: 17231788 | Q6: 16550936 | R6: 680852.02 | S6: 3608694.5 | T6: 2986734.8 | U6: 621959.68 | V6: 12923344 | W6: 11282768 | X6: 10674431 | Y6: 608336.49 | Z6: 1640576.7 | AA6: 1087990.7 | AB6: 552585.93 | AC6: 5239104.2 | AD6: 4637267.5 | AE6: 4506613 | AF6: 130654.49 | AG6: 601836.66 | AH6: 420962.73 | AI6: 180873.93 | AJ6: 703132.29 | AK6: 612125.29 | AL6: 584896.29 | AM6: 27229 | AN6: 91007 | AO6: 69451 | AP6: 21556 | AQ6: 4965555 | AR6: 4322568 | AS6: 4147890 | AT6: 174678 | AU6: 642987 | AV6: 452893 | AW6: 190094 | AX6: 2015553 | AY6: 1710807 | AZ6: 1435032 | BA6: 275775 | BB6: 304746 | BC6: 144684 | BD6: 160062 | BE6: 7917138.3 | BF6: 5949020.4 | BG6: 5876504.9 | BH6: 72515.53 | BI6: 1968117.8 | BJ6: 1898744.1 | BK6: 69373.75 | BL6: 1423513.2 | BM6: 1053361.7 | BN6: 1044954 | BO6: 8407.65 | BP6: 370151.53 | BQ6: 360460.12 | BR6: 9691.41 | BS6: 2041880.1 | BT6: 1595162.3 | BU6: 1575099.4 | BV6: 20062.88 | BW6: 446717.81 | BX6: 418325.47 | BY6: 28392.34 | BZ6: 2879927 | CA6: 2082617 | CB6: 2058262 | CC6: 24355 | CD6: 797310 | CE6: 775874 | CF6: 21436 | CG6: 1571818 | CH6: 1217879.5 | CI6: 1198189.5 | CJ6: 19690 | CK6: 353938.5 | CL6: 344084.5 | CM6: 9854 | CN6: -981 | CO6: 6424854 | CP6: 3097263.5 | CQ6: 1826549.8 | CR6: 1574677.2 | CS6: 0 | CT6: 96162.56 | CU6: 0 | CV6: 23158 | CW6: 20250 | CX6: 19321 | CY6: 929 | CZ6: 2908 | DA6: 1894 | DB6: 1014 | DC6: 16127 | DD6: 251 | DE6: 14217 | DF6: 13703 | DG6: 514 | DH6: 1910 | DI6: 1272 | DJ6: 638 | DK6: 5607 | DL6: 4839 | DM6: 4665 | DN6: 174 | DO6: 768 | DP6: 540 | DQ6: 228 | DR6: 1173 | DS6: 0 | DT6: 957 | DU6: 722 | DV6: 235 | DW6: 216 | DX6: 78 | DY6: 138 | DZ6: 0 | EA6: 0 | EB6: 0 | EC6: 0 | ED6: 0 | EE6: 0 | EF6: 0 | EG6: 737 | EH6: 550 | EI6: 545 | EJ6: 5 | EK6: 187 | EL6: 181 | EM6: 6 | EN6: 860 | EO6: 0 | EP6: 0 | EQ6: 860 | ER6: 0 | ES6: 0 | ET6: 98 | EU6: 73 | EV6: 0 | EW6: 0 | EX6: 73 | EY6: 0 | EZ6: 0 | FA6: 0 | FB6: 54
A7: 4 | B7: 成人非手术 | C7: 神经内科 | D7: 6972544.5 | E7: 3626581.5 | F7: 3345963 | G7: 15467 | H7: 306 | I7: 826 | J7: 0 | K7: 93509.65 | L7: 156244.5 | M7: 59201 | N7: 399.07 | O7: 15524657 | P7: 12939918 | Q7: 12664442 | R7: 275476.47 | S7: 2584739.1 | T7: 2257222.1 | U7: 327516.94 | V7: 7964990.2 | W7: 7011810.4 | X7: 6783101 | Y7: 228709.37 | Z7: 953179.89 | AA7: 713075.13 | AB7: 240104.76 | AC7: 4327761.5 | AD7: 3908922.6 | AE7: 3820626.2 | AF7: 88296.37 | AG7: 418838.89 | AH7: 317814.13 | AI7: 101024.76 | AJ7: 10647.28 | AK7: 8239.28 | AL7: 7594.28 | AM7: 645 | AN7: 2408 | AO7: 1763 | AP7: 645 | AQ7: 3007835 | AR7: 2564902 | AS7: 2451381 | AT7: 113521 | AU7: 442933 | AV7: 332149 | AW7: 110784 | AX7: 618746.5 | AY7: 529746.5 | AZ7: 503499.5 | BA7: 26247 | BB7: 89000 | BC7: 61349 | BD7: 27651 | BE7: 7559667.2 | BF7: 5928108 | BG7: 5881340.9 | BH7: 46767.1 | BI7: 1631559.2 | BJ7: 1544147 | BK7: 87412.18 | BL7: 1399756.3 | BM7: 1085758.6 | BN7: 1077473 | BO7: 8285.65 | BP7: 313997.68 | BQ7: 297799.76 | BR7: 16197.92 | BS7: 2813947.9 | BT7: 2299958.4 | BU7: 2296061.5 | BV7: 3896.95 | BW7: 513989.52 | BX7: 507281.26 | BY7: 6708.26 | BZ7: 2507090 | CA7: 1852666 | CB7: 1827609 | CC7: 25057 | CD7: 654424 | CE7: 599601 | CF7: 54823 | CG7: 838873 | CH7: 689725 | CI7: 680197.5 | CJ7: 9527.5 | CK7: 149148 | CL7: 139465 | CM7: 9683 | CN7: -60 | CO7: 3960365 | CP7: 1616226.9 | CQ7: 1430226.6 | CR7: 958171.78 | CS7: 0 | CT7: 0 | CU7: 0 | CV7: 15467 | CW7: 13804 | CX7: 13267 | CY7: 537 | CZ7: 1663 | DA7: 1173 | DB7: 490 | DC7: 11687 | DD7: 271 | DE7: 10604 | DF7: 10240 | DG7: 364 | DH7: 1083 | DI7: 766 | DJ7: 317 | DK7: 2591 | DL7: 2219 | DM7: 2112 | DN7: 107 | DO7: 372 | DP7: 276 | DQ7: 96 | DR7: 918 | DS7: 0 | DT7: 726 | DU7: 674 | DV7: 52 | DW7: 192 | DX7: 131 | DY7: 61 | DZ7: 0 | EA7: 0 | EB7: 0 | EC7: 0 | ED7: 0 | EE7: 0 | EF7: 0 | EG7: 306 | EH7: 235 | EI7: 231 | EJ7: 4 | EK7: 71 | EL7: 66 | EM7: 5 | EN7: 126 | EO7: 0 | EP7: 27 | EQ7: 99 | ER7: 0 | ES7: 0 | ET7: 0 | EU7: 4 | EV7: 0 | EW7: 4 | EX7: 0 | EY7: 23 | EZ7: 0 | FA7: 23 | FB7: 86
A8: 5 | B8: 成人非手术 | C8: 心血管内科 | D8: 18452422 | E8: 4874729 | F8: 13577693 | G8: 36241 | H8: 1191 | I8: 5742 | J8: 0 | K8: 0 | L8: 238314.5 | M8: 2970828 | N8: 456.83 | O8: 73227690 | P8: 56427676 | Q8: 55729351 | R8: 698324.99 | S8: 16800013 | T8: 16420941 | U8: 379072.27 | V8: 16650715 | W8: 15304543 | X8: 15079078 | Y8: 225465.25 | Z8: 1346171.7 | AA8: 1122950.7 | AB8: 223220.95 | AC8: 11715680 | AD8: 10878793 | AE8: 10774702 | AF8: 104091.25 | AG8: 836886.69 | AH8: 735685.74 | AI8: 101200.95 | AJ8: 60306 | AK8: 53269 | AL8: 51779 | AM8: 1490 | AN8: 7037 | AO8: 4887 | AP8: 2150 | AQ8: 3631631 | AR8: 3265794 | AS8: 3177688 | AT8: 88106 | AU8: 365837 | AV8: 280305 | AW8: 85532 | AX8: 1243098 | AY8: 1106687 | AZ8: 1074909 | BA8: 31778 | BB8: 136411 | BC8: 102073 | BD8: 34338 | BE8: 56576975 | BF8: 41123133 | BG8: 40650273 | BH8: 472859.74 | BI8: 15453842 | BJ8: 15297990 | BK8: 155851.32 | BL8: 2914392.3 | BM8: 2272102 | BN8: 2248265.6 | BO8: 23836.36 | BP8: 642290.26 | BQ8: 636215.9 | BR8: 6074.36 | BS8: 40084890 | BT8: 28689193 | BU8: 28353638 | BV8: 335555.13 | BW8: 11395697 | BX8: 11292577 | BY8: 103119.96 | BZ8: 8590941 | CA8: 6458582 | CB8: 6393427 | CC8: 65155 | CD8: 2132359 | CE8: 2106561 | CF8: 25798 | CG8: 4986752 | CH8: 3703256.2 | CI8: 3654943 | CJ8: 48313.25 | CK8: 1283495.8 | CL8: 1262636.8 | CM8: 20859 | CN8: 0 | CO8: 7696489 | CP8: 6051406.9 | CQ8: 2468449.1 | CR8: 434369.72 | CS8: 0 | CT8: 0 | CU8: 0 | CV8: 36241 | CW8: 33096 | CX8: 32455 | CY8: 641 | CZ8: 3145 | DA8: 2470 | DB8: 675 | DC8: 24540 | DD8: 507 | DE8: 22707 | DF8: 22330 | DG8: 377 | DH8: 1833 | DI8: 1441 | DJ8: 392 | DK8: 10662 | DL8: 9489 | DM8: 9257 | DN8: 232 | DO8: 1173 | DP8: 944 | DQ8: 229 | DR8: 532 | DS8: 0 | DT8: 406 | DU8: 382 | DV8: 24 | DW8: 126 | DX8: 81 | DY8: 45 | DZ8: 0 | EA8: 0 | EB8: 0 | EC8: 0 | ED8: 0 | EE8: 0 | EF8: 0 | EG8: 1191 | EH8: 893 | EI8: 886 | EJ8: 7 | EK8: 298 | EL8: 296 | EM8: 2 | EN8: 1156 | EO8: 171 | EP8: 570 | EQ8: 415 | ER8: 0 | ES8: 0 | ET8: 0 | EU8: 518 | EV8: 165 | EW8: 353 | EX8: 0 | EY8: 43 | EZ8: 2 | FA8: 41 | FB8: 290
A9: 6 | B9: 成人非手术 | C9: 血液内科 | D9: 2099214 | E9: 263441 | F9: 1835773 | G9: 1416 | H9: 386 | I9: 986 | J9: 0 | K9: 0 | L9: 101490 | M9: 5289 | N9: 519.12 | O9: 8213142.6 | P9: 4135836.6 | Q9: 4125777.5 | R9: 10059.11 | S9: 4077305.9 | T9: 4030383 | U9: 46922.87 | V9: 1127742.8 | W9: 980816.06 | X9: 971400.45 | Y9: 9415.61 | Z9: 146926.77 | AA9: 128171.57 | AB9: 18755.2 | AC9: 851849.53 | AD9: 756557.76 | AE9: 754348.15 | AF9: 2209.61 | AG9: 95291.77 | AH9: 88191.57 | AI9: 7100.2 | AJ9: 12452.3 | AK9: 12194.3 | AL9: 12194.3 | AM9: 0 | AN9: 258 | AO9: 258 | AP9: 0 | AQ9: 209898 | AR9: 168826 | AS9: 163410 | AT9: 5416 | AU9: 41072 | AV9: 31356 | AW9: 9716 | AX9: 53543 | AY9: 43238 | AZ9: 41448 | BA9: 1790 | BB9: 10305 | BC9: 8366 | BD9: 1939 | BE9: 7085399.7 | BF9: 3155020.6 | BG9: 3154377.1 | BH9: 643.5 | BI9: 3930379.1 | BJ9: 3902211.5 | BK9: 28167.67 | BL9: 5022957.5 | BM9: 2246441.6 | BN9: 2246441.6 | BO9: 0 | BP9: 2776516 | BQ9: 2760374.6 | BR9: 16141.35 | BS9: 226669.18 | BT9: 83771.03 | BU9: 83771.03 | BV9: 0 | BW9: 142898.15 | BX9: 141183.33 | BY9: 1714.82 | BZ9: 1304941 | CA9: 615656 | CB9: 615089 | CC9: 567 | CD9: 689285 | CE9: 682633 | CF9: 6652 | CG9: 530832 | CH9: 209152 | CI9: 209075.5 | CJ9: 76.5 | CK9: 321680 | CL9: 318020.5 | CM9: 3659.5 | CN9: 0 | CO9: 285085.98 | CP9: 699225.37 | CQ9: 130565.12 | CR9: 12866.36 | CS9: 0 | CT9: 0 | CU9: 0 | CV9: 1416 | CW9: 1125 | CX9: 1076 | CY9: 49 | CZ9: 291 | DA9: 238 | DB9: 53 | DC9: 851 | DD9: 0 | DE9: 654 | DF9: 628 | DG9: 26 | DH9: 197 | DI9: 160 | DJ9: 37 | DK9: 548 | DL9: 457 | DM9: 434 | DN9: 23 | DO9: 91 | DP9: 76 | DQ9: 15 | DR9: 17 | DS9: 0 | DT9: 14 | DU9: 14 | DV9: 0 | DW9: 3 | DX9: 2 | DY9: 1 | DZ9: 0 | EA9: 0 | EB9: 0 | EC9: 0 | ED9: 0 | EE9: 0 | EF9: 0 | EG9: 386 | EH9: 176 | EI9: 175 | EJ9: 1 | EK9: 210 | EL9: 209 | EM9: 1 | EN9: 268 | EO9: 0 | EP9: 0 | EQ9: 268 | ER9: 0 | ES9: 0 | ET9: 0 | EU9: 0 | EV9: 0 | EW9: 0 | EX9: 0 | EY9: 0 | EZ9: 0 | FA9: 0 | FB9: 39
A10: 7 | B10: 成人非手术 | C10: 肾脏风湿免疫科 | D10: 7367993.5 | E10: 5188718 | F10: 2179275.5 | G10: 8314 | H10: 250 | I10: 3630905 | J10: 0 | K10: 0 | L10: 141301.5 | M10: 45729 | N10: 0 | O10: 13471348 | P10: 11874330 | Q10: 11740331 | R10: 133999.08 | S10: 1597018.1 | T10: 1439276.5 | U10: 157741.53 | V10: 10113520 | W10: 9321683.6 | X10: 9215928.1 | Y10: 105755.5 | Z10: 791836.85 | AA10: 653816.03 | AB10: 138020.82 | AC10: 3995686.3 | AD10: 3666715.5 | AE10: 3626135.5 | AF10: 40579.96 | AG10: 328970.81 | AH10: 260195.17 | AI10: 68775.64 | AJ10: 929116.17 | AK10: 887282.13 | AL10: 881691.59 | AM10: 5590.54 | AN10: 41834.04 | AO10: 34666.86 | AP10: 7167.18 | AQ10: 1261705 | AR10: 1105671 | AS10: 1069571 | AT10: 36100 | AU10: 156034 | AV10: 119885 | AW10: 36149 | AX10: 3927013 | AY10: 3662015 | AZ10: 3638530 | BA10: 23485 | BB10: 264998 | BC10: 239069 | BD10: 25929 | BE10: 3357827.4 | BF10: 2552646.2 | BG10: 2524402.6 | BH10: 28243.58 | BI10: 805181.22 | BJ10: 785460.51 | BK10: 19720.71 | BL10: 995537.89 | BM10: 797627.04 | BN10: 793281.16 | BO10: 4345.88 | BP10: 197910.85 | BQ10: 196431.03 | BR10: 1479.82 | BS10: 183014.04 | BT10: 139315.67 | BU10: 139089.47 | BV10: 226.2 | BW10: 43698.37 | BX10: 43424.98 | BY10: 273.39 | BZ10: 1631340 | CA10: 1210610 | CB10: 1189086 | CC10: 21524 | CD10: 420730 | CE10: 404968 | CF10: 15762 | CG10: 547935.5 | CH10: 405093.5 | CI10: 402946 | CJ10: 2147.5 | CK10: 142842 | CL10: 140636.5 | CM10: 2205.5 | CN10: 0 | CO10: 1474700.8 | CP10: 1616938.7 | CQ10: 6852330 | CR10: 169550.97 | CS10: 0 | CT10: 0 | CU10: 0 | CV10: 8314 | CW10: 7420 | CX10: 7214 | CY10: 206 | CZ10: 894 | DA10: 653 | DB10: 241 | DC10: 6026 | DD10: 108 | DE10: 5416 | DF10: 5261 | DG10: 155 | DH10: 610 | DI10: 452 | DJ10: 158 | DK10: 2030 | DL10: 1795 | DM10: 1752 | DN10: 43 | DO10: 235 | DP10: 175 | DQ10: 60 | DR10: 150 | DS10: 0 | DT10: 114 | DU10: 108 | DV10: 6 | DW10: 36 | DX10: 25 | DY10: 11 | DZ10: 0 | EA10: 0 | EB10: 0 | EC10: 0 | ED10: 0 | EE10: 0 | EF10: 0 | EG10: 250 | EH10: 185 | EI10: 183 | EJ10: 2 | EK10: 65 | EL10: 63 | EM10: 2 | EN10: 71 | EO10: 18 | EP10: 0 | EQ10: 53 | ER10: 0 | ES10: 0 | ET10: 0 | EU10: 0 | EV10: 0 | EW10: 0 | EX10: 0 | EY10: 0 | EZ10: 0 | FA10: 0 | FB10: 149
A11: 8 | B11: 成人非手术 | C11: 内分泌科 | D11: 6248309 | E11: 4211805 | F11: 2036504 | G11: 18604 | H11: 214 | I11: 7038 | J11: 1148 | K11: 0 | L11: 205970.5 | M11: 8960 | N11: 0 | O11: 11514934 | P11: 10237945 | Q11: 10059900 | R11: 178045.52 | S11: 1276988.4 | T11: 1071549.2 | U11: 205439.26 | V11: 8897351.9 | W11: 8146723.3 | X11: 7968677.8 | Y11: 178045.52 | Z11: 750628.63 | AA11: 592793.65 | AB11: 157834.98 | AC11: 4596625.7 | AD11: 4256485.3 | AE11: 4196368.6 | AF11: 60116.72 | AG11: 340140.43 | AH11: 290620.65 | AI11: 49519.78 | AJ11: 88921.2 | AK11: 81103 | AL11: 79615.2 | AM11: 1487.8 | AN11: 7818.2 | AO11: 6592 | AP11: 1226.2 | AQ11: 3543082 | AR11: 3207566 | AS11: 3114547 | AT11: 93019 | AU11: 335516 | AV11: 245449 | AW11: 90067 | AX11: 668723 | AY11: 601569 | AZ11: 578147 | BA11: 23422 | BB11: 67154 | BC11: 50132 | BD11: 17022 | BE11: 2617581.6 | BF11: 2091221.8 | BG11: 2091221.8 | BH11: 0 | BI11: 526359.82 | BJ11: 478755.54 | BK11: 47604.28 | BL11: 534509.3 | BM11: 429732.53 | BN11: 429732.53 | BO11: 0 | BP11: 104776.77 | BQ11: 94013.87 | BR11: 10762.9 | BS11: 46568.32 | BT11: 38837.27 | BU11: 38837.27 | BV11: 0 | BW11: 7731.05 | BX11: 6800.67 | BY11: 930.38 | BZ11: 1580809 | CA11: 1260897 | CB11: 1260897 | CC11: 0 | CD11: 319912 | CE11: 291584 | CF11: 28328 | CG11: 455695 | CH11: 361755 | CI11: 361755 | CJ11: 0 | CK11: 93940 | CL11: 86357 | CM11: 7583 | CN11: -90 | CO11: 4815032.5 | CP11: 2871145.7 | CQ11: 839638.59 | CR11: 371535.07 | CS11: 0 | CT11: 0 | CU11: 0 | CV11: 18604 | CW11: 16899 | CX11: 16433 | CY11: 466 | CZ11: 1705 | DA11: 1292 | DB11: 413 | DC11: 12632 | DD11: 208 | DE11: 11526 | DF11: 11230 | DG11: 296 | DH11: 1106 | DI11: 841 | DJ11: 265 | DK11: 5295 | DL11: 4775 | DM11: 4629 | DN11: 146 | DO11: 520 | DP11: 406 | DQ11: 114 | DR11: 462 | DS11: 7 | DT11: 395 | DU11: 374 | DV11: 21 | DW11: 67 | DX11: 45 | DY11: 22 | DZ11: 0 | EA11: 0 | EB11: 0 | EC11: 0 | ED11: 0 | EE11: 0 | EF11: 0 | EG11: 214 | EH11: 172 | EI11: 167 | EJ11: 5 | EK11: 42 | EL11: 36 | EM11: 6 | EN11: 1 | EO11: 0 | EP11: 0 | EQ11: 1 | ER11: 0 | ES11: 0 | ET11: 0 | EU11: 0 | EV11: 0 | EW11: 0 | EX11: 0 | EY11: 0 | EZ11: 0 | FA11: 0 | FB11: 197
A12: 9 | B12: 成人非手术 | C12: 老年医学科 | D12: 4062487.5 | E12: 257381.5 | F12: 3805106 | G12: 2336 | H12: 67 | I12: 8342 | J12: 0 | K12: 56510.61 | L12: 754731.5 | M12: 23002 | N12: 761.79 | O12: 7445922.8 | P12: 7414010.7 | Q12: 7404248.1 | R12: 9762.59 | S12: 31912.16 | T12: 18441.51 | U12: 13470.65 | V12: 1631098.5 | W12: 1599186.3 | X12: 1589423.8 | Y12: 9762.59 | Z12: 31912.16 | AA12: 18441.51 | AB12: 13470.65 | AC12: 1364326.6 | AD12: 1337916.4 | AE12: 1330875.8 | AF12: 7040.59 | AG12: 26410.16 | AH12: 15133.51 | AI12: 11276.65 | AJ12: 9390.45 | AK12: 9302.45 | AL12: 9302.45 | AM12: 0 | AN12: 88 | AO12: 43 | AP12: 45 | AQ12: 186999 | AR12: 183867 | AS12: 181776 | AT12: 2091 | AU12: 3132 | AV12: 2268 | AW12: 864 | AX12: 70382.5 | AY12: 68100.5 | AZ12: 67469.5 | BA12: 631 | BB12: 2282 | BC12: 997 | BD12: 1285 | BE12: 5814824.3 | BF12: 5814824.3 | BG12: 5814824.3 | BH12: 0 | BI12: 0 | BJ12: 0 | BK12: 0 | BL12: 1860077.9 | BM12: 1860077.9 | BN12: 1860077.9 | BO12: 0 | BP12: 0 | BQ12: 0 | BR12: 0 | BS12: 149640.37 | BT12: 149640.37 | BU12: 149640.37 | BV12: 0 | BW12: 0 | BX12: 0 | BY12: 0 | BZ12: 1717023 | CA12: 1717023 | CB12: 1717023 | CC12: 0 | CD12: 0 | CE12: 0 | CF12: 0 | CG12: 2088083 | CH12: 2088083 | CI12: 2088083 | CJ12: 0 | CK12: 0 | CL12: 0 | CM12: 0 | CN12: 0 | CO12: 1611616 | CP12: 0 | CQ12: 75 | CR12: 19407.5 | CS12: 0 | CT12: 0 | CU12: 0 | CV12: 2336 | CW12: 2289 | CX12: 2282 | CY12: 7 | CZ12: 47 | DA12: 37 | DB12: 10 | DC12: 2323 | DD12: 0 | DE12: 2285 | DF12: 2282 | DG12: 3 | DH12: 38 | DI12: 37 | DJ12: 1 | DK12: 0 | DL12: 0 | DM12: 0 | DN12: 0 | DO12: 0 | DP12: 0 | DQ12: 0 | DR12: 13 | DS12: 0 | DT12: 4 | DU12: 0 | DV12: 4 | DW12: 9 | DX12: 0 | DY12: 9 | DZ12: 0 | EA12: 0 | EB12: 0 | EC12: 0 | ED12: 0 | EE12: 0 | EF12: 0 | EG12: 67 | EH12: 67 | EI12: 67 | EJ12: 0 | EK12: 0 | EL12: 0 | EM12: 0 | EN12: 35 | EO12: 0 | EP12: 0 | EQ12: 35 | ER12: 0 | ES12: 0 | ET12: 0 | EU12: 0 | EV12: 0 | EW12: 0 | EX12: 0 | EY12: 0 | EZ12: 0 | FA12: 0 | FB12: 0
A13: 10 | B13: 成人非手术 | C13: 全科医学科 | D13: 1779935.8 | E13: 604848 | F13: 1175087.8 | G13: 3411 | H13: 75 | I13: 132 | J13: 0 | K13: 0 | L13: 37921.5 | M13: 48467.8 | N13: 0 | O13: 2908503.5 | P13: 2265453.7 | Q13: 2201044.4 | R13: 64409.34 | S13: 643049.78 | T13: 614396.95 | U13: 28652.83 | V13: 1412393.7 | W13: 1279667.4 | X13: 1258071.7 | Y13: 21595.68 | Z13: 132726.37 | AA13: 104073.54 | AB13: 28652.83 | AC13: 805793.73 | AD13: 750893.36 | AE13: 746243.68 | AF13: 4649.68 | AG13: 54900.37 | AH13: 48444.54 | AI13: 6455.83 | AJ13: 1752 | AK13: 1583 | AL13: 1583 | AM13: 0 | AN13: 169 | AO13: 126 | AP13: 43 | AQ13: 513570 | AR13: 443982 | AS13: 428671 | AT13: 15311 | AU13: 69588 | AV13: 48854 | AW13: 20734 | AX13: 91278 | AY13: 83209 | AZ13: 81574 | BA13: 1635 | BB13: 8069 | BC13: 6649 | BD13: 1420 | BE13: 1496109.7 | BF13: 985786.33 | BG13: 942972.67 | BH13: 42813.66 | BI13: 510323.41 | BJ13: 510323.41 | BK13: 0 | BL13: 225899.78 | BM13: 156775.99 | BN13: 154261.61 | BO13: 2514.38 | BP13: 69123.79 | BQ13: 69123.79 | BR13: 0 | BS13: 95122.16 | BT13: 55594.64 | BU13: 54839.36 | BV13: 755.28 | BW13: 39527.52 | BX13: 39527.52 | BY13: 0 | BZ13: 565618 | CA13: 369167 | CB13: 357918 | CC13: 11249 | CD13: 196451 | CE13: 196451 | CF13: 0 | CG13: 609469.8 | CH13: 404248.7 | CI13: 375953.7 | CJ13: 28295 | CK13: 205221.1 | CL13: 205221.1 | CM13: 0 | CN13: 0 | CO13: 1222825.7 | CP13: 162239.61 | CQ13: 2660.54 | CR13: 24667.92 | CS13: 0 | CT13: 0 | CU13: 0 | CV13: 3411 | CW13: 3123 | CX13: 3059 | CY13: 64 | CZ13: 288 | DA13: 236 | DB13: 52 | DC13: 3086 | DD13: 61 | DE13: 2832 | DF13: 2783 | DG13: 49 | DH13: 254 | DI13: 212 | DJ13: 42 | DK13: 238 | DL13: 211 | DM13: 202 | DN13: 9 | DO13: 27 | DP13: 19 | DQ13: 8 | DR13: 26 | DS13: 0 | DT13: 22 | DU13: 22 | DV13: 0 | DW13: 4 | DX13: 4 | DY13: 0 | DZ13: 0 | EA13: 0 | EB13: 0 | EC13: 0 | ED13: 0 | EE13: 0 | EF13: 0 | EG13: 75 | EH13: 50 | EI13: 47 | EJ13: 3 | EK13: 25 | EL13: 25 | EM13: 0 | EN13: 6 | EO13: 0 | EP13: 0 | EQ13: 6 | ER13: 0 | ES13: 0 | ET13: 0 | EU13: 0 | EV13: 0 | EW13: 0 | EX13: 0 | EY13: 0 | EZ13: 0 | FA13: 0 | FB13: 0
A14: 11 | B14: 成人手术 | C14: 普外科 | D14: 14792687 | E14: 2553220.5 | F14: 12239466 | G14: 11197 | H14: 1151 | I14: 175110.5 | J14: 123470 | K14: 0 | L14: 916504.75 | M14: 3773027.9 | N14: 3003 | O14: 31673731 | P14: 21547094 | Q14: 21055002 | R14: 492091.72 | S14: 10126637 | T14: 9717516.8 | U14: 409120.38 | V14: 4275525.2 | W14: 3580090.5 | X14: 3427570.6 | Y14: 152519.86 | Z14: 695434.78 | AA14: 549725.23 | AB14: 145709.55 | AC14: 1186994.3 | AD14: 973392.89 | AE14: 943987.05 | AF14: 29405.84 | AG14: 213601.4 | AH14: 189484.86 | AI14: 24116.54 | AJ14: 535310.46 | AK14: 490578.08 | AL14: 477013.06 | AM14: 13565.02 | AN14: 44732.38 | AO14: 35721.37 | AP14: 9011.01 | AQ14: 1822088 | AR14: 1501330 | AS14: 1431913 | AT14: 69417 | AU14: 320758 | AV14: 240327 | AW14: 80431 | AX14: 731132.5 | AY14: 614789.5 | AZ14: 574657.5 | BA14: 40132 | BB14: 116343 | BC14: 84192 | BD14: 32151 | BE14: 27398206 | BF14: 17967003 | BG14: 17627431 | BH14: 339571.86 | BI14: 9431202.4 | BJ14: 9167791.6 | BK14: 263410.83 | BL14: 4990311.1 | BM14: 3191183.1 | BN14: 3144610.8 | BO14: 46572.33 | BP14: 1799128 | BQ14: 1744128.6 | BR14: 54999.36 | BS14: 10168429 | BT14: 6773311.9 | BU14: 6667769.2 | BV14: 105542.78 | BW14: 3395116.6 | BX14: 3318879.9 | BY14: 76236.72 | BZ14: 4572319 | CA14: 2773131 | CB14: 2718023 | CC14: 55108 | CD14: 1799188 | CE14: 1740299 | CF14: 58889 | CG14: 7667147.1 | CH14: 5229377.2 | CI14: 5097028.5 | CJ14: 132348.75 | CK14: 2437769.9 | CL14: 2364484.1 | CM14: 73285.75 | CN14: 1140711.6 | CO14: 1346056.6 | CP14: 1075406.1 | CQ14: 576037.93 | CR14: 137273 | CS14: 0 | CT14: 129945.5 | CU14: 0 | CV14: 11197 | CW14: 9428 | CX14: 8983 | CY14: 445 | CZ14: 1769 | DA14: 1305 | DB14: 464 | DC14: 5569 | DD14: 21 | DE14: 4809 | DF14: 4576 | DG14: 233 | DH14: 760 | DI14: 532 | DJ14: 228 | DK14: 2937 | DL14: 2406 | DM14: 2302 | DN14: 104 | DO14: 531 | DP14: 409 | DQ14: 122 | DR14: 194 | DS14: 0 | DT14: 126 | DU14: 113 | DV14: 13 | DW14: 68 | DX14: 48 | DY14: 20 | DZ14: 2476 | EA14: 2068 | EB14: 1974 | EC14: 94 | ED14: 408 | EE14: 316 | EF14: 92 | EG14: 1151 | EH14: 813 | EI14: 803 | EJ14: 10 | EK14: 338 | EL14: 328 | EM14: 10 | EN14: 1010 | EO14: 762 | EP14: 0 | EQ14: 248 | ER14: 376 | ES14: 0 | ET14: 3 | EU14: 266 | EV14: 202 | EW14: 0 | EX14: 64 | EY14: 194 | EZ14: 194 | FA14: 0 | FB14: 379
A15: 12 | B15: 成人手术 | C15: 神经外科 | D15: 10008305 | E15: 689654 | F15: 9318651 | G15: 3295 | H15: 632 | I15: 537 | J15: 0 | K15: 0 | L15: 635143.25 | M15: 2756204 | N15: 0 | O15: 36684250 | P15: 20216003 | Q15: 19690013 | R15: 525989.89 | S15: 16468248 | T15: 15867837 | U15: 600410.93 | V15: 1045625.5 | W15: 808909.05 | X15: 757974.51 | Y15: 50934.54 | Z15: 236716.46 | AA15: 149251.52 | AB15: 87464.94 | AC15: 345565.51 | AD15: 285819.05 | AE15: 276771.51 | AF15: 9047.54 | AG15: 59746.46 | AH15: 43986.52 | AI15: 15759.94 | AJ15: 10406 | AK15: 8471 | AL15: 8084 | AM15: 387 | AN15: 1935 | AO15: 1204 | AP15: 731 | AQ15: 556861 | AR15: 430826 | AS15: 397012 | AT15: 33814 | AU15: 126035 | AV15: 76335 | AW15: 49700 | AX15: 132793 | AY15: 83793 | AZ15: 76107 | BA15: 7686 | BB15: 49000 | BC15: 27726 | BD15: 21274 | BE15: 35638625 | BF15: 19407094 | BG15: 18932038 | BH15: 475055.35 | BI15: 16231531 | BJ15: 15718585 | BK15: 512945.99 | BL15: 3639828.9 | BM15: 1943397.4 | BN15: 1874619.3 | BO15: 68778.1 | BP15: 1696431.5 | BQ15: 1638530 | BR15: 57901.57 | BS15: 22680145 | BT15: 12822802 | BU15: 12635459 | BV15: 187343 | BW15: 9857342.9 | BX15: 9635128 | BY15: 222214.92 | BZ15: 3615948 | CA15: 1865240 | CB15: 1800781 | CC15: 64459 | CD15: 1750708 | CE15: 1690209 | CF15: 60499 | CG15: 5702703 | CH15: 2775654.3 | CI15: 2621179 | CJ15: 154475.25 | CK15: 2927048.7 | CL15: 2754718.2 | CM15: 172330.5 | CN15: -50 | CO15: 537335.11 | CP15: 406826.83 | CQ15: 69212.97 | CR15: 32250.6 | CS15: 0 | CT15: 519104.78 | CU15: 0 | CV15: 3295 | CW15: 2423 | CX15: 2224 | CY15: 199 | CZ15: 872 | DA15: 524 | DB15: 348 | DC15: 1807 | DD15: 24 | DE15: 1485 | DF15: 1363 | DG15: 122 | DH15: 322 | DI15: 203 | DJ15: 119 | DK15: 1388 | DL15: 902 | DM15: 829 | DN15: 73 | DO15: 486 | DP15: 287 | DQ15: 199 | DR15: 76 | DS15: 0 | DT15: 14 | DU15: 11 | DV15: 3 | DW15: 62 | DX15: 34 | DY15: 28 | DZ15: 0 | EA15: 0 | EB15: 0 | EC15: 0 | ED15: 0 | EE15: 0 | EF15: 0 | EG15: 632 | EH15: 346 | EI15: 329 | EJ15: 17 | EK15: 286 | EL15: 270 | EM15: 16 | EN15: 548 | EO15: 247 | EP15: 157 | EQ15: 144 | ER15: 112 | ES15: 0 | ET15: 0 | EU15: 118 | EV15: 82 | EW15: 11 | EX15: 25 | EY15: 273 | EZ15: 127 | FA15: 146 | FB15: 254
... A66: 63 | B66: 其他 | C66: 临床药物试验办公室GCP | D66: 55044 | E66: 55044 | F66: 0 | G66: 194 | H66: 0 | I66: 0 | J66: 0 | K66: 0 | L66: 0 | M66: 0 | N66: 0 | O66: 57314.82 | P66: 33600.79 | Q66: 0 | R66: 33600.79 | S66: 23714.03 | T66: 0 | U66: 23714.03 | V66: 57314.82 | W66: 33600.79 | X66: 0 | Y66: 33600.79 | Z66: 23714.03 | AA66: 0 | AB66: 23714.03 | AC66: 2232.82 | AD66: 434.79 | AE66: 0 | AF66: 434.79 | AG66: 1798.03 | AH66: 0 | AI66: 1798.03 | AJ66: 38 | AK66: 38 | AL66: 0 | AM66: 38 | AN66: 0 | AO66: 0 | AP66: 0 | AQ66: 50194 | AR66: 30253 | AS66: 0 | AT66: 30253 | AU66: 19941 | AV66: 0 | AW66: 19941 | AX66: 4850 | AY66: 2875 | AZ66: 0 | BA66: 2875 | BB66: 1975 | BC66: 0 | BD66: 1975 | BE66: 0 | BF66: 0 | BG66: 0 | BH66: 0 | BI66: 0 | BJ66: 0 | BK66: 0 | BL66: 0 | BM66: 0 | BN66: 0 | BO66: 0 | BP66: 0 | BQ66: 0 | BR66: 0 | BS66: 0 | BT66: 0 | BU66: 0 | BV66: 0 | BW66: 0 | BX66: 0 | BY66: 0 | BZ66: 0 | CA66: 0 | CB66: 0 | CC66: 0 | CD66: 0 | CE66: 0 | CF66: 0 | CG66: 0 | CH66: 0 | CI66: 0 | CJ66: 0 | CK66: 0 | CL66: 0 | CM66: 0 | CN66: 0 | CO66: 0 | CP66: 0 | CQ66: 57314.82 | CR66: 0 | CS66: 0 | CT66: 0 | CU66: 0 | CV66: 194 | CW66: 115 | CX66: 0 | CY66: 115 | CZ66: 79 | DA66: 0 | DB66: 79 | DC66: 194 | DD66: 0 | DE66: 115 | DF66: 0 | DG66: 115 | DH66: 79 | DI66: 0 | DJ66: 79 | DK66: 0 | DL66: 0 | DM66: 0 | DN66: 0 | DO66: 0 | DP66: 0 | DQ66: 0 | DR66: 0 | DS66: 0 | DT66: 0 | DU66: 0 | DV66: 0 | DW66: 0 | DX66: 0 | DY66: 0 | DZ66: 0 | EA66: 0 | EB66: 0 | EC66: 0 | ED66: 0 | EE66: 0 | EF66: 0 | EG66: 0 | EH66: 0 | EI66: 0 | EJ66: 0 | EK66: 0 | EL66: 0 | EM66: 0 | EN66: 0 | EO66: 0 | EP66: 0 | EQ66: 0 | ER66: 0 | ES66: 0 | ET66: 0 | EU66: 0 | EV66: 0 | EW66: 0 | EX66: 0 | EY66: 0 | EZ66: 0 | FA66: 0 | FB66: 0
A67: 64 | C67: 其它 | D67: 67.5 | E67: 0 | F67: 67.5 | G67: 188 | H67: 74 | I67: 0 | J67: 0 | K67: 0 | L67: 0 | M67: 0 | N67: 0 | O67: 67.5 | P67: 0 | Q67: 0 | R67: 0 | S67: 67.5 | T67: 0 | U67: 67.5 | V67: 0 | W67: 0 | X67: 0 | Y67: 0 | Z67: 0 | AA67: 0 | AB67: 0 | AC67: 0 | AD67: 0 | AE67: 0 | AF67: 0 | AG67: 0 | AH67: 0 | AI67: 0 | AJ67: 0 | AK67: 0 | AL67: 0 | AM67: 0 | AN67: 0 | AO67: 0 | AP67: 0 | AQ67: 0 | AR67: 0 | AS67: 0 | AT67: 0 | AU67: 0 | AV67: 0 | AW67: 0 | AX67: 0 | AY67: 0 | AZ67: 0 | BA67: 0 | BB67: 0 | BC67: 0 | BD67: 0 | BE67: 67.5 | BF67: 0 | BG67: 0 | BH67: 0 | BI67: 67.5 | BJ67: 0 | BK67: 67.5 | BL67: 0 | BM67: 0 | BN67: 0 | BO67: 0 | BP67: 0 | BQ67: 0 | BR67: 0 | BS67: 0 | BT67: 0 | BU67: 0 | BV67: 0 | BW67: 0 | BX67: 0 | BY67: 0 | BZ67: 0 | CA67: 0 | CB67: 0 | CC67: 0 | CD67: 0 | CE67: 0 | CF67: 0 | CG67: 67.5 | CH67: 0 | CI67: 0 | CJ67: 0 | CK67: 67.5 | CL67: 0 | CM67: 67.5 | CN67: 0 | CO67: 0 | CP67: 0 | CQ67: 250 | CR67: 0 | CS67: 0 | CT67: 0 | CU67: 0 | CV67: 188 | CW67: 60 | CX67: 9 | CY67: 51 | CZ67: 128 | DA67: 0 | DB67: 128 | DC67: 188 | DD67: 0 | DE67: 60 | DF67: 9 | DG67: 51 | DH67: 128 | DI67: 0 | DJ67: 128 | DK67: 0 | DL67: 0 | DM67: 0 | DN67: 0 | DO67: 0 | DP67: 0 | DQ67: 0 | DR67: 0 | DS67: 0 | DT67: 0 | DU67: 0 | DV67: 0 | DW67: 0 | DX67: 0 | DY67: 0 | DZ67: 0 | EA67: 0 | EB67: 0 | EC67: 0 | ED67: 0 | EE67: 0 | EF67: 0 | EG67: 74 | EH67: 50 | EI67: 48 | EJ67: 2 | EK67: 24 | EL67: 23 | EM67: 1 | EN67: 0 | EO67: 0 | EP67: 0 | EQ67: 0 | ER67: 0 | ES67: 0 | ET67: 0 | EU67: 0 | EV67: 0 | EW67: 0 | EX67: 0 | EY67: 0 | EZ67: 0 | FA67: 0 | FB67: 0

Sheet 当年累计数据表奉贤
A1: 日期范围：20260401-20260430 | D1: 25 | O1: 1=2+5=8+43 | P1: 2=3+4 | Q1: 3 | R1: 4 | S1: 5=6+7 | T1: 6 | U1: 7 | V1: 8=9+12=15+22+29+36 | W1: 9=10+11 | X1: 10 | Y1: 11 | Z1: 12=13+14 | AA1: 13 | AB1: 14 | AC1: 15=16+19 | AD1: 16=17+18 | AE1: 17 | AF1: 18 | AG1: 19=20+21 | AH1: 20 | AI1: 21 | AJ1: 22=23+26 | AK1: 23=24+25 | AL1: 24 | AM1: 25 | AN1: 26=27+28 | AO1: 27 | AP1: 28 | AQ1: 29=30+33 | AR1: 30=31+32 | AS1: 31 | AT1: 32 | AU1: 33=34+35 | AV1: 34 | AW1: 35 | AX1: 36=37+40 | AY1: 37=38+39 | AZ1: 38 | BA1: 39 | BB1: 40=41+42 | BC1: 41 | BD1: 42 | BE1: 43=50+57+64+71=44+47 | BF1: 44=45+46 | BG1: 45 | BH1: 46 | BI1: 47=48+49 | BJ1: 48 | BK1: 49 | BL1: 50=51+54 | BM1: 51=52+53 | BN1: 52 | BO1: 53 | BP1: 54=55+56 | BQ1: 55 | BR1: 56 | BS1: 57=58+61 | BT1: 58=59+60 | BU1: 59 | BV1: 60 | BW1: 61=62+63 | BX1: 62 | BY1: 63 | BZ1: 64=65+68 | CA1: 65=66+67 | CB1: 66 | CC1: 67 | CD1: 68=69+70 | CE1: 69 | CF1: 70 | CG1: 71=72+75 | CH1: 72=73+74 | CI1: 73 | CJ1: 74 | CK1: 75=76+77 | CL1: 76 | CM1: 77 | CV1: 78=85+93+100+108+86+101=79+82 | CW1: 79=80+81 | CX1: 80 | CY1: 81 | CZ1: 82=83+84 | DA1: 83 | DB1: 84 | DC1: 85=87+90=78-93-100-108-86-101 | DD1: 86 | DE1: 87=88+89 | DF1: 88 | DG1: 89 | DH1: 90=91+92 | DI1: 91 | DJ1: 92 | DK1: 93=94+97 | DL1: 94=95+96 | DM1: 95 | DN1: 96 | DO1: 97=98+99 | DP1: 98 | DQ1: 99 | DR1: 100=102+105 | DS1: 101 | DT1: 102=103+104 | DU1: 103 | DV1: 104 | DW1: 105=106+107 | DX1: 106 | DY1: 107 | DZ1: 108=109+112 | EA1: 109=110+111 | EB1: 110 | EC1: 111 | ED1: 112=113+114 | EE1: 113 | EF1: 114 | EG1: 115=116+119 | EH1: 116=117+118 | EI1: 117 | EJ1: 118 | EK1: 119=120+121 | EL1: 120 | EM1: 121 | EN1: 122=123+124+125 | EO1: 123 | EP1: 124 | EQ1: 125 | EU1: 126=127+128+129 | EV1: 127 | EW1: 128 | EX1: 129 | EY1: 130=131+132 | EZ1: 131 | FA1: 132 | FB1: 133
A2: 序号 | B2: 科室类别 | C2: 科室名称 | D2: 医疗收入不含药耗 | E2: 门急诊收入不含药耗 | F2: 住院收入不含药耗 | G2: 门急诊人次 | H2: 住院人次 | I2: 门急诊治疗收入 | J2: 门急诊手术收入 | K2: 门诊中药饮片收入 | L2: 住院治疗收入 | M2: 住院手术收入 | N2: 住院中药饮片收入 | O2: 医疗收入 | P2: 其中本地病人医疗收入 | Q2: 其中本地病人医保医疗收入 | R2: 其中本地病人自费医疗收入 | S2: 其中异地病人医疗收入 | T2: 其中异地病人医保医疗收入 | U2: 其中异地病人自费医疗收入 | V2: 门急诊收入 | W2: 其中本地病人医疗收入 | X2: 其中本地病人医保医疗收入 | Y2: 其中本地病人自费医疗收入 | Z2: 其中异地病人医疗收入 | AA2: 其中异地病人医保医疗收入 | AB2: 其中异地病人自费医疗收入 | AC2: 门急诊药品收入 | AD2: 其中本地病人医疗收入 | AE2: 其中本地病人医保医疗收入 | AF2: 其中本地病人自费医疗收入 | AG2: 其中异地病人医疗收入 | AH2: 其中异地病人医保医疗收入 | AI2: 其中异地病人自费医疗收入 | AJ2: 门急诊耗材收入 | AK2: 其中本地病人医疗收入 | AL2: 其中本地病人医保医疗收入 | AM2: 其中本地病人自费医疗收入 | AN2: 其中异地病人医疗收入 | AO2: 其中异地病人医保医疗收入 | AP2: 其中异地病人自费医疗收入 | AQ2: 门急诊检查化验收入 | AR2: 其中本地病人医疗收入 | AS2: 其中本地病人医保医疗收入 | AT2: 其中本地病人自费医疗收入 | AU2: 其中异地病人医疗收入 | AV2: 其中异地病人医保医疗收入 | AW2: 其中异地病人自费医疗收入 | AX2: 门急诊劳务收入 | AY2: 其中本地病人医疗收入 | AZ2: 其中本地病人医保医疗收入 | BA2: 其中本地病人自费医疗收入 | BB2: 其中异地病人医疗收入 | BC2: 其中异地病人医保医疗收入 | BD2: 其中异地病人自费医疗收入 | BE2: 住院收入 | BF2: 其中本地病人医疗收入 | BG2: 其中本地病人医保医疗收入 | BH2: 其中本地病人自费医疗收入 | BI2: 其中异地病人医疗收入 | BJ2: 其中异地病人医保医疗收入 | BK2: 其中异地病人自费医疗收入 | BL2: 住院药品收入 | BM2: 其中本地病人医疗收入 | BN2: 其中本地病人医保医疗收入 | BO2: 其中本地病人自费医疗收入 | BP2: 其中异地病人医疗收入 | BQ2: 其中异地病人医保医疗收入 | BR2: 其中异地病人自费医疗收入 | BS2: 住院耗材收入 | BT2: 其中本地病人医疗收入 | BU2: 其中本地病人医保医疗收入 | BV2: 其中本地病人自费医疗收入 | BW2: 其中异地病人医疗收入 | BX2: 其中异地病人医保医疗收入 | BY2: 其中异地病人自费医疗收入 | BZ2: 住院检查化验收入 | CA2: 其中本地病人医疗收入 | CB2: 其中本地病人医保医疗收入 | CC2: 其中本地病人自费医疗收入 | CD2: 其中异地病人医疗收入 | CE2: 其中异地病人医保医疗收入 | CF2: 其中异地病人自费医疗收入 | CG2: 住院劳务收入 | CH2: 其中本地病人医疗收入 | CI2: 其中本地病人医保医疗收入 | CJ2: 其中本地病人自费医疗收入 | CK2: 其中异地病人医疗收入 | CL2: 其中异地病人医保医疗收入 | CM2: 其中异地病人自费医疗收入 | CN2: 急诊收入 | CO2: 普通门诊收入 | CP2: 专家门诊收入 | CQ2: 专病门诊收入 | CR2: 特需门诊收入 | CS2: MDT门诊收入 | CT2: 镜朗诊疗部收入 | CU2: 特需病房收入 | CV2: 门急诊人次 | CW2: 其中本地病人人次 | CX2: 其中本地病人医保人次 | CY2: 其中本地病人自费人次 | CZ2: 其中异地病人人次 | DA2: 其中异地病人医保人次 | DB2: 其中异地病人自费人次 | DC2: 普通门诊 (普通+专病) | DD2: 互联网普通门诊人次 | DE2: 其中本地病人人次 | DF2: 其中本地病人医保人次 | DG2: 其中本地病人自费人次 | DH2: 其中异地病人人次 | DI2: 其中异地病人医保人次 | DJ2: 其中异地病人自费人次 | DK2: 专家门诊 | DL2: 其中本地病人人次 | DM2: 其中本地病人医保人次 | DN2: 其中本地病人自费人次 | DO2: 其中异地病人人次 | DP2: 其中异地病人医保人次 | DQ2: 其中异地病人自费人次 | DR2: 特需门诊 (特需+MDT) | DS2: 互联网特需门诊人次 | DT2: 其中本地病人人次 | DU2: 其中本地病人医保人次 | DV2: 其中本地病人自费人次 | DW2: 其中异地病人人次 | DX2: 其中异地病人医保人次 | DY2: 其中异地病人自费人次 | DZ2: 急诊人次 | EA2: 其中本地病人人次 | EB2: 其中本地病人医保人次 | EC2: 其中本地病人自费人次 | ED2: 其中异地病人人次 | EE2: 其中异地病人医保人次 | EF2: 其中异地病人自费人次 | EG2: 住院人次 | EH2: 其中本地病人人次 | EI2: 其中本地病人医保人次 | EJ2: 其中本地病人自费人次 | EK2: 其中异地病人人次 | EL2: 其中异地病人医保人次 | EM2: 其中异地病人自费人次 | EN2: 手术人次与操作人次 | EO2: 手术人次 | EP2: 介入人次 | EQ2: 操作人次(治疗+诊断) | ER2: 微创手术人次（手术） | ES2: 微创手术人次（介入） | ET2: 微创手术人次（操作） | EU2: 三级手术 | EV2: 三级手术(手术) | EW2: 三级手术(介入) | EX2: 三级手术(操作) | EY2: 四级手术 | EZ2: 四级手术(手术) | FA2: 四级手术(介入) | FB2: 重点病种人次
A3: 小计： | D3: 63035641 | E3: 26460446 | F3: 36575196 | G3: 96874 | H3: 3626 | I3: 3975904.1 | J3: 1220362.2 | K3: 449634.74 | L3: 2637791.4 | M3: 11101801 | N3: 3234.33 | O3: 1.4595393e+08 | P3: 1.0799713e+08 | Q3: 99873532 | R3: 8123601.5 | S3: 37956801 | T3: 33982810 | U3: 3973990.4 | V3: 44517237 | W3: 38292509 | X3: 34983354 | Y3: 3309155.6 | Z3: 6224727.8 | AA3: 3987539.8 | AB3: 2237188.1 | AC3: 16038423 | AD3: 14065901 | AE3: 13302765 | AF3: 763135.7 | AG3: 1972522.2 | AH3: 1430608.1 | AI3: 541914.15 | AJ3: 2018368.7 | AK3: 1794913.1 | AL3: 1466583.2 | AM3: 328329.87 | AN3: 223455.64 | AO3: 140656.47 | AP3: 82799.17 | AQ3: 17326586 | AR3: 14770406 | AS3: 13462756 | AT3: 1307650 | AU3: 2556180 | AV3: 1577459 | AW3: 978721 | AX3: 9133859.2 | AY3: 7661289.2 | AZ3: 6751249.2 | BA3: 910039.99 | BB3: 1472570 | BC3: 838816.25 | BD3: 633753.76 | BE3: 1.014367e+08 | BF3: 69704624 | BG3: 64890178 | BH3: 4814445.9 | BI3: 31732073 | BJ3: 29995271 | BK3: 1736802.4 | BL3: 11351020 | BM3: 6961777.4 | BN3: 6515567.6 | BO3: 446209.81 | BP3: 4389242.5 | BQ3: 4155953.8 | BR3: 233288.72 | BS3: 53510482 | BT3: 37626985 | BU3: 34846189 | BV3: 2780796.4 | BW3: 15883496 | BX3: 14961163 | BY3: 922333.53 | BZ3: 14330608 | CA3: 9832429 | CB3: 9381494 | CC3: 450935 | CD3: 4498179.5 | CE3: 4285196.5 | CF3: 212983 | CG3: 22244587 | CH3: 15283432 | CI3: 14146928 | CJ3: 1136504.6 | CK3: 6961154.8 | CL3: 6592957.7 | CM3: 368197.1 | CN3: 8821136.2 | CO3: 15814905 | CP3: 13122985 | CQ3: 4866573.9 | CR3: 1891036.1 | CS3: 516 | CT3: 384522.6 | CU3: 0 | CV3: 96874 | CW3: 83352 | CX3: 74886 | CY3: 8466 | CZ3: 13522 | DA3: 7980 | DB3: 5542 | DC3: 49568 | DD3: 0 | DE3: 43086 | DF3: 39214 | DG3: 3872 | DH3: 6482 | DI3: 3708 | DJ3: 2774 | DK3: 27179 | DL3: 22567 | DM3: 20273 | DN3: 2294 | DO3: 4612 | DP3: 2842 | DQ3: 1770 | DR3: 2458 | DS3: 0 | DT3: 1894 | DU3: 1679 | DV3: 215 | DW3: 564 | DX3: 272 | DY3: 292 | DZ3: 17669 | EA3: 15805 | EB3: 13720 | EC3: 2085 | ED3: 1864 | EE3: 1158 | EF3: 706 | EG3: 3626 | EH3: 2561 | EI3: 2408 | EJ3: 153 | EK3: 1065 | EL3: 1013 | EM3: 52 | EN3: 3022 | EO3: 1849 | EP3: 283 | EQ3: 890 | ER3: 578 | ES3: 0 | ET3: 56 | EU3: 945 | EV3: 759 | EW3: 132 | EX3: 54 | EY3: 675 | EZ3: 581 | FA3: 94 | FB3: 1237
