Workbook

Sheet 饼图
D1: 1月
F2: 自动 | I2: 自动 | J2: 自动 | K2: 自动
C3: 项 目 | D3: 2026年 | E3: 占 比 % | F3: 奉贤 | G3: 占 比 % | H3: 2025年 | I3: 占 比 % | J3: 增减额 | K3: 增减率
C4: 人员经费 | D4: 24327 | E4: 0.34595694 | F4: 6393 | G4: 0.36775196 | H4: 21579 | I4: 0.37453138 | J4: 2748 | K4: 0.12734603 | M4: =E4-I4
C5: 药品费 | D5: 16495 | E5: 0.23457721 | F5: 2771 | G5: 0.15939945 | H5: 13387 | I5: 0.23234865 | J5: 3108 | K5: 0.23216553 | M5: =E5-I5
C6: 耗材费 | D6: 22400 | E6: 0.31855286 | F6: 6605 | G6: 0.37994708 | H6: 16986 | I6: 0.29481394 | J6: 5414 | K6: 0.31873307 | M6: =E6-I6
C7: 折旧/摊销 | D7: 1120 | E7: 0.015927643 | F7: 178 | G7: 0.010239301 | H7: 1078 | I7: 0.018710081 | J7: 42 | K7: 0.038961039 | M7: =E7-I7
C8: 风险基金 | D8: 103 | E8: 0.0014647743 | F8: 22 | G8: 0.0012655315 | H8: 77 | I8: 0.0013364343 | J8: 26 | K8: 0.33766234 | L8: 自动 | M8: =E9-I9
C9: 其他费用 | D9: 5873 | E9: 0.083520578 | F9: 1415 | G9: 0.081396687 | H9: 4509 | I9: 0.078259511 | J9: 1364 | K9: 0.3025061
C10: 医疗成本合计 | D10: 70318 | E10: 1 | F10: 17384 | G10: 1 | H10: 57616 | I10: 1 | J10: 12702 | K10: 0.22045959 | L10: 自动 | M10: =E9-I9
L13: 自动 | P13: 2025年 | R13: 2024年
K14: 人员经费 | L14: =E4 | O14: 医疗风险基金 | P14: 78 | R14: 78
K15: 药品费 | L15: =E5 | O15: 能源费 | P15: 516 | R15: 472
K16: 耗材费 | L16: =E6 | O16: 物业管理费 | R16: 624
K17: 折旧/摊销 | L17: =E7 | O17: 维修护费 | R17: 1353
K18: 其他费用 | L18: =E9 | O18: 劳务费 | R18: 354
O24: 其他 | P24: =P25-P14-P15-P16-P17-P18-P19-P20-P21-P22-P23 | R24: =R25-R14-R15-R16-R17-R18-R19-R20-R21-R22-R23
C25: 2024年 | D25: 2023年 | F25: 增减额 | H25: 增减率 | O25: 总计 | P25: 4586 | R25: 4124
B26: 项 目 | C26: 1-9月 | D26: 1-9月
C27: 498726 | D27: 451737 | F27: =C27-D27 | H27: =C27/D27-1
B28: 医疗成本 | C28: 143587 | D28: 127531 | F28: =C28-D28 | H28: =C28/D28-1
B29: 其中：工资总额 | C29: 3802 | D29: 3829 | F29: =C29-D29 | H29: =C29/D29-1
B30: 其他费用 | C30: =C27+C29 | D30: =D27+D29 | F30: =C30-D30 | H30: =C30/D30-1
B31: 小 计

Sheet 医疗成本
B3: 项 目 | C3: 2026年 | D3: 占 比% | E3: 奉贤院区 | F3: 占 比% | G3: 2025年 | H3: 占 比% | I3: 增减额 | J3: 增减率 | K3: 46082
C4: 5月 | G4: 5月
B5: 人员经费 | C5: =ROUND(当月附表3!B7/10000,0) | D5: =C5/C$11 | E5: =ROUND(当月奉贤附表3!B7/10000,0) | F5: =E5/E$11 | G5: =ROUND(上年同期附表3!B7/10000,0) | H5: =G5/G$11 | I5: =C5-G5 | J5: =I5/G5 | K5: =ROUND(当月附表3!B7/10000,0)
B6: 药品费 | C6: =ROUND(当月附表3!B47/10000,0) | D6: =C6/C$11 | E6: =ROUND(当月奉贤附表3!B47/10000,0) | F6: =E6/E$11 | G6: =ROUND(上年同期附表3!B47/10000,0) | H6: =G6/G$11 | I6: =C6-G6 | J6: =I6/G6 | K6: =ROUND(当月附表3!B47/10000,0)
B7: 卫生材料费 | C7: =ROUND(当月附表3!B33/10000,0) | D7: =C7/C$11 | E7: =ROUND(当月奉贤附表3!B33/10000,0) | F7: =E7/E$11 | G7: =ROUND(上年同期附表3!B33/10000,0) | H7: =G7/G$11 | I7: =C7-G7 | J7: =I7/G7 | K7: =ROUND(当月附表3!B33/10000,0)
B8: 折旧/摊销 | C8: =C11-C10-C7-C6-C5-C9 | D8: =C8/C$11 | E8: =E11-E10-E7-E6-E5-E9 | F8: =E8/E$11 | G8: =G11-G10-G7-G6-G5-G9 | H8: =G8/G$11 | I8: =C8-G8 | J8: =I8/G8 | K8: =K11-K10-K7-K6-K5-K9
B9: 医疗风险基金 | C9: =ROUND(当月附表3!B53/10000,0) | D9: =C9/C$11 | E9: =ROUND(当月奉贤附表3!B53/10000,0) | F9: =E9/E$11 | G9: =ROUND(上年同期附表3!B53/10000,0) | H9: =G9/G$11 | I9: =C9-G9 | J9: =I9/G9 | K9: =ROUND(当月附表3!B53/10000,0)
B10: 商品和服务费 | C10: =ROUND(当月附表3!B54/10000,0) | D10: =C10/C$11 | E10: =ROUND(当月奉贤附表3!B54/10000,0) | F10: =E10/E$11 | G10: =ROUND(上年同期附表3!B54/10000,0) | H10: =G10/G$11 | I10: =C10-G10 | J10: =I10/G10 | K10: =ROUND(当月附表3!B54/10000,0)
B11: 医疗成本合计 | C11: =ROUND(当月附表3!B6/10000,0) | D11: 1 | E11: =ROUND(当月奉贤附表3!B6/10000,0) | F11: 1 | G11: =ROUND(上年同期附表3!B6/10000,0) | H11: 1 | I11: =C11-G11 | J11: =I11/G11 | K11: =ROUND(当月附表3!B6/10000,0)

Sheet 人员经费
B3: 项 目 | C3: 46143 | D3: 其中 | E3: 45778 | F3: 增减额 | G3: 增减率
D4: 奉贤院区
B5: 医疗服务收入 | C5: =ROUND((当年累计数据表!AQ3+当年累计数据表!AX3+当年累计数据表!BZ3+当年累计数据表!CG3)/10000,0) | D5: =ROUND((当年累计数据表奉贤!AQ3+当年累计数据表奉贤!AX3+当年累计数据表奉贤!BZ3+当年累计数据表奉贤!CG3)/10000,0) | E5: =ROUND((去年累计数据表!AQ3+去年累计数据表!AX3+去年累计数据表!BZ3+去年累计数据表!CG3)/10000,0) | F5: =C5-E5 | G5: =F5/E5
B6: 人员经费 | C6: =医疗成本!C5 | D6: =医疗成本!E5 | E6: =医疗成本!G5 | F6: =医疗成本!I5 | G6: =医疗成本!J5
B7: 其中：工资总额 | C7: =ROUND((当月附表3!B9+当月附表3!B10+当月附表3!B11+当月附表3!B12+当月附表3!B13+当月附表3!B20)/10000,0) | D7: =ROUND((当月奉贤附表3!B9+当月奉贤附表3!B10+当月奉贤附表3!B11+当月奉贤附表3!B12+当月奉贤附表3!B13+当月奉贤附表3!B20)/10000,0) | E7: =ROUND((上年同期附表3!B9+上年同期附表3!B10+上年同期附表3!B11+上年同期附表3!B12+上年同期附表3!B13+上年同期附表3!B20)/10000,0) | F7: =C7-E7 | G7: =F7/E7
B8: 其中：基本工资等 | C8: =ROUND((当月附表3!B9+当月附表3!B10+当月附表3!B11+当月附表3!B12+当月附表3!B20)/10000,0) | D8: =ROUND((当月奉贤附表3!B9+当月奉贤附表3!B10+当月奉贤附表3!B11+当月奉贤附表3!B12+当月奉贤附表3!B20)/10000,0) | E8: =ROUND((上年同期附表3!B9+上年同期附表3!B10+上年同期附表3!B11+上年同期附表3!B12+上年同期附表3!B20)/10000,0) | F8: =C8-E8 | G8: =F8/E8
B9: 绩效工资 | C9: =C7-C8 | D9: =D7-D8 | E9: =E7-E8 | F9: =C9-E9 | G9: =F9/E9
B10: 社保公积金 | C10: =ROUND((当月附表3!B14+当月附表3!B15+当月附表3!B16+当月附表3!B17+当月附表3!B18)/10000,0) | D10: =ROUND((当月奉贤附表3!B14+当月奉贤附表3!B15+当月奉贤附表3!B16+当月奉贤附表3!B17+当月奉贤附表3!B18)/10000,0) | E10: =ROUND((上年同期附表3!B14+上年同期附表3!B15+上年同期附表3!B16+上年同期附表3!B17+上年同期附表3!B18)/10000,0) | F10: =C10-E10 | G10: =F10/E10

Sheet 水电煤
B2: 项 目 | C2: 46143 | D2: 其中 | E2: 45778 | F2: 增减额 | G2: 增减率
D3: 奉贤院区
B4: 能耗成本 | C4: =C5+C6+C7 | D4: =D5+D6+D7 | E4: =E5+E6+E7 | F4: =C4-E4 | G4: =F4/E4
B5: 其中：水费 | C5: =ROUND(当月附表3!B59/10000,0) | D5: =ROUND(当月奉贤附表3!B59/10000,0) | E5: =ROUND(上年同期附表3!B59/10000,0) | F5: =C5-E5 | G5: =F5/E5
B6: 电费 | C6: =ROUND(当月附表3!B60/10000,0) | D6: =ROUND(当月奉贤附表3!B60/10000,0) | E6: =ROUND(上年同期附表3!B60/10000,0) | F6: =C6-E6 | G6: =F6/E6
B7: 燃气费 | C7: =ROUND(当月附表3!B72/10000,0) | D7: =ROUND(当月奉贤附表3!B72/10000,0) | E7: =ROUND(上年同期附表3!B72/10000,0) | F7: =C7-E7 | G7: =F7/E7

Sheet 预算完成情况
B2: 项 目 | C2: 执行率指标 | J2: 年终
C3: 核定数 | D3: 执行数 | E3: 执行率 | F3: 与时间节点比较 | H3: 0.333 | J3: 17532 | K3: =J3*(1-H3)
B4: 医疗收入 | C4: 750000 | D4: =收支结余!C4 | E4: =D4/C4 | F4: =E4-$H$3 | K4: =D6-K3 | L4: =K4/C6
B5: 医疗成本 | C5: 768743 | D5: =收支结余!C6 | E5: =D5/C5 | F5: =E5-$H$3
B6: 工资总额 | C6: 225000 | D6: =人员经费!C7 | E6: =D6/C6 | F6: =E6-$H$3

Sheet 收支结余
B2: 项 目 | C2: 46143 | D2: 其中 | E2: 45778 | F2: 增减额 | G2: 增减率
D3: 奉贤院区
B4: 医疗收入 | C4: =ROUND(当年累计数据表!O3/10000,0) | D4: =ROUND(当年累计数据表奉贤!O3/10000,0) | E4: =ROUND(去年累计数据表!O3/10000,0) | F4: =C4-E4 | G4: =F4/E4
B5: 加：财政基本拨款收入 | C5: 2502 | D5: 0 | E5: 2411 | F5: =C5-E5 | G5: =F5/E5
B6: 减：医疗成本 | C6: =医疗成本!C11 | D6: =医疗成本!E11 | E6: =医疗成本!G11 | F6: =C6-E6 | G6: =F6/E6
B7: 医疗服务盈余 | C7: =C4+C5-C6 | D7: =D4+D5-D6 | E7: =E4+E5-E6 | F7: =C7-E7 | G7: =F7/E7
B8: 其他盈余 | C8: =C9-C7 | D8: =D9-D7 | E8: =E9-E7 | F8: =C8-E8 | G8: -
B9: 收支结余 | C9: =ROUND(当月附表1!B5/10000,0) | D9: =ROUND(当月奉贤附表1!B5/10000,0) | E9: =ROUND(上年同期附表1!B5/10000,0) | F9: =C9-E9 | G9: -
B16: 项 目 | C16: 46113 | D16: 45748 | E16: 增减额 | F16: 增减率
B17: 新华医疗开发公司 | E17: =C17-D17 | F17: =E17/D17

Sheet 商品服务
B2: 项 目 | C2: 46143 | D2: 其中 | E2: 45778 | F2: 增减额 | G2: 增减率
D3: 奉贤院区
B4: 商品服务 | C4: =ROUND(当月附表3!B54/10000,0) | D4: =ROUND(当月奉贤附表3!B54/10000,0) | E4: =ROUND(上年同期附表3!B54/10000,0) | F4: =C4-E4 | G4: =F4/E4
B5: 其中：能源成本 | C5: =水电煤!C4 | D5: =水电煤!D4 | E5: =水电煤!E4 | F5: =C5-E5 | G5: =F5/E5
B6: 维修护费 | C6: 683 | D6: 183 | E6: 719 | F6: =C6-E6 | G6: =F6/E6
B7: 物业管理费 | C7: 1182 | D7: 388 | E7: 729 | F7: =C7-E7 | G7: =F7/E7
B8: 委托业务费 | C8: =ROUND(当月附表3!B74/10000,0) | D8: =ROUND(当月奉贤附表3!B74/10000,0) | E8: =ROUND(上年同期附表3!B74/10000,0) | F8: =C8-E8 | G8: =F8/E8
B9: 劳务费 | C9: =ROUND(当月附表3!B73/10000,0) | D9: =ROUND(当月奉贤附表3!B73/10000,0) | E9: =ROUND(上年同期附表3!B73/10000,0) | F9: =C9-E9 | G9: =F9/E9
B10: 专用材料费 | C10: =ROUND(当月附表3!B71/10000,0) | D10: =ROUND(当月奉贤附表3!B71/10000,0) | E10: =ROUND(上年同期附表3!B71/10000,0) | F10: =C10-E10 | G10: =F10/E10
B11: 供应室外包成本 | C11: 470 | D11: 104 | E11: 575 | F11: =C11-E11 | G11: =F11/E11
B12: 租赁费 | C12: =ROUND(当月附表3!B67/10000,0) | D12: =ROUND(当月奉贤附表3!B67/10000,0) | E12: =ROUND(上年同期附表3!B67/10000,0) | F12: =C12-E12 | G12: =F12/E12
B13: 其他 | C13: =C4-C5-C6-C7-C8-C9-C10-C11-C12 | D13: =D4-D5-D6-D7-D8-D9-D10-D11-D12 | E13: =E4-E5-E6-E7-E8-E9-E10-E11-E12 | F13: =C13-E13 | G13: =F13/E13
C24: =C11+C13 | D24: =D11+D13 | E24: =E11+E13 | F24: =F11+F13 | G24: =F24/E24

Sheet 物业管理
B3: 项 目 | C3: 46143 | D3: 其中 | E3: 45778 | F3: 增减额 | G3: 增减率 | I3: 项 目 | J3: 46143 | K3: 其中 | L3: 45778 | M3: 增减额 | N3: 增减率
D4: 奉贤院区 | K4: 奉贤院区
B5: 物业管理费 | C5: =商品服务!C7 | D5: =商品服务!D7 | E5: =商品服务!E7 | F5: =C5-E5 | G5: =F5/E5 | I5: 物业管理费 | J5: =商品服务!C7 | K5: =商品服务!D7 | L5: =商品服务!E7 | M5: =J5-L5 | N5: =M5/L5
B6: 其中： 电梯驾驶服务 | C6: 58 | D6: 26 | E6: 0 | F6: =C6-E6 | G6: =F6/E6 | I6: 其中： 电梯驾驶服务 | J6: 58 | K6: 26 | L6: 0 | M6: =J6-L6 | N6: =M6/L6
B7: 保安管理 | C7: 197 | D7: 58 | E7: 145 | F7: =C7-E7 | G7: =F7/E7 | I7: 保安管理 | J7: 197 | K7: 58 | L7: 145 | M7: =J7-L7 | N7: =M7/L7
B8: 运送服务费 | C8: 212 | D8: 87 | E8: 78 | F8: =C8-E8 | G8: =F8/E8 | I8: 运送服务费 | J8: 212 | K8: 87 | L8: 78 | M8: =J8-L8 | N8: =M8/L8
B9: 保洁服务 | C9: 481 | D9: 113 | E9: 361 | F9: =C9-E9 | G9: =F9/E9 | I9: 保洁服务 | J9: 481 | K9: 113 | L9: 361 | M9: =J9-L9 | N9: =M9/L9
B10: 被服洗涤 | C10: 73 | D10: 29 | E10: 58 | F10: =C10-E10 | G10: =F10/E10 | I10: 被服洗涤 | J10: 73 | K10: 29 | L10: 58 | M10: =J10-L10 | N10: =M10/L10
B11: 会务 | C11: 75 | D11: 27 | E11: 60 | F11: =C11-E11 | G11: =F11/E11 | I11: 物业其他 | J11: =J5-J6-J7-J8-J9-J10 | K11: =K5-K6-K7-K8-K9-K10 | L11: =L5-L6-L7-L8-L9-L10 | M11: =J11-L11 | N11: =M11/L11
B12: 绿化 | C12: 3 | D12: 0 | E12: 0 | F12: =C12-E12 | G12: =F12/E12
B13: 垃圾清运 | C13: 18 | D13: 2 | E13: 0 | F13: =C13-E13 | G13: =F13/E13
B14: 危险废弃物 | C14: 2 | D14: 1 | E14: 0 | F14: =C14-E14 | G14: =F14/E14
B15: 医废处置 | C15: 16 | D15: 10 | E15: 0 | F15: =C15-E15 | G15: =F15/E15
B16: 医废收运 | C16: 20 | D16: 8 | E16: 27 | F16: =C16-E16 | G16: =F16/E16
B17: 交通管理服务费 | C17: 6 | D17: 1 | E17: 0
B18: 园区物业管理 | C18: =C5-C6-C7-C8-C9-C10-C11-C12-C13-C14-C15-C16-C17 | D18: =D5-D6-D7-D8-D9-D10-D11-D12-D13-D14-D15-D16-D17 | E18: =E5-E6-E7-E8-E9-E10-E11-E12-E13-E14-E15-E16-E17 | F18: =C18-E18 | G18: =F18/E18

Sheet 维修护费
B1: 项 目 | C1: 46143 | D1: 其中 | E1: 45778 | F1: 增减额 | G1: 增减率
D2: 奉贤院区 | I2: 柯渡
B3: 维修费 | C3: =商品服务!C6 | D3: =商品服务!D6 | E3: =商品服务!E6 | F3: =C3-E3 | G3: =F3/E3
B4: 其中：网络维修 | C4: 55 | D4: 11 | E4: 219 | F4: =C4-E4 | G4: =F4/E4
B5: 设备维修 | C5: 347 | D5: 81 | E5: 421 | F5: =C5-E5 | G5: =F5/E5 | H5: 1114 | I5: 100 | J5: 1146
B6: 后勤维修 | C6: 199 | D6: 91 | E6: 59 | F6: =C6-E6 | G6: =F6/E6
B7: 房屋维修 | C7: 83 | D7: 0 | E7: 20 | F7: =C7-E7 | G7: =F7/E7

Sheet 后勤维修
C3: 项 目 | D3: 46143 | E3: 其中 | F3: 45778 | G3: 增减额 | H3: 增减率 | K3: 项 目 | L3: 46113 | M3: 其中 | N3: 45748 | O3: 增减额 | P3: 增减率
E4: 奉贤院区 | M4: 奉贤院区
C5: 后勤维修费 | D5: =维修护费!C6 | E5: =维修护费!D6 | F5: =维修护费!E6 | G5: =D5-F5 | H5: =G5/F5 | K5: 后勤维修费 | L5: =维修护费!C6 | M5: =维修护费!D6 | N5: =维修护费!E6 | O5: =L5-N5 | P5: =O5/N5
C6: 其中：物业维修 | D6: 70 | E6: 34 | F6: 45 | G6: =D6-F6 | H6: =G6/F6 | K6: 其中：物业维修 | L6: 70 | M6: 34 | N6: 45 | O6: =L6-N6 | P6: =O6/N6
C7: 电梯运行 | D7: 12 | E7: 2 | F7: 0 | G7: =D7-F7 | H7: =G7/F7 | K7: 通用设施设备管理 | L7: 0 | M7: 0 | N7: 0 | O7: =L7-N7 | P7: =O7/N7
C8: 通用设施 | D8: 0 | E8: 0 | F8: 0 | G8: =D8-F8 | H8: =G8/F8 | K8: 空调运行管理费 | L8: 43 | M8: 13 | N8: 0 | O8: =L8-N8 | P8: =O8/N8
C9: 空调运行管理费 | D9: 43 | E9: 13 | F9: 0 | G9: =D9-F9 | H9: =G9/F9 | K9: 其他 | L9: =L5-L6-L7-L8 | M9: =M5-M6-M7-M8 | N9: =N5-N6-N7-N8 | O9: =L9-N9 | P9: =O9/N9
C10: 电站运行 | D10: 16 | E10: 9 | F10: 9 | G10: =D10-F10 | H10: =G10/F10
C11: 给排水锅炉 | D11: 18 | E11: 12 | F11: 4 | G11: =D11-F11 | H11: =G11/F11
C12: 后勤智能化 | D12: 8 | E12: 5 | F12: 0 | G12: =D12-F12 | H12: =G12/F12
C13: 污水处理站 | D13: 20 | E13: 11 | F13: 0 | G13: =D13-F13 | H13: =G13/F13
C14: 污水管线 | D14: 2 | E14: 0 | F14: 0 | G14: =D14-F14 | H14: =G14/F14
C15: 医用气体 | D15: 9 | E15: 5 | F15: 0 | G15: =D15-F15 | H15: =G15/F15
C16: 其他 | D16: =D5-D6-D7-D8-D9-D10-D11-D12-D13-D14-D15 | E16: =E5-E6-E7-E8-E9-E10-E11-E12-E13-E14-E15 | F16: =F5-F6-F7-F8-F9-F10-F11-F12-F13-F14-F15 | G16: =D16-F16 | H16: =G16/F16

Sheet 卫生材料
B2: 项 目 | C2: 46143 | D2: 其中 | E2: 45778 | F2: 增减额 | G2: 增减率
D3: 奉贤院区
B4: 卫生材料收入 | C4: =ROUND((当年累计数据表!AJ3+当年累计数据表!BS3)/10000,0) | D4: =ROUND((当年累计数据表奉贤!AJ3+当年累计数据表奉贤!BS3)/10000,0) | E4: =ROUND((去年累计数据表!AJ3+去年累计数据表!BS3)/10000,0) | F4: =C4-E4 | G4: =F4/E4
B5: 卫生材料费 | C5: =医疗成本!C7 | D5: =医疗成本!E7 | E5: =医疗成本!G7 | F5: =C5-E5 | G5: =F5/E5
B6: 其中：可收费 | C6: =C5-C7 | D6: =D5-D7 | E6: =E5-E7 | F6: =C6-E6 | G6: =F6/E6 | I6: 调整
B7: 不可收费 | C7: 3490 | D7: 714 | E7: 2764 | F7: =C7-E7 | G7: =F7/E7 | I7: 101
B8: 其中：检验试剂 | C8: 2558 | D8: 567 | E8: 1729 | F8: =C8-E8 | G8: =F8/E8
B9: 其他不可收费卫生材料 | C9: =C7-C8 | D9: =D7-D8 | E9: =E7-E8 | F9: =F7-F8 | G9: =F9/E9
B11: 项 目 | C11: 46143 | D11: 其中：奉贤院区 | E11: 45778 | F11: 增减额 | G11: 增减率
B12: 检验试剂成本 | C12: =C8 | D12: =D8 | E12: =E8 | F12: =F8 | G12: =G8
B13: 其中：医学检验科 | C13: 2059 | D13: 395 | E13: 1373 | F13: =C13-E13 | G13: =F13/E13
B14: 化验收入 | C14: =ROUND((当月附表2!B10+当月附表2!B23)/10000,0) | D14: =ROUND((当月奉贤附表2!B10+当月奉贤附表2!B23)/10000,0) | E14: =ROUND((上年同期附表2!B10+上年同期附表2!B23)/10000,0) | F14: =C14-E14 | G14: =F14/E14
B15: 成本收入比重 | C15: =C12/C14 | D15: =D12/D14 | E15: =E12/E14 | F15: =C15-E15 | G15: -
B16: 门急诊人次 | C16: =ROUND(当年累计数据表!G3/10000,2) | D16: =ROUND(当年累计数据表奉贤!G3/10000,2) | E16: =ROUND(去年累计数据表!G3/10000,2) | F16: =C16-E16 | G16: =F16/E16
B17: 住院人次 | C17: =ROUND(当年累计数据表!H3/10000,2) | D17: =ROUND(当年累计数据表奉贤!H3/10000,2) | E17: =ROUND(去年累计数据表!H3/10000,2) | F17: =C17-E17 | G17: =F17/E17

Sheet 当年累计数据表
A1: 日期范围：20260501-20260531 | D1: 25 | O1: 1=2+5=8+43 | P1: 2=3+4 | Q1: 3 | R1: 4 | S1: 5=6+7 | T1: 6 | U1: 7 | V1: 8=9+12=15+22+29+36 | W1: 9=10+11 | X1: 10 | Y1: 11 | Z1: 12=13+14 | AA1: 13 | AB1: 14 | AC1: 15=16+19 | AD1: 16=17+18 | AE1: 17 | AF1: 18 | AG1: 19=20+21 | AH1: 20 | AI1: 21 | AJ1: 22=23+26 | AK1: 23=24+25 | AL1: 24 | AM1: 25 | AN1: 26=27+28 | AO1: 27 | AP1: 28 | AQ1: 29=30+33 | AR1: 30=31+32 | AS1: 31 | AT1: 32 | AU1: 33=34+35 | AV1: 34 | AW1: 35 | AX1: 36=37+40 | AY1: 37=38+39 | AZ1: 38 | BA1: 39 | BB1: 40=41+42 | BC1: 41 | BD1: 42 | BE1: 43=50+57+64+71=44+47 | BF1: 44=45+46 | BG1: 45 | BH1: 46 | BI1: 47=48+49 | BJ1: 48 | BK1: 49 | BL1: 50=51+54 | BM1: 51=52+53 | BN1: 52 | BO1: 53 | BP1: 54=55+56 | BQ1: 55 | BR1: 56 | BS1: 57=58+61 | BT1: 58=59+60 | BU1: 59 | BV1: 60 | BW1: 61=62+63 | BX1: 62 | BY1: 63 | BZ1: 64=65+68 | CA1: 65=66+67 | CB1: 66 | CC1: 67 | CD1: 68=69+70 | CE1: 69 | CF1: 70 | CG1: 71=72+75 | CH1: 72=73+74 | CI1: 73 | CJ1: 74 | CK1: 75=76+77 | CL1: 76 | CM1: 77 | CV1: 78=85+93+100+108+86+101=79+82 | CW1: 79=80+81 | CX1: 80 | CY1: 81 | CZ1: 82=83+84 | DA1: 83 | DB1: 84 | DC1: 85=87+90=78-93-100-108-86-101 | DD1: 86 | DE1: 87=88+89 | DF1: 88 | DG1: 89 | DH1: 90=91+92 | DI1: 91 | DJ1: 92 | DK1: 93=94+97 | DL1: 94=95+96 | DM1: 95 | DN1: 96 | DO1: 97=98+99 | DP1: 98 | DQ1: 99 | DR1: 100=102+105 | DS1: 101 | DT1: 102=103+104 | DU1: 103 | DV1: 104 | DW1: 105=106+107 | DX1: 106 | DY1: 107 | DZ1: 108=109+112 | EA1: 109=110+111 | EB1: 110 | EC1: 111 | ED1: 112=113+114 | EE1: 113 | EF1: 114 | EG1: 115=116+119 | EH1: 116=117+118 | EI1: 117 | EJ1: 118 | EK1: 119=120+121 | EL1: 120 | EM1: 121 | EN1: 122=123+124+125 | EO1: 123 | EP1: 124 | EQ1: 125 | EU1: 126=127+128+129 | EV1: 127 | EW1: 128 | EX1: 129 | EY1: 130=131+132 | EZ1: 131 | FA1: 132 | FB1: 133
A2: 序号 | B2: 科室类别 | C2: 科室名称 | D2: 医疗收入不含药耗 | E2: 门急诊收入不含药耗 | F2: 住院收入不含药耗 | G2: 门急诊人次 | H2: 住院人次 | I2: 门急诊治疗收入 | J2: 门急诊手术收入 | K2: 门诊中药饮片收入 | L2: 住院治疗收入 | M2: 住院手术收入 | N2: 住院中药饮片收入 | O2: 医疗收入 | P2: 其中本地病人医疗收入 | Q2: 其中本地病人医保医疗收入 | R2: 其中本地病人自费医疗收入 | S2: 其中异地病人医疗收入 | T2: 其中异地病人医保医疗收入 | U2: 其中异地病人自费医疗收入 | V2: 门急诊收入 | W2: 其中本地病人医疗收入 | X2: 其中本地病人医保医疗收入 | Y2: 其中本地病人自费医疗收入 | Z2: 其中异地病人医疗收入 | AA2: 其中异地病人医保医疗收入 | AB2: 其中异地病人自费医疗收入 | AC2: 门急诊药品收入 | AD2: 其中本地病人医疗收入 | AE2: 其中本地病人医保医疗收入 | AF2: 其中本地病人自费医疗收入 | AG2: 其中异地病人医疗收入 | AH2: 其中异地病人医保医疗收入 | AI2: 其中异地病人自费医疗收入 | AJ2: 门急诊耗材收入 | AK2: 其中本地病人医疗收入 | AL2: 其中本地病人医保医疗收入 | AM2: 其中本地病人自费医疗收入 | AN2: 其中异地病人医疗收入 | AO2: 其中异地病人医保医疗收入 | AP2: 其中异地病人自费医疗收入 | AQ2: 门急诊检查化验收入 | AR2: 其中本地病人医疗收入 | AS2: 其中本地病人医保医疗收入 | AT2: 其中本地病人自费医疗收入 | AU2: 其中异地病人医疗收入 | AV2: 其中异地病人医保医疗收入 | AW2: 其中异地病人自费医疗收入 | AX2: 门急诊劳务收入 | AY2: 其中本地病人医疗收入 | AZ2: 其中本地病人医保医疗收入 | BA2: 其中本地病人自费医疗收入 | BB2: 其中异地病人医疗收入 | BC2: 其中异地病人医保医疗收入 | BD2: 其中异地病人自费医疗收入 | BE2: 住院收入 | BF2: 其中本地病人医疗收入 | BG2: 其中本地病人医保医疗收入 | BH2: 其中本地病人自费医疗收入 | BI2: 其中异地病人医疗收入 | BJ2: 其中异地病人医保医疗收入 | BK2: 其中异地病人自费医疗收入 | BL2: 住院药品收入 | BM2: 其中本地病人医疗收入 | BN2: 其中本地病人医保医疗收入 | BO2: 其中本地病人自费医疗收入 | BP2: 其中异地病人医疗收入 | BQ2: 其中异地病人医保医疗收入 | BR2: 其中异地病人自费医疗收入 | BS2: 住院耗材收入 | BT2: 其中本地病人医疗收入 | BU2: 其中本地病人医保医疗收入 | BV2: 其中本地病人自费医疗收入 | BW2: 其中异地病人医疗收入 | BX2: 其中异地病人医保医疗收入 | BY2: 其中异地病人自费医疗收入 | BZ2: 住院检查化验收入 | CA2: 其中本地病人医疗收入 | CB2: 其中本地病人医保医疗收入 | CC2: 其中本地病人自费医疗收入 | CD2: 其中异地病人医疗收入 | CE2: 其中异地病人医保医疗收入 | CF2: 其中异地病人自费医疗收入 | CG2: 住院劳务收入 | CH2: 其中本地病人医疗收入 | CI2: 其中本地病人医保医疗收入 | CJ2: 其中本地病人自费医疗收入 | CK2: 其中异地病人医疗收入 | CL2: 其中异地病人医保医疗收入 | CM2: 其中异地病人自费医疗收入 | CN2: 急诊收入 | CO2: 普通门诊收入 | CP2: 专家门诊收入 | CQ2: 专病门诊收入 | CR2: 特需门诊收入 | CS2: MDT门诊收入 | CT2: 镜朗诊疗部收入 | CU2: 特需病房收入 | CV2: 门急诊人次 | CW2: 其中本地病人人次 | CX2: 其中本地病人医保人次 | CY2: 其中本地病人自费人次 | CZ2: 其中异地病人人次 | DA2: 其中异地病人医保人次 | DB2: 其中异地病人自费人次 | DC2: 普通门诊 (普通+专病) | DD2: 互联网普通门诊人次 | DE2: 其中本地病人人次 | DF2: 其中本地病人医保人次 | DG2: 其中本地病人自费人次 | DH2: 其中异地病人人次 | DI2: 其中异地病人医保人次 | DJ2: 其中异地病人自费人次 | DK2: 专家门诊 | DL2: 其中本地病人人次 | DM2: 其中本地病人医保人次 | DN2: 其中本地病人自费人次 | DO2: 其中异地病人人次 | DP2: 其中异地病人医保人次 | DQ2: 其中异地病人自费人次 | DR2: 特需门诊 (特需+MDT) | DS2: 互联网特需门诊人次 | DT2: 其中本地病人人次 | DU2: 其中本地病人医保人次 | DV2: 其中本地病人自费人次 | DW2: 其中异地病人人次 | DX2: 其中异地病人医保人次 | DY2: 其中异地病人自费人次 | DZ2: 急诊人次 | EA2: 其中本地病人人次 | EB2: 其中本地病人医保人次 | EC2: 其中本地病人自费人次 | ED2: 其中异地病人人次 | EE2: 其中异地病人医保人次 | EF2: 其中异地病人自费人次 | EG2: 住院人次 | EH2: 其中本地病人人次 | EI2: 其中本地病人医保人次 | EJ2: 其中本地病人自费人次 | EK2: 其中异地病人人次 | EL2: 其中异地病人医保人次 | EM2: 其中异地病人自费人次 | EN2: 手术人次与操作人次 | EO2: 手术人次 | EP2: 介入人次 | EQ2: 操作人次(治疗+诊断) | ER2: 微创手术人次（手术） | ES2: 微创手术人次（介入） | ET2: 微创手术人次（操作） | EU2: 三级手术 | EV2: 三级手术(手术) | EW2: 三级手术(介入) | EX2: 三级手术(操作) | EY2: 四级手术 | EZ2: 四级手术(手术) | FA2: 四级手术(介入) | FB2: 重点病种人次
A3: 小计： | D3: 3.0476275e+08 | E3: 1.3394059e+08 | F3: 1.7082215e+08 | G3: 454375 | H3: 15504 | I3: 23830756 | J3: 6184160 | K3: 2586256.2 | L3: 16825765 | M3: 43941230 | N3: 45012.893 | O3: 6.3529023e+08 | P3: 4.2623201e+08 | Q3: 3.8965963e+08 | R3: 36572379 | S3: 2.0905823e+08 | T3: 1.8480133e+08 | U3: 24256892 | V3: 2.3200361e+08 | W3: 1.8996545e+08 | X3: 1.7410947e+08 | Y3: 15855974 | Z3: 42038161 | AA3: 22706819 | AB3: 19331342 | AC3: 89682950 | AD3: 78384687 | AE3: 75588660 | AF3: 2796026.4 | AG3: 11298263 | AH3: 8423575.2 | AI3: 2874688 | AJ3: 8380067.3 | AK3: 7318139 | AL3: 6502668.1 | AM3: 815470.86 | AN3: 1061928.4 | AO3: 674129.09 | AP3: 387799.29 | AQ3: 75571406 | AR3: 61913801 | AS3: 56450220 | AT3: 5463581.5 | AU3: 13657604 | AV3: 7242125 | AW3: 6415479.5 | AX3: 58369187 | AY3: 42348822 | AZ3: 35567927 | BA3: 6780895.2 | BB3: 16020365 | BC3: 6366989.5 | BD3: 9653375.3 | BE3: 4.0328662e+08 | BF3: 2.3626656e+08 | BG3: 2.1555015e+08 | BH3: 20716405 | BI3: 1.6702007e+08 | BJ3: 1.6209452e+08 | BK3: 4925549.6 | BL3: 62594215 | BM3: 32952610 | BN3: 30905034 | BO3: 2047575.8 | BP3: 29641606 | BQ3: 28710226 | BR3: 931379.52 | BS3: 1.6987025e+08 | BT3: 1.0297809e+08 | BU3: 96111702 | BV3: 6866390.2 | BW3: 66892163 | BX3: 65945066 | BY3: 947097.29 | BZ3: 70668172 | CA3: 43124066 | CB3: 39793004 | CC3: 3331061.3 | CD3: 27544107 | CE3: 26995138 | CF3: 548968.25 | CG3: 1.0015398e+08 | CH3: 57211792 | CI3: 48740414 | CJ3: 8471377.5 | CK3: 42942190 | CL3: 40444085 | CM3: 2498104.5 | CN3: 30495394 | CO3: 82165321 | CP3: 57649478 | CQ3: 31223223 | CR3: 30181622 | CS3: 287165.52 | CT3: 8248119.2 | CU3: 0 | CV3: 454375 | CW3: 388783 | CX3: 355506 | CY3: 33277 | CZ3: 65592 | DA3: 35080 | DB3: 30512 | DC3: 245641 | DD3: 5812 | DE3: 216653 | DF3: 201402 | DG3: 15251 | DH3: 28988 | DI3: 16639 | DJ3: 12349 | DK3: 100478 | DL3: 82051 | DM3: 75437 | DN3: 6614 | DO3: 18427 | DP3: 10589 | DQ3: 7838 | DR3: 38113 | DS3: 143 | DT3: 28296 | DU3: 23810 | DV3: 4486 | DW3: 9817 | DX3: 3878 | DY3: 5939 | DZ3: 64188 | EA3: 56960 | EB3: 51037 | EC3: 5923 | ED3: 7228 | EE3: 3920 | EF3: 3308 | EG3: 15504 | EH3: 9790 | EI3: 8851 | EJ3: 939 | EK3: 5714 | EL3: 5439 | EM3: 275 | EN3: 12341 | EO3: 6537 | EP3: 892 | EQ3: 4912 | ER3: 1693 | ES3: 0 | ET3: 104 | EU3: 3260 | EV3: 2655 | EW3: 450 | EX3: 155 | EY3: 2174 | EZ3: 1920 | FA3: 254 | FB3: 4850
A4: 1 | B4: 成人非手术 | C4: 内科 | D4: 190440 | E4: 190440 | F4: 0 | G4: 986 | H4: 0 | I4: 166 | J4: 0 | K4: 0 | L4: 0 | M4: 0 | N4: 0 | O4: 460164.38 | P4: 431894.92 | Q4: 411754.28 | R4: 20140.64 | S4: 28269.46 | T4: 23236.39 | U4: 5033.07 | V4: 460164.38 | W4: 431894.92 | X4: 411754.28 | Y4: 20140.64 | Z4: 28269.46 | AA4: 23236.39 | AB4: 5033.07 | AC4: 268433.31 | AD4: 255132.85 | AE4: 250892.41 | AF4: 4240.44 | AG4: 13300.46 | AH4: 11166.39 | AI4: 2134.07 | AJ4: 1291.07 | AK4: 1167.07 | AL4: 992.87 | AM4: 174.2 | AN4: 124 | AO4: 43 | AP4: 81 | AQ4: 158181 | AR4: 145137 | AS4: 135482 | AT4: 9655 | AU4: 13044 | AV4: 10606 | AW4: 2438 | AX4: 32259 | AY4: 30458 | AZ4: 24387 | BA4: 6071 | BB4: 1801 | BC4: 1421 | BD4: 380 | BE4: 0 | BF4: 0 | BG4: 0 | BH4: 0 | BI4: 0 | BJ4: 0 | BK4: 0 | BL4: 0 | BM4: 0 | BN4: 0 | BO4: 0 | BP4: 0 | BQ4: 0 | BR4: 0 | BS4: 0 | BT4: 0 | BU4: 0 | BV4: 0 | BW4: 0 | BX4: 0 | BY4: 0 | BZ4: 0 | CA4: 0 | CB4: 0 | CC4: 0 | CD4: 0 | CE4: 0 | CF4: 0 | CG4: 0 | CH4: 0 | CI4: 0 | CJ4: 0 | CK4: 0 | CL4: 0 | CM4: 0 | CN4: 0 | CO4: 243161.06 | CP4: 106247.51 | CQ4: 89883.11 | CR4: 20872.7 | CS4: 0 | CT4: 0 | CU4: 0 | CV4: 986 | CW4: 905 | CX4: 871 | CY4: 34 | CZ4: 81 | DA4: 51 | DB4: 30 | DC4: 744 | DD4: 60 | DE4: 690 | DF4: 678 | DG4: 12 | DH4: 54 | DI4: 42 | DJ4: 12 | DK4: 164 | DL4: 154 | DM4: 151 | DN4: 3 | DO4: 10 | DP4: 8 | DQ4: 2 | DR4: 18 | DS4: 0 | DT4: 17 | DU4: 6 | DV4: 11 | DW4: 1 | DX4: 1 | DY4: 0 | DZ4: 0 | EA4: 0 | EB4: 0 | EC4: 0 | ED4: 0 | EE4: 0 | EF4: 0 | EG4: 0 | EH4: 0 | EI4: 0 | EJ4: 0 | EK4: 0 | EL4: 0 | EM4: 0 | EN4: 0 | EO4: 0 | EP4: 0 | EQ4: 0 | ER4: 0 | ES4: 0 | ET4: 0 | EU4: 0 | EV4: 0 | EW4: 0 | EX4: 0 | EY4: 0 | EZ4: 0 | FA4: 0 | FB4: 0
A5: 2 | B5: 成人非手术 | C5: 呼吸内科 | D5: 5468271.5 | E5: 2160548 | F5: 3307723.5 | G5: 10165 | H5: 329 | I5: 13988 | J5: 0 | K5: 0 | L5: 184144 | M5: 3028 | N5: 357 | O5: 10135078 | P5: 7341275.5 | Q5: 7170240 | R5: 171035.42 | S5: 2793802.4 | T5: 2629179.5 | U5: 164622.94 | V5: 4323553.8 | W5: 3800574.6 | X5: 3693507.8 | Y5: 107066.81 | Z5: 522979.17 | AA5: 376311.66 | AB5: 146667.51 | AC5: 2094052.2 | AD5: 1820730.2 | AE5: 1785224.4 | AF5: 35505.81 | AG5: 273321.98 | AH5: 206927.47 | AI5: 66394.51 | AJ5: 68953.58 | AK5: 61664.39 | AL5: 59755.39 | AM5: 1909 | AN5: 7289.19 | AO5: 5025.19 | AP5: 2264 | AQ5: 1793278 | AR5: 1596099 | AS5: 1540079 | AT5: 56020 | AU5: 197179 | AV5: 132375 | AW5: 64804 | AX5: 367270 | AY5: 322081 | AZ5: 308449 | BA5: 13632 | BB5: 45189 | BC5: 31984 | BD5: 13205 | BE5: 5811524.1 | BF5: 3540700.8 | BG5: 3476732.2 | BH5: 63968.61 | BI5: 2270823.2 | BJ5: 2252867.8 | BK5: 17955.43 | BL5: 2295779.5 | BM5: 1357648.3 | BN5: 1338779.2 | BO5: 18869.13 | BP5: 938131.13 | BQ5: 933832.06 | BR5: 4299.07 | BS5: 208021.12 | BT5: 126593 | BU5: 124679.02 | BV5: 1913.98 | BW5: 81428.12 | BX5: 80860.76 | BY5: 567.36 | BZ5: 2631940 | CA5: 1639312 | CB5: 1607724 | CC5: 31588 | CD5: 992628 | CE5: 982412 | CF5: 10216 | CG5: 675783.5 | CH5: 417147.5 | CI5: 405550 | CJ5: 11597.5 | CK5: 258636 | CL5: 255763 | CM5: 2873 | CN5: -75 | CO5: 2687317 | CP5: 1324630 | CQ5: 82831.97 | CR5: 228774.86 | CS5: 0 | CT5: 0 | CU5: 0 | CV5: 10165 | CW5: 9019 | CX5: 8712 | CY5: 307 | CZ5: 1146 | DA5: 796 | DB5: 350 | DC5: 7596 | DD5: 67 | DE5: 6812 | DF5: 6598 | DG5: 214 | DH5: 784 | DI5: 538 | DJ5: 246 | DK5: 2223 | DL5: 1908 | DM5: 1835 | DN5: 73 | DO5: 315 | DP5: 225 | DQ5: 90 | DR5: 277 | DS5: 2 | DT5: 234 | DU5: 215 | DV5: 19 | DW5: 43 | DX5: 33 | DY5: 10 | DZ5: 0 | EA5: 0 | EB5: 0 | EC5: 0 | ED5: 0 | EE5: 0 | EF5: 0 | EG5: 329 | EH5: 211 | EI5: 208 | EJ5: 3 | EK5: 118 | EL5: 117 | EM5: 1 | EN5: 208 | EO5: 1 | EP5: 0 | EQ5: 207 | ER5: 0 | ES5: 0 | ET5: 0 | EU5: 0 | EV5: 0 | EW5: 0 | EX5: 0 | EY5: 0 | EZ5: 0 | FA5: 0 | FB5: 96
A6: 3 | B6: 成人非手术 | C6: 消化内科（内窥镜诊治部） | D6: 10993209 | E6: 6703879 | F6: 4289330.3 | G6: 21193 | H6: 715 | I6: 462650 | J6: 11400 | K6: 0 | L6: 388024.5 | M6: 530013 | N6: 1270.5 | O6: 19743331 | P6: 15905375 | Q6: 15202208 | R6: 703167.44 | S6: 3837955.5 | T6: 3325493.6 | U6: 512461.95 | V6: 11740377 | W6: 10223424 | X6: 9655598.4 | Y6: 567825.92 | Z6: 1516952.3 | AA6: 1030491 | AB6: 486461.38 | AC6: 4352330.7 | AD6: 3847348.4 | AE6: 3737102.5 | AF6: 110245.92 | AG6: 504982.34 | AH6: 361485.96 | AI6: 143496.38 | AJ6: 684167 | AK6: 590578 | AL6: 567458 | AM6: 23120 | AN6: 93589 | AO6: 74826 | AP6: 18763 | AQ6: 4818752 | AR6: 4187500 | AS6: 4021101 | AT6: 166399 | AU6: 631252 | AV6: 439240 | AW6: 192012 | AX6: 1885127 | AY6: 1597998 | AZ6: 1329937 | BA6: 268061 | BB6: 287129 | BC6: 154939 | BD6: 132190 | BE6: 8002954 | BF6: 5681950.8 | BG6: 5546609.3 | BH6: 135341.52 | BI6: 2321003.2 | BJ6: 2295002.6 | BK6: 26000.57 | BL6: 1456545.6 | BM6: 1018119 | BN6: 996355.35 | BO6: 21763.65 | BP6: 438426.6 | BQ6: 433303.66 | BR6: 5122.94 | BS6: 2257078.1 | BT6: 1630048 | BU6: 1604531.4 | BV6: 25516.57 | BW6: 627030.1 | BX6: 626054.97 | BY6: 975.13 | BZ6: 2695778.8 | CA6: 1867159.8 | CB6: 1816779 | CC6: 50380.8 | CD6: 828619 | CE6: 814964 | CF6: 13655 | CG6: 1593551.5 | CH6: 1166624 | CI6: 1128943.5 | CJ6: 37680.5 | CK6: 426927.5 | CL6: 420680 | CM6: 6247.5 | CN6: -50 | CO6: 5691556 | CP6: 2812994.7 | CQ6: 1761913.4 | CR6: 1473912.6 | CS6: 0 | CT6: 39371.86 | CU6: 0 | CV6: 21193 | CW6: 18498 | CX6: 17574 | CY6: 924 | CZ6: 2695 | DA6: 1790 | DB6: 905 | DC6: 14414 | DD6: 248 | DE6: 12695 | DF6: 12224 | DG6: 471 | DH6: 1719 | DI6: 1139 | DJ6: 580 | DK6: 5374 | DL6: 4624 | DM6: 4420 | DN6: 204 | DO6: 750 | DP6: 552 | DQ6: 198 | DR6: 1157 | DS6: 0 | DT6: 946 | DU6: 705 | DV6: 241 | DW6: 211 | DX6: 94 | DY6: 117 | DZ6: 0 | EA6: 0 | EB6: 0 | EC6: 0 | ED6: 0 | EE6: 0 | EF6: 0 | EG6: 715 | EH6: 513 | EI6: 501 | EJ6: 12 | EK6: 202 | EL6: 200 | EM6: 2 | EN6: 824 | EO6: 2 | EP6: 0 | EQ6: 822 | ER6: 0 | ES6: 0 | ET6: 99 | EU6: 78 | EV6: 1 | EW6: 0 | EX6: 77 | EY6: 0 | EZ6: 0 | FA6: 0 | FB6: 54
A7: 4 | B7: 成人非手术 | C7: 神经内科 | D7: 6279402.5 | E7: 3160499.5 | F7: 3118903 | G7: 13784 | H7: 301 | I7: 1076 | J7: 0 | K7: 77841.38 | L7: 180154 | M7: 74721 | N7: 803.6 | O7: 14467950 | P7: 11696477 | Q7: 11441253 | R7: 255224.24 | S7: 2771473 | T7: 2559079.8 | U7: 212393.27 | V7: 6854147.3 | W7: 6063633.2 | X7: 5827974.5 | Y7: 235658.68 | Z7: 790514.12 | AA7: 578120.85 | AB7: 212393.27 | AC7: 3683703.5 | AD7: 3338045 | AE7: 3243302 | AF7: 94743.04 | AG7: 345658.48 | AH7: 264417.21 | AI7: 81241.27 | AJ7: 9944.36 | AK7: 7888.72 | AL7: 7510.08 | AM7: 378.64 | AN7: 2055.64 | AO7: 1711.64 | AP7: 344 | AQ7: 2599627 | AR7: 2243434 | AS7: 2131853 | AT7: 111581 | AU7: 356193 | AV7: 254445 | AW7: 101748 | AX7: 560872.5 | AY7: 474265.5 | AZ7: 445309.5 | BA7: 28956 | BB7: 86607 | BC7: 57547 | BD7: 29060 | BE7: 7613802.7 | BF7: 5632843.8 | BG7: 5613278.2 | BH7: 19565.56 | BI7: 1980958.9 | BJ7: 1980958.9 | BK7: 0 | BL7: 1333451.4 | BM7: 1050578.6 | BN7: 1044611.9 | BO7: 5966.7 | BP7: 282872.86 | BQ7: 282872.86 | BR7: 0 | BS7: 3161448.3 | BT7: 2145121.7 | BU7: 2144832.3 | BV7: 289.36 | BW7: 1016326.6 | BX7: 1016326.6 | BY7: 0 | BZ7: 2213935 | CA7: 1701049 | CB7: 1689618 | CC7: 11431 | CD7: 512886 | CE7: 512886 | CF7: 0 | CG7: 904968 | CH7: 736094.5 | CI7: 734216 | CJ7: 1878.5 | CK7: 168873.5 | CL7: 168873.5 | CM7: 0 | CN7: 0 | CO7: 3345242.9 | CP7: 1429690.2 | CQ7: 1166977.8 | CR7: 912236.48 | CS7: 0 | CT7: 0 | CU7: 0 | CV7: 13784 | CW7: 12289 | CX7: 11790 | CY7: 499 | CZ7: 1495 | DA7: 1013 | DB7: 482 | DC7: 10314 | DD7: 261 | DE7: 9378 | DF7: 9062 | DG7: 316 | DH7: 936 | DI7: 627 | DJ7: 309 | DK7: 2305 | DL7: 1979 | DM7: 1884 | DN7: 95 | DO7: 326 | DP7: 249 | DQ7: 77 | DR7: 904 | DS7: 0 | DT7: 697 | DU7: 622 | DV7: 75 | DW7: 207 | DX7: 134 | DY7: 73 | DZ7: 0 | EA7: 0 | EB7: 0 | EC7: 0 | ED7: 0 | EE7: 0 | EF7: 0 | EG7: 301 | EH7: 237 | EI7: 234 | EJ7: 3 | EK7: 64 | EL7: 64 | EM7: 0 | EN7: 105 | EO7: 0 | EP7: 36 | EQ7: 69 | ER7: 0 | ES7: 0 | ET7: 0 | EU7: 6 | EV7: 0 | EW7: 6 | EX7: 0 | EY7: 30 | EZ7: 0 | FA7: 30 | FB7: 99
A8: 5 | B8: 成人非手术 | C8: 心血管内科 | D8: 16364810 | E8: 3955095 | F8: 12409715 | G8: 32529 | H8: 1186 | I8: 4676 | J8: 0 | K8: 0 | L8: 164607.75 | M8: 2580951.5 | N8: 97.5 | O8: 63680331 | P8: 47547833 | Q8: 47147948 | R8: 399884.99 | S8: 16132498 | T8: 15840886 | U8: 291612.16 | V8: 13771868 | W8: 12665014 | X8: 12484549 | Y8: 180465.6 | Z8: 1106854.2 | AA8: 886645.26 | AB8: 220208.9 | AC8: 9775565.7 | AD8: 9123385.5 | AE8: 9040423.9 | AF8: 82961.6 | AG8: 652180.16 | AH8: 556948.26 | AI8: 95231.9 | AJ8: 41207.8 | AK8: 35412.8 | AL8: 33993.8 | AM8: 1419 | AN8: 5795 | AO8: 3602 | AP8: 2193 | AQ8: 2837491 | AR8: 2511157 | AS8: 2440701 | AT8: 70456 | AU8: 326334 | AV8: 237803 | AW8: 88531 | AX8: 1117604 | AY8: 995059 | AZ8: 969430 | BA8: 25629 | BB8: 122545 | BC8: 88292 | BD8: 34253 | BE8: 49908462 | BF8: 34882818 | BG8: 34663399 | BH8: 219419.39 | BI8: 15025644 | BJ8: 14954241 | BK8: 71403.26 | BL8: 2436157.6 | BM8: 1790204.6 | BN8: 1777009.4 | BO8: 13195.19 | BP8: 645952.93 | BQ8: 640716.81 | BR8: 5236.12 | BS8: 35062590 | BT8: 24126042 | BU8: 24022986 | BV8: 103055.7 | BW8: 10936548 | BX8: 10895294 | BY8: 41254.64 | BZ8: 7930500 | CA8: 5767731 | CB8: 5705519 | CC8: 62212 | CD8: 2162769 | CE8: 2151102 | CF8: 11667 | CG8: 4479214.8 | CH8: 3198841 | CI8: 3157884.5 | CJ8: 40956.5 | CK8: 1280373.8 | CL8: 1267128.2 | CM8: 13245.5 | CN8: -25 | CO8: 6409354.3 | CP8: 4847064.3 | CQ8: 2127559.4 | CR8: 387890.44 | CS8: 0 | CT8: 41859.82 | CU8: 0 | CV8: 32529 | CW8: 29584 | CX8: 28994 | CY8: 590 | CZ8: 2945 | DA8: 2260 | DB8: 685 | DC8: 21990 | DD8: 499 | DE8: 20170 | DF8: 19849 | DG8: 321 | DH8: 1820 | DI8: 1405 | DJ8: 415 | DK8: 9567 | DL8: 8568 | DM8: 8324 | DN8: 244 | DO8: 999 | DP8: 784 | DQ8: 215 | DR8: 473 | DS8: 0 | DT8: 372 | DU8: 355 | DV8: 17 | DW8: 101 | DX8: 62 | DY8: 39 | DZ8: 0 | EA8: 0 | EB8: 0 | EC8: 0 | ED8: 0 | EE8: 0 | EF8: 0 | EG8: 1186 | EH8: 869 | EI8: 858 | EJ8: 11 | EK8: 317 | EL8: 315 | EM8: 2 | EN8: 1030 | EO8: 167 | EP8: 473 | EQ8: 390 | ER8: 0 | ES8: 0 | ET8: 0 | EU8: 467 | EV8: 163 | EW8: 304 | EX8: 0 | EY8: 25 | EZ8: 3 | FA8: 22 | FB8: 230
A9: 6 | B9: 成人非手术 | C9: 血液内科 | D9: 2250983.5 | E9: 259051 | F9: 1991932.5 | G9: 1387 | H9: 439 | I9: 1032 | J9: 0 | K9: 0 | L9: 208692 | M9: 2192 | N9: 259.56 | O9: 9333747.5 | P9: 3939958.8 | Q9: 3884466.5 | R9: 55492.33 | S9: 5393788.7 | T9: 5374452.2 | U9: 19336.45 | V9: 1110257.2 | W9: 909956.16 | X9: 891440.76 | Y9: 18515.4 | Z9: 200301.06 | AA9: 180964.61 | AB9: 19336.45 | AC9: 844297.92 | AD9: 712643.86 | AE9: 703246.46 | AF9: 9397.4 | AG9: 131654.06 | AH9: 122454.61 | AI9: 9199.45 | AJ9: 6908.3 | AK9: 6822.3 | AL9: 6672.3 | AM9: 150 | AN9: 86 | AO9: 43 | AP9: 43 | AQ9: 206794 | AR9: 150243 | AS9: 143449 | AT9: 6794 | AU9: 56551 | AV9: 49294 | AW9: 7257 | AX9: 52257 | AY9: 40247 | AZ9: 38073 | BA9: 2174 | BB9: 12010 | BC9: 9173 | BD9: 2837 | BE9: 8223490.3 | BF9: 3030002.7 | BG9: 2993025.7 | BH9: 36976.93 | BI9: 5193487.6 | BJ9: 5193487.6 | BK9: 0 | BL9: 5859374.7 | BM9: 2237778.1 | BN9: 2228668 | BO9: 9110.1 | BP9: 3621596.6 | BQ9: 3621596.6 | BR9: 0 | BS9: 372183.07 | BT9: 71265.03 | BU9: 70062.2 | BV9: 1202.83 | BW9: 300918.04 | BX9: 300918.04 | BY9: 0 | BZ9: 1271761 | CA9: 542160 | CB9: 534104 | CC9: 8056 | CD9: 729601 | CE9: 729601 | CF9: 0 | CG9: 720171.5 | CH9: 178799.5 | CI9: 160191.5 | CJ9: 18608 | CK9: 541372 | CL9: 541372 | CM9: 0 | CN9: 0 | CO9: 279437.79 | CP9: 684566.74 | CQ9: 125257.87 | CR9: 20994.82 | CS9: 0 | CT9: 30270.71 | CU9: 0 | CV9: 1387 | CW9: 1079 | CX9: 1023 | CY9: 56 | CZ9: 308 | DA9: 256 | DB9: 52 | DC9: 871 | DD9: 0 | DE9: 667 | DF9: 633 | DG9: 34 | DH9: 204 | DI9: 173 | DJ9: 31 | DK9: 496 | DL9: 400 | DM9: 379 | DN9: 21 | DO9: 96 | DP9: 80 | DQ9: 16 | DR9: 20 | DS9: 0 | DT9: 12 | DU9: 11 | DV9: 1 | DW9: 8 | DX9: 3 | DY9: 5 | DZ9: 0 | EA9: 0 | EB9: 0 | EC9: 0 | ED9: 0 | EE9: 0 | EF9: 0 | EG9: 439 | EH9: 204 | EI9: 201 | EJ9: 3 | EK9: 235 | EL9: 235 | EM9: 0 | EN9: 307 | EO9: 0 | EP9: 0 | EQ9: 307 | ER9: 0 | ES9: 0 | ET9: 0 | EU9: 0 | EV9: 0 | EW9: 0 | EX9: 0 | EY9: 0 | EZ9: 0 | FA9: 0 | FB9: 24
A10: 7 | B10: 成人非手术 | C10: 肾脏风湿免疫科 | D10: 7311864.5 | E10: 5303081 | F10: 2008783.5 | G10: 8053 | H10: 245 | I10: 3658168 | J10: 0 | K10: 0 | L10: 146264.5 | M10: 21182 | N10: 0 | O10: 13207228 | P10: 11580471 | Q10: 11427629 | R10: 152842.34 | S10: 1626757.1 | T10: 1511943.7 | U10: 114813.42 | V10: 10061749 | W10: 9272025 | X10: 9153032.5 | Y10: 118992.46 | Z10: 789723.67 | AA10: 674910.25 | AB10: 114813.42 | AC10: 3755767.8 | AD10: 3441433 | AE10: 3393696.9 | AF10: 47736.15 | AG10: 314334.84 | AH10: 257902.96 | AI10: 56431.88 | AJ10: 1002899.8 | AK10: 958189.96 | AL10: 946484.65 | AM10: 11705.31 | AN10: 44709.83 | AO10: 42378.29 | AP10: 2331.54 | AQ10: 1366987 | AR10: 1214980 | AS10: 1187139 | AT10: 27841 | AU10: 152007 | AV10: 112391 | AW10: 39616 | AX10: 3936094 | AY10: 3657422 | AZ10: 3625712 | BA10: 31710 | BB10: 278672 | BC10: 262238 | BD10: 16434 | BE10: 3145479.4 | BF10: 2308446 | BG10: 2274596.1 | BH10: 33849.88 | BI10: 837033.45 | BJ10: 837033.45 | BK10: 0 | BL10: 895729.92 | BM10: 649457.36 | BN10: 638053.76 | BO10: 11403.6 | BP10: 246272.56 | BQ10: 246272.56 | BR10: 0 | BS10: 240966.01 | BT10: 194514.62 | BU10: 194336.34 | BV10: 178.28 | BW10: 46451.39 | BX10: 46451.39 | BY10: 0 | BZ10: 1492599 | CA10: 1087092 | CB10: 1067239 | CC10: 19853 | CD10: 405507 | CE10: 405507 | CF10: 0 | CG10: 516184.5 | CH10: 377382 | CI10: 374967 | CJ10: 2415 | CK10: 138802.5 | CL10: 138802.5 | CM10: 0 | CN10: 0 | CO10: 1453184.4 | CP10: 1434535.5 | CQ10: 6971380 | CR10: 202648.74 | CS10: 0 | CT10: 0 | CU10: 0 | CV10: 8053 | CW10: 7209 | CX10: 7008 | CY10: 201 | CZ10: 844 | DA10: 620 | DB10: 224 | DC10: 5939 | DD10: 111 | DE10: 5379 | DF10: 5240 | DG10: 139 | DH10: 560 | DI10: 419 | DJ10: 141 | DK10: 1865 | DL10: 1622 | DM10: 1566 | DN10: 56 | DO10: 243 | DP10: 177 | DQ10: 66 | DR10: 138 | DS10: 0 | DT10: 106 | DU10: 102 | DV10: 4 | DW10: 32 | DX10: 22 | DY10: 10 | DZ10: 0 | EA10: 0 | EB10: 0 | EC10: 0 | ED10: 0 | EE10: 0 | EF10: 0 | EG10: 245 | EH10: 181 | EI10: 176 | EJ10: 5 | EK10: 64 | EL10: 64 | EM10: 0 | EN10: 61 | EO10: 10 | EP10: 0 | EQ10: 51 | ER10: 0 | ES10: 0 | ET10: 0 | EU10: 0 | EV10: 0 | EW10: 0 | EX10: 0 | EY10: 0 | EZ10: 0 | FA10: 0 | FB10: 136
A11: 8 | B11: 成人非手术 | C11: 内分泌科 | D11: 6100953.5 | E11: 4175385 | F11: 1925568.5 | G11: 17407 | H11: 202 | I11: 6970 | J11: 574 | K11: 0 | L11: 195804 | M11: 9748 | N11: 0 | O11: 10521720 | P11: 9372690.9 | Q11: 9180521.3 | R11: 192169.6 | S11: 1149029.6 | T11: 1003175.6 | U11: 145853.95 | V11: 8078531.8 | W11: 7419690.1 | X11: 7227520.5 | Y11: 192169.6 | Z11: 658841.76 | AA11: 512987.81 | AB11: 145853.95 | AC11: 3827825.4 | AD11: 3554399.7 | AE11: 3493726.5 | AF11: 60673.2 | AG11: 273425.76 | AH11: 230946.21 | AI11: 42479.55 | AJ11: 75321.4 | AK11: 70635.4 | AL11: 69579 | AM11: 1056.4 | AN11: 4686 | AO11: 3397.6 | AP11: 1288.4 | AQ11: 3534589 | AR11: 3221056 | AS11: 3116399 | AT11: 104657 | AU11: 313533 | AV11: 232478 | AW11: 81055 | AX11: 640796 | AY11: 573599 | AZ11: 547816 | BA11: 25783 | BB11: 67197 | BC11: 46166 | BD11: 21031 | BE11: 2443188.6 | BF11: 1953000.8 | BG11: 1953000.8 | BH11: 0 | BI11: 490187.79 | BJ11: 490187.79 | BK11: 0 | BL11: 468706.79 | BM11: 377179.47 | BN11: 377179.47 | BO11: 0 | BP11: 91527.32 | BQ11: 91527.32 | BR11: 0 | BS11: 48913.3 | BT11: 36926.83 | BU11: 36926.83 | BV11: 0 | BW11: 11986.47 | BX11: 11986.47 | BY11: 0 | BZ11: 1483750 | CA11: 1185820 | CB11: 1185820 | CC11: 0 | CD11: 297930 | CE11: 297930 | CF11: 0 | CG11: 441818.5 | CH11: 353074.5 | CI11: 353074.5 | CJ11: 0 | CK11: 88744 | CL11: 88744 | CM11: 0 | CN11: -25 | CO11: 4264574.2 | CP11: 2549082.9 | CQ11: 850924.02 | CR11: 413950.7 | CS11: 0 | CT11: 0 | CU11: 0 | CV11: 17407 | CW11: 15835 | CX11: 15360 | CY11: 475 | CZ11: 1572 | DA11: 1188 | DB11: 384 | DC11: 11767 | DD11: 200 | DE11: 10743 | DF11: 10446 | DG11: 297 | DH11: 1024 | DI11: 796 | DJ11: 228 | DK11: 4895 | DL11: 4446 | DM11: 4306 | DN11: 140 | DO11: 449 | DP11: 341 | DQ11: 108 | DR11: 537 | DS11: 8 | DT11: 450 | DU11: 413 | DV11: 37 | DW11: 87 | DX11: 51 | DY11: 36 | DZ11: 0 | EA11: 0 | EB11: 0 | EC11: 0 | ED11: 0 | EE11: 0 | EF11: 0 | EG11: 202 | EH11: 161 | EI11: 160 | EJ11: 1 | EK11: 41 | EL11: 41 | EM11: 0 | EN11: 2 | EO11: 0 | EP11: 0 | EQ11: 2 | ER11: 0 | ES11: 0 | ET11: 0 | EU11: 0 | EV11: 0 | EW11: 0 | EX11: 0 | EY11: 0 | EZ11: 0 | FA11: 0 | FB11: 179
A12: 9 | B12: 成人非手术 | C12: 老年医学科 | D12: 3963449.5 | E12: 224416 | F12: 3739033.5 | G12: 2025 | H12: 80 | I12: 7430 | J12: 0 | K12: 42064.32 | L12: 632551 | M12: 16102 | N12: 15516.45 | O12: 6922375.9 | P12: 6905819.2 | Q12: 6690594.7 | R12: 215224.59 | S12: 16556.7 | T12: 13724.2 | U12: 2832.5 | V12: 1229141.9 | W12: 1212585.2 | X12: 1209281.5 | Y12: 3303.74 | Z12: 16556.7 | AA12: 13724.2 | AB12: 2832.5 | AC12: 998788.75 | AD12: 988078.05 | AE12: 986143.31 | AF12: 1934.74 | AG12: 10710.7 | AH12: 9105.2 | AI12: 1605.5 | AJ12: 5937.18 | AK12: 5851.18 | AL12: 5808.18 | AM12: 43 | AN12: 86 | AO12: 86 | AP12: 0 | AQ12: 164644 | AR12: 159740 | AS12: 158756 | AT12: 984 | AU12: 4904 | AV12: 3838 | AW12: 1066 | AX12: 59772 | AY12: 58916 | AZ12: 58574 | BA12: 342 | BB12: 856 | BC12: 695 | BD12: 161 | BE12: 5693234 | BF12: 5693234 | BG12: 5481313.2 | BH12: 211920.85 | BI12: 0 | BJ12: 0 | BK12: 0 | BL12: 1796818.9 | BM12: 1796818.9 | BN12: 1723381.6 | BO12: 73437.3 | BP12: 0 | BQ12: 0 | BR12: 0 | BS12: 157381.63 | BT12: 157381.63 | BU12: 149127.58 | BV12: 8254.05 | BW12: 0 | BX12: 0 | BY12: 0 | BZ12: 1793588 | CA12: 1793588 | CB12: 1725237 | CC12: 68351 | CD12: 0 | CE12: 0 | CF12: 0 | CG12: 1945445.5 | CH12: 1945445.5 | CI12: 1883567 | CJ12: 61878.5 | CK12: 0 | CL12: 0 | CM12: 0 | CN12: 0 | CO12: 1225927.9 | CP12: 0 | CQ12: 25 | CR12: 3189 | CS12: 0 | CT12: 0 | CU12: 0 | CV12: 2025 | CW12: 1998 | CX12: 1989 | CY12: 9 | CZ12: 27 | DA12: 25 | DB12: 2 | DC12: 2023 | DD12: 0 | DE12: 1997 | DF12: 1989 | DG12: 8 | DH12: 26 | DI12: 25 | DJ12: 1 | DK12: 0 | DL12: 0 | DM12: 0 | DN12: 0 | DO12: 0 | DP12: 0 | DQ12: 0 | DR12: 2 | DS12: 0 | DT12: 1 | DU12: 0 | DV12: 1 | DW12: 1 | DX12: 0 | DY12: 1 | DZ12: 0 | EA12: 0 | EB12: 0 | EC12: 0 | ED12: 0 | EE12: 0 | EF12: 0 | EG12: 80 | EH12: 80 | EI12: 79 | EJ12: 1 | EK12: 0 | EL12: 0 | EM12: 0 | EN12: 45 | EO12: 0 | EP12: 0 | EQ12: 45 | ER12: 0 | ES12: 0 | ET12: 0 | EU12: 0 | EV12: 0 | EW12: 0 | EX12: 0 | EY12: 0 | EZ12: 0 | FA12: 0 | FB12: 0
A13: 10 | B13: 成人非手术 | C13: 全科医学科 | D13: 2436244.2 | E13: 622677 | F13: 1813567.2 | G13: 3280 | H13: 112 | I13: 442 | J13: 0 | K13: 0 | L13: 86412.25 | M13: 46645 | N13: 129.15 | O13: 3556463.9 | P13: 2615182.3 | Q13: 2571299.6 | R13: 43882.75 | S13: 941281.55 | T13: 860156.36 | U13: 81125.19 | V13: 1337199.9 | W13: 1235124.2 | X13: 1215734.4 | Y13: 19389.86 | Z13: 102075.63 | AA13: 91752.81 | AB13: 10322.82 | AC13: 712973.85 | AD13: 675293.22 | AE13: 669067.36 | AF13: 6225.86 | AG13: 37680.63 | AH13: 36408.81 | AI13: 1271.82 | AJ13: 1549 | AK13: 1337 | AL13: 1294 | AM13: 43 | AN13: 212 | AO13: 212 | AP13: 0 | AQ13: 533811 | AR13: 477066 | AS13: 465421 | AT13: 11645 | AU13: 56745 | AV13: 48884 | AW13: 7861 | AX13: 88866 | AY13: 81428 | AZ13: 79952 | BA13: 1476 | BB13: 7438 | BC13: 6248 | BD13: 1190 | BE13: 2219264 | BF13: 1380058.1 | BG13: 1355565.2 | BH13: 24492.89 | BI13: 839205.92 | BJ13: 768403.55 | BK13: 70802.37 | BL13: 269274.98 | BM13: 189565.57 | BN13: 186354 | BO13: 3211.57 | BP13: 79709.41 | BQ13: 71308.74 | BR13: 8400.67 | BS13: 136421.79 | BT13: 76839.28 | BU13: 76330.96 | BV13: 508.32 | BW13: 59582.51 | BX13: 58132.31 | BY13: 1450.2 | BZ13: 740337 | CA13: 378704 | CB13: 376162 | CC13: 2542 | CD13: 361633 | CE13: 345654 | CF13: 15979 | CG13: 1073230.2 | CH13: 734949.25 | CI13: 716718.25 | CJ13: 18231 | CK13: 338281 | CL13: 293308.5 | CM13: 44972.5 | CN13: 0 | CO13: 1144695.1 | CP13: 162070.64 | CQ13: 5149.07 | CR13: 25285.01 | CS13: 0 | CT13: 0 | CU13: 0 | CV13: 3280 | CW13: 3003 | CX13: 2942 | CY13: 61 | CZ13: 277 | DA13: 228 | DB13: 49 | DC13: 2952 | DD13: 58 | DE13: 2710 | DF13: 2662 | DG13: 48 | DH13: 242 | DI13: 196 | DJ13: 46 | DK13: 241 | DL13: 212 | DM13: 209 | DN13: 3 | DO13: 29 | DP13: 28 | DQ13: 1 | DR13: 29 | DS13: 0 | DT13: 28 | DU13: 27 | DV13: 1 | DW13: 1 | DX13: 1 | DY13: 0 | DZ13: 0 | EA13: 0 | EB13: 0 | EC13: 0 | ED13: 0 | EE13: 0 | EF13: 0 | EG13: 112 | EH13: 67 | EI13: 65 | EJ13: 2 | EK13: 45 | EL13: 43 | EM13: 2 | EN13: 11 | EO13: 0 | EP13: 0 | EQ13: 11 | ER13: 0 | ES13: 0 | ET13: 0 | EU13: 0 | EV13: 0 | EW13: 0 | EX13: 0 | EY13: 0 | EZ13: 0 | FA13: 0 | FB13: 0
A14: 11 | B14: 成人手术 | C14: 普外科 | D14: 15156262 | E14: 2647631 | F14: 12508631 | G14: 11567 | H14: 1090 | I14: 185514 | J14: 136076 | K14: 45 | L14: 911564.25 | M14: 3927381.5 | N14: 2167.5 | O14: 30993485 | P14: 20694947 | Q14: 19903233 | R14: 791714.32 | S14: 10298539 | T14: 9972803.8 | U14: 325734.75 | V14: 4240925.1 | W14: 3345677 | X14: 3206041.5 | Y14: 139635.5 | Z14: 895248.1 | AA14: 676621.11 | AB14: 218626.99 | AC14: 1132111 | AD14: 848573.45 | AE14: 824101.82 | AF14: 24471.63 | AG14: 283537.55 | AH14: 240384.11 | AI14: 43153.44 | AJ14: 461183.11 | AK14: 406888.56 | AL14: 393337.69 | AM14: 13550.87 | AN14: 54294.55 | AO14: 38841 | AP14: 15453.55 | AQ14: 1910274 | AR14: 1475413 | AS14: 1405170 | AT14: 70243 | AU14: 434861 | AV14: 319090 | AW14: 115771 | AX14: 737357 | AY14: 614802 | AZ14: 583432 | BA14: 31370 | BB14: 122555 | BC14: 78306 | BD14: 44249 | BE14: 26752560 | BF14: 17349270 | BG14: 16697191 | BH14: 652078.82 | BI14: 9403290.5 | BJ14: 9296182.7 | BK14: 107107.76 | BL14: 4709261.8 | BM14: 2931038.4 | BN14: 2841117.9 | BO14: 89920.45 | BP14: 1778223.4 | BQ14: 1756727.6 | BR14: 21495.84 | BS14: 9534667.3 | BT14: 6359459 | BU14: 6161297.7 | BV14: 198161.37 | BW14: 3175208.3 | BX14: 3139946.1 | BY14: 35262.17 | BZ14: 4526843 | CA14: 2707625 | CB14: 2621419 | CC14: 86206 | CD14: 1819218 | CE14: 1796747 | CF14: 22471 | CG14: 7981788.2 | CH14: 5351147.5 | CI14: 5073356.5 | CJ14: 277791 | CK14: 2630640.8 | CL14: 2602762 | CM14: 27878.75 | CN14: 1147547.2 | CO14: 1449234.1 | CP14: 1027895.6 | CQ14: 533761.7 | CR14: 82536.51 | CS14: 0 | CT14: 260282.86 | CU14: 0 | CV14: 11567 | CW14: 9553 | CX14: 9098 | CY14: 455 | CZ14: 2014 | DA14: 1402 | DB14: 612 | DC14: 5646 | DD14: 23 | DE14: 4799 | DF14: 4559 | DG14: 240 | DH14: 847 | DI14: 585 | DJ14: 262 | DK14: 3010 | DL14: 2365 | DM14: 2261 | DN14: 104 | DO14: 645 | DP14: 454 | DQ14: 191 | DR14: 122 | DS14: 0 | DT14: 83 | DU14: 75 | DV14: 8 | DW14: 39 | DX14: 24 | DY14: 15 | DZ14: 2766 | EA14: 2285 | EB14: 2182 | EC14: 103 | ED14: 481 | EE14: 339 | EF14: 142 | EG14: 1090 | EH14: 750 | EI14: 721 | EJ14: 29 | EK14: 340 | EL14: 337 | EM14: 3 | EN14: 948 | EO14: 719 | EP14: 0 | EQ14: 229 | ER14: 409 | ES14: 0 | ET14: 0 | EU14: 288 | EV14: 234 | EW14: 0 | EX14: 54 | EY14: 201 | EZ14: 201 | FA14: 0 | FB14: 391
A15: 12 | B15: 成人手术 | C15: 神经外科 | D15: 9739809.2 | E15: 546218 | F15: 9193591.2 | G15: 2789 | H15: 588 | I15: 316 | J15: 0 | K15: 0 | L15: 666722.5 | M15: 2726276.2 | N15: 0 | O15: 36575367 | P15: 19813626 | Q15: 18934585 | R15: 879041.01 | S15: 16761741 | T15: 16654070 | U15: 107670.99 | V15: 851805.58 | W15: 677847.95 | X15: 621501.24 | Y15: 56346.71 | Z15: 173957.63 | AA15: 112742.8 | AB15: 61214.83 | AC15: 295413.58 | AD15: 249778.95 | AE15: 234809.24 | AF15: 14969.71 | AG15: 45634.63 | AH15: 33994.8 | AI15: 11639.83 | AJ15: 10174 | AK15: 8411 | AL15: 7938 | AM15: 473 | AN15: 1763 | AO15: 989 | AP15: 774 | AQ15: 436952 | AR15: 348015 | AS15: 313922 | AT15: 34093 | AU15: 88937 | AV15: 54208 | AW15: 34729 | AX15: 109266 | AY15: 71643 | AZ15: 64832 | BA15: 6811 | BB15: 37623 | BC15: 23551 | BD15: 14072 | BE15: 35723562 | BF15: 19135779 | BG15: 18313084 | BH15: 822694.3 | BI15: 16587783 | BJ15: 16541327 | BK15: 46456.16 | BL15: 3575350.8 | BM15: 1772766.7 | BN15: 1660095.6 | BO15: 112671.08 | BP15: 1802584.1 | BQ15: 1800882.9 | BR15: 1701.18 | BS15: 22954619 | BT15: 13012275 | BU15: 12619669 | BV15: 392605.97 | BW15: 9942344.7 | BX15: 9921519.7 | BY15: 20824.98 | BZ15: 3570783 | CA15: 1728856 | CB15: 1626190 | CC15: 102666 | CD15: 1841927 | CE15: 1839054 | CF15: 2873 | CG15: 5622808.2 | CH15: 2621881 | CI15: 2407129.8 | CJ15: 214751.25 | CK15: 3000927.2 | CL15: 2979870.2 | CM15: 21057 | CN15: 0 | CO15: 470210.91 | CP15: 307264.94 | CQ15: 48518.82 | CR15: 25810.91 | CS15: 0 | CT15: 216953.1 | CU15: 0 | CV15: 2789 | CW15: 2083 | CX15: 1891 | CY15: 192 | CZ15: 706 | DA15: 438 | DB15: 268 | DC15: 1580 | DD15: 16 | DE15: 1303 | DF15: 1178 | DG15: 125 | DH15: 277 | DI15: 167 | DJ15: 110 | DK15: 1133 | DL15: 753 | DM15: 689 | DN15: 64 | DO15: 380 | DP15: 241 | DQ15: 139 | DR15: 60 | DS15: 0 | DT15: 13 | DU15: 11 | DV15: 2 | DW15: 47 | DX15: 30 | DY15: 17 | DZ15: 0 | EA15: 0 | EB15: 0 | EC15: 0 | ED15: 0 | EE15: 0 | EF15: 0 | EG15: 588 | EH15: 316 | EI15: 296 | EJ15: 20 | EK15: 272 | EL15: 270 | EM15: 2 | EN15: 526 | EO15: 225 | EP15: 191 | EQ15: 110 | ER15: 107 | ES15: 0 | ET15: 0 | EU15: 96 | EV15: 71 | EW15: 10 | EX15: 15 | EY15: 291 | EZ15: 110 | FA15: 181 | FB15: 219
... A66: 63 | B66: 其他 | C66: 临床药物试验办公室GCP | D66: 49322 | E66: 49322 | F66: 0 | G66: 132 | H66: 0 | I66: 40 | J66: 0 | K66: 0 | L66: 0 | M66: 0 | N66: 0 | O66: 49354 | P66: 12650 | Q66: 0 | R66: 12650 | S66: 36704 | T66: 0 | U66: 36704 | V66: 49354 | W66: 12650 | X66: 0 | Y66: 12650 | Z66: 36704 | AA66: 0 | AB66: 36704 | AC66: 0 | AD66: 0 | AE66: 0 | AF66: 0 | AG66: 0 | AH66: 0 | AI66: 0 | AJ66: 32 | AK66: 0 | AL66: 0 | AM66: 0 | AN66: 32 | AO66: 0 | AP66: 32 | AQ66: 45982 | AR66: 10900 | AS66: 0 | AT66: 10900 | AU66: 35082 | AV66: 0 | AW66: 35082 | AX66: 3340 | AY66: 1750 | AZ66: 0 | BA66: 1750 | BB66: 1590 | BC66: 0 | BD66: 1590 | BE66: 0 | BF66: 0 | BG66: 0 | BH66: 0 | BI66: 0 | BJ66: 0 | BK66: 0 | BL66: 0 | BM66: 0 | BN66: 0 | BO66: 0 | BP66: 0 | BQ66: 0 | BR66: 0 | BS66: 0 | BT66: 0 | BU66: 0 | BV66: 0 | BW66: 0 | BX66: 0 | BY66: 0 | BZ66: 0 | CA66: 0 | CB66: 0 | CC66: 0 | CD66: 0 | CE66: 0 | CF66: 0 | CG66: 0 | CH66: 0 | CI66: 0 | CJ66: 0 | CK66: 0 | CL66: 0 | CM66: 0 | CN66: 0 | CO66: 0 | CP66: 0 | CQ66: 49354 | CR66: 0 | CS66: 0 | CT66: 0 | CU66: 0 | CV66: 132 | CW66: 70 | CX66: 0 | CY66: 70 | CZ66: 62 | DA66: 0 | DB66: 62 | DC66: 132 | DD66: 0 | DE66: 70 | DF66: 0 | DG66: 70 | DH66: 62 | DI66: 0 | DJ66: 62 | DK66: 0 | DL66: 0 | DM66: 0 | DN66: 0 | DO66: 0 | DP66: 0 | DQ66: 0 | DR66: 0 | DS66: 0 | DT66: 0 | DU66: 0 | DV66: 0 | DW66: 0 | DX66: 0 | DY66: 0 | DZ66: 0 | EA66: 0 | EB66: 0 | EC66: 0 | ED66: 0 | EE66: 0 | EF66: 0 | EG66: 0 | EH66: 0 | EI66: 0 | EJ66: 0 | EK66: 0 | EL66: 0 | EM66: 0 | EN66: 0 | EO66: 0 | EP66: 0 | EQ66: 0 | ER66: 0 | ES66: 0 | ET66: 0 | EU66: 0 | EV66: 0 | EW66: 0 | EX66: 0 | EY66: 0 | EZ66: 0 | FA66: 0 | FB66: 0
A67: 64 | C67: 其它 | D67: 0 | E67: 0 | F67: 0 | G67: 151 | H67: 25 | I67: 0 | J67: 0 | K67: 0 | L67: 0 | M67: 0 | N67: 0 | O67: 461875.28 | P67: 375685.16 | Q67: 292336.4 | R67: 83348.76 | S67: 86190.12 | T67: 60390.12 | U67: 25800 | V67: 0 | W67: 0 | X67: 0 | Y67: 0 | Z67: 0 | AA67: 0 | AB67: 0 | AC67: 0 | AD67: 0 | AE67: 0 | AF67: 0 | AG67: 0 | AH67: 0 | AI67: 0 | AJ67: 0 | AK67: 0 | AL67: 0 | AM67: 0 | AN67: 0 | AO67: 0 | AP67: 0 | AQ67: 0 | AR67: 0 | AS67: 0 | AT67: 0 | AU67: 0 | AV67: 0 | AW67: 0 | AX67: 0 | AY67: 0 | AZ67: 0 | BA67: 0 | BB67: 0 | BC67: 0 | BD67: 0 | BE67: 461875.28 | BF67: 375685.16 | BG67: 292336.4 | BH67: 83348.76 | BI67: 86190.12 | BJ67: 60390.12 | BK67: 25800 | BL67: 0 | BM67: 0 | BN67: 0 | BO67: 0 | BP67: 0 | BQ67: 0 | BR67: 0 | BS67: 461875.28 | BT67: 375685.16 | BU67: 292336.4 | BV67: 83348.76 | BW67: 86190.12 | BX67: 60390.12 | BY67: 25800 | BZ67: 0 | CA67: 0 | CB67: 0 | CC67: 0 | CD67: 0 | CE67: 0 | CF67: 0 | CG67: 0 | CH67: 0 | CI67: 0 | CJ67: 0 | CK67: 0 | CL67: 0 | CM67: 0 | CN67: 0 | CO67: 0 | CP67: 0 | CQ67: 0 | CR67: 0 | CS67: 0 | CT67: 103200 | CU67: 0 | CV67: 151 | CW67: 34 | CX67: 0 | CY67: 34 | CZ67: 117 | DA67: 0 | DB67: 117 | DC67: 151 | DD67: 0 | DE67: 34 | DF67: 0 | DG67: 34 | DH67: 117 | DI67: 0 | DJ67: 117 | DK67: 0 | DL67: 0 | DM67: 0 | DN67: 0 | DO67: 0 | DP67: 0 | DQ67: 0 | DR67: 0 | DS67: 0 | DT67: 0 | DU67: 0 | DV67: 0 | DW67: 0 | DX67: 0 | DY67: 0 | DZ67: 0 | EA67: 0 | EB67: 0 | EC67: 0 | ED67: 0 | EE67: 0 | EF67: 0 | EG67: 25 | EH67: 8 | EI67: 2 | EJ67: 6 | EK67: 17 | EL67: 15 | EM67: 2 | EN67: 1 | EO67: 1 | EP67: 0 | EQ67: 0 | ER67: 0 | ES67: 0 | ET67: 0 | EU67: 0 | EV67: 0 | EW67: 0 | EX67: 0 | EY67: 0 | EZ67: 0 | FA67: 0 | FB67: 0

Sheet 当年累计数据表奉贤
A1: 日期范围：20260501-20260531 | D1: 25 | O1: 1=2+5=8+43 | P1: 2=3+4 | Q1: 3 | R1: 4 | S1: 5=6+7 | T1: 6 | U1: 7 | V1: 8=9+12=15+22+29+36 | W1: 9=10+11 | X1: 10 | Y1: 11 | Z1: 12=13+14 | AA1: 13 | AB1: 14 | AC1: 15=16+19 | AD1: 16=17+18 | AE1: 17 | AF1: 18 | AG1: 19=20+21 | AH1: 20 | AI1: 21 | AJ1: 22=23+26 | AK1: 23=24+25 | AL1: 24 | AM1: 25 | AN1: 26=27+28 | AO1: 27 | AP1: 28 | AQ1: 29=30+33 | AR1: 30=31+32 | AS1: 31 | AT1: 32 | AU1: 33=34+35 | AV1: 34 | AW1: 35 | AX1: 36=37+40 | AY1: 37=38+39 | AZ1: 38 | BA1: 39 | BB1: 40=41+42 | BC1: 41 | BD1: 42 | BE1: 43=50+57+64+71=44+47 | BF1: 44=45+46 | BG1: 45 | BH1: 46 | BI1: 47=48+49 | BJ1: 48 | BK1: 49 | BL1: 50=51+54 | BM1: 51=52+53 | BN1: 52 | BO1: 53 | BP1: 54=55+56 | BQ1: 55 | BR1: 56 | BS1: 57=58+61 | BT1: 58=59+60 | BU1: 59 | BV1: 60 | BW1: 61=62+63 | BX1: 62 | BY1: 63 | BZ1: 64=65+68 | CA1: 65=66+67 | CB1: 66 | CC1: 67 | CD1: 68=69+70 | CE1: 69 | CF1: 70 | CG1: 71=72+75 | CH1: 72=73+74 | CI1: 73 | CJ1: 74 | CK1: 75=76+77 | CL1: 76 | CM1: 77 | CV1: 78=85+93+100+108+86+101=79+82 | CW1: 79=80+81 | CX1: 80 | CY1: 81 | CZ1: 82=83+84 | DA1: 83 | DB1: 84 | DC1: 85=87+90=78-93-100-108-86-101 | DD1: 86 | DE1: 87=88+89 | DF1: 88 | DG1: 89 | DH1: 90=91+92 | DI1: 91 | DJ1: 92 | DK1: 93=94+97 | DL1: 94=95+96 | DM1: 95 | DN1: 96 | DO1: 97=98+99 | DP1: 98 | DQ1: 99 | DR1: 100=102+105 | DS1: 101 | DT1: 102=103+104 | DU1: 103 | DV1: 104 | DW1: 105=106+107 | DX1: 106 | DY1: 107 | DZ1: 108=109+112 | EA1: 109=110+111 | EB1: 110 | EC1: 111 | ED1: 112=113+114 | EE1: 113 | EF1: 114 | EG1: 115=116+119 | EH1: 116=117+118 | EI1: 117 | EJ1: 118 | EK1: 119=120+121 | EL1: 120 | EM1: 121 | EN1: 122=123+124+125 | EO1: 123 | EP1: 124 | EQ1: 125 | EU1: 126=127+128+129 | EV1: 127 | EW1: 128 | EX1: 129 | EY1: 130=131+132 | EZ1: 131 | FA1: 132 | FB1: 133
A2: 序号 | B2: 科室类别 | C2: 科室名称 | D2: 医疗收入不含药耗 | E2: 门急诊收入不含药耗 | F2: 住院收入不含药耗 | G2: 门急诊人次 | H2: 住院人次 | I2: 门急诊治疗收入 | J2: 门急诊手术收入 | K2: 门诊中药饮片收入 | L2: 住院治疗收入 | M2: 住院手术收入 | N2: 住院中药饮片收入 | O2: 医疗收入 | P2: 其中本地病人医疗收入 | Q2: 其中本地病人医保医疗收入 | R2: 其中本地病人自费医疗收入 | S2: 其中异地病人医疗收入 | T2: 其中异地病人医保医疗收入 | U2: 其中异地病人自费医疗收入 | V2: 门急诊收入 | W2: 其中本地病人医疗收入 | X2: 其中本地病人医保医疗收入 | Y2: 其中本地病人自费医疗收入 | Z2: 其中异地病人医疗收入 | AA2: 其中异地病人医保医疗收入 | AB2: 其中异地病人自费医疗收入 | AC2: 门急诊药品收入 | AD2: 其中本地病人医疗收入 | AE2: 其中本地病人医保医疗收入 | AF2: 其中本地病人自费医疗收入 | AG2: 其中异地病人医疗收入 | AH2: 其中异地病人医保医疗收入 | AI2: 其中异地病人自费医疗收入 | AJ2: 门急诊耗材收入 | AK2: 其中本地病人医疗收入 | AL2: 其中本地病人医保医疗收入 | AM2: 其中本地病人自费医疗收入 | AN2: 其中异地病人医疗收入 | AO2: 其中异地病人医保医疗收入 | AP2: 其中异地病人自费医疗收入 | AQ2: 门急诊检查化验收入 | AR2: 其中本地病人医疗收入 | AS2: 其中本地病人医保医疗收入 | AT2: 其中本地病人自费医疗收入 | AU2: 其中异地病人医疗收入 | AV2: 其中异地病人医保医疗收入 | AW2: 其中异地病人自费医疗收入 | AX2: 门急诊劳务收入 | AY2: 其中本地病人医疗收入 | AZ2: 其中本地病人医保医疗收入 | BA2: 其中本地病人自费医疗收入 | BB2: 其中异地病人医疗收入 | BC2: 其中异地病人医保医疗收入 | BD2: 其中异地病人自费医疗收入 | BE2: 住院收入 | BF2: 其中本地病人医疗收入 | BG2: 其中本地病人医保医疗收入 | BH2: 其中本地病人自费医疗收入 | BI2: 其中异地病人医疗收入 | BJ2: 其中异地病人医保医疗收入 | BK2: 其中异地病人自费医疗收入 | BL2: 住院药品收入 | BM2: 其中本地病人医疗收入 | BN2: 其中本地病人医保医疗收入 | BO2: 其中本地病人自费医疗收入 | BP2: 其中异地病人医疗收入 | BQ2: 其中异地病人医保医疗收入 | BR2: 其中异地病人自费医疗收入 | BS2: 住院耗材收入 | BT2: 其中本地病人医疗收入 | BU2: 其中本地病人医保医疗收入 | BV2: 其中本地病人自费医疗收入 | BW2: 其中异地病人医疗收入 | BX2: 其中异地病人医保医疗收入 | BY2: 其中异地病人自费医疗收入 | BZ2: 住院检查化验收入 | CA2: 其中本地病人医疗收入 | CB2: 其中本地病人医保医疗收入 | CC2: 其中本地病人自费医疗收入 | CD2: 其中异地病人医疗收入 | CE2: 其中异地病人医保医疗收入 | CF2: 其中异地病人自费医疗收入 | CG2: 住院劳务收入 | CH2: 其中本地病人医疗收入 | CI2: 其中本地病人医保医疗收入 | CJ2: 其中本地病人自费医疗收入 | CK2: 其中异地病人医疗收入 | CL2: 其中异地病人医保医疗收入 | CM2: 其中异地病人自费医疗收入 | CN2: 急诊收入 | CO2: 普通门诊收入 | CP2: 专家门诊收入 | CQ2: 专病门诊收入 | CR2: 特需门诊收入 | CS2: MDT门诊收入 | CT2: 镜朗诊疗部收入 | CU2: 特需病房收入 | CV2: 门急诊人次 | CW2: 其中本地病人人次 | CX2: 其中本地病人医保人次 | CY2: 其中本地病人自费人次 | CZ2: 其中异地病人人次 | DA2: 其中异地病人医保人次 | DB2: 其中异地病人自费人次 | DC2: 普通门诊 (普通+专病) | DD2: 互联网普通门诊人次 | DE2: 其中本地病人人次 | DF2: 其中本地病人医保人次 | DG2: 其中本地病人自费人次 | DH2: 其中异地病人人次 | DI2: 其中异地病人医保人次 | DJ2: 其中异地病人自费人次 | DK2: 专家门诊 | DL2: 其中本地病人人次 | DM2: 其中本地病人医保人次 | DN2: 其中本地病人自费人次 | DO2: 其中异地病人人次 | DP2: 其中异地病人医保人次 | DQ2: 其中异地病人自费人次 | DR2: 特需门诊 (特需+MDT) | DS2: 互联网特需门诊人次 | DT2: 其中本地病人人次 | DU2: 其中本地病人医保人次 | DV2: 其中本地病人自费人次 | DW2: 其中异地病人人次 | DX2: 其中异地病人医保人次 | DY2: 其中异地病人自费人次 | DZ2: 急诊人次 | EA2: 其中本地病人人次 | EB2: 其中本地病人医保人次 | EC2: 其中本地病人自费人次 | ED2: 其中异地病人人次 | EE2: 其中异地病人医保人次 | EF2: 其中异地病人自费人次 | EG2: 住院人次 | EH2: 其中本地病人人次 | EI2: 其中本地病人医保人次 | EJ2: 其中本地病人自费人次 | EK2: 其中异地病人人次 | EL2: 其中异地病人医保人次 | EM2: 其中异地病人自费人次 | EN2: 手术人次与操作人次 | EO2: 手术人次 | EP2: 介入人次 | EQ2: 操作人次(治疗+诊断) | ER2: 微创手术人次（手术） | ES2: 微创手术人次（介入） | ET2: 微创手术人次（操作） | EU2: 三级手术 | EV2: 三级手术(手术) | EW2: 三级手术(介入) | EX2: 三级手术(操作) | EY2: 四级手术 | EZ2: 四级手术(手术) | FA2: 四级手术(介入) | FB2: 重点病种人次
A3: 小计： | D3: 62648278 | E3: 25025509 | F3: 37622769 | G3: 95116 | H3: 3578 | I3: 3560692.2 | J3: 1219717.8 | K3: 448212.16 | L3: 2720225 | M3: 10946942 | N3: 4343.17 | O3: 1.4263148e+08 | P3: 1.0429655e+08 | Q3: 96341160 | R3: 7955391.7 | S3: 38334926 | T3: 35898735 | U3: 2436191.3 | V3: 41796775 | W3: 35927381 | X3: 32801690 | Y3: 3125690.8 | Z3: 5869393.7 | AA3: 3750504.2 | AB3: 2118889.4 | AC3: 14746208 | AD3: 12946543 | AE3: 12221683 | AF3: 724859.66 | AG3: 1799665 | AH3: 1326873.9 | AI3: 472791.15 | AJ3: 2025058.1 | AK3: 1782756 | AL3: 1462999.4 | AM3: 319756.63 | AN3: 242302.15 | AO3: 142095.37 | AP3: 100206.78 | AQ3: 16440181 | AR3: 13998399 | AS3: 12777987 | AT3: 1220412 | AU3: 2441782 | AV3: 1538162 | AW3: 903620 | AX3: 8585328 | AY3: 7199683.5 | AZ3: 6339021 | BA3: 860662.55 | BB3: 1385644.5 | BC3: 743373 | BD3: 642271.5 | BE3: 1.008347e+08 | BF3: 68369171 | BG3: 63539470 | BH3: 4829700.8 | BI3: 32465532 | BJ3: 32148231 | BK3: 317301.85 | BL3: 11466479 | BM3: 6677764.3 | BN3: 6228071.7 | BO3: 449692.63 | BP3: 4788714.9 | BQ3: 4711439.6 | BR3: 77275.3 | BS3: 51745455 | BT3: 35931529 | BU3: 33315333 | BV3: 2616195.8 | BW3: 15813926 | BX3: 15707976 | BY3: 105950.05 | BZ3: 15170809 | CA3: 10335539 | CB3: 9792617.5 | CC3: 542921.5 | CD3: 4835270 | CE3: 4765515 | CF3: 69755 | CG3: 22451960 | CH3: 15424339 | CI3: 14203448 | CJ3: 1220890.9 | CK3: 7027621.4 | CL3: 6963299.9 | CM3: 64321.5 | CN3: 9309038.3 | CO3: 14403938 | CP3: 11553205 | CQ3: 4798578.3 | CR3: 1729731.6 | CS3: 1848 | CT3: 246911.2 | CU3: 0 | CV3: 95116 | CW3: 81739 | CX3: 73571 | CY3: 8168 | CZ3: 13377 | DA3: 7850 | DB3: 5527 | DC3: 47744 | DD3: 0 | DE3: 41468 | DF3: 37712 | DG3: 3756 | DH3: 6276 | DI3: 3566 | DJ3: 2710 | DK3: 24947 | DL3: 20818 | DM3: 18744 | DN3: 2074 | DO3: 4129 | DP3: 2480 | DQ3: 1649 | DR3: 2513 | DS3: 0 | DT3: 1983 | DU3: 1745 | DV3: 238 | DW3: 530 | DX3: 276 | DY3: 254 | DZ3: 19912 | EA3: 17470 | EB3: 15370 | EC3: 2100 | ED3: 2442 | EE3: 1528 | EF3: 914 | EG3: 3578 | EH3: 2523 | EI3: 2342 | EJ3: 181 | EK3: 1055 | EL3: 1036 | EM3: 19 | EN3: 2970 | EO3: 1789 | EP3: 310 | EQ3: 871 | ER3: 503 | ES3: 0 | ET3: 38 | EU3: 939 | EV3: 749 | EW3: 151 | EX3: 39 | EY3: 622 | EZ3: 518 | FA3: 104 | FB3: 1260
A4: 1 | B4: 成人非手术 | C4: 内科 | D4: 0 | E4: 0 | F4: 0 | G4: 31 | H4: 0 | I4: 0 | J4: 0 | K4: 0 | L4: 0 | M4: 0 | N4: 0 | O4: 0 | P4: 0 | Q4: 0 | R4: 0 | S4: 0 | T4: 0 | U4: 0 | V4: 0 | W4: 0 | X4: 0 | Y4: 0 | Z4: 0 | AA4: 0 | AB4: 0 | AC4: 0 | AD4: 0 | AE4: 0 | AF4: 0 | AG4: 0 | AH4: 0 | AI4: 0 | AJ4: 0 | AK4: 0 | AL4: 0 | AM4: 0 | AN4: 0 | AO4: 0 | AP4: 0 | AQ4: 0 | AR4: 0 | AS4: 0 | AT4: 0 | AU4: 0 | AV4: 0 | AW4: 0 | AX4: 0 | AY4: 0 | AZ4: 0 | BA4: 0 | BB4: 0 | BC4: 0 | BD4: 0 | BE4: 0 | BF4: 0 | BG4: 0 | BH4: 0 | BI4: 0 | BJ4: 0 | BK4: 0 | BL4: 0 | BM4: 0 | BN4: 0 | BO4: 0 | BP4: 0 | BQ4: 0 | BR4: 0 | BS4: 0 | BT4: 0 | BU4: 0 | BV4: 0 | BW4: 0 | BX4: 0 | BY4: 0 | BZ4: 0 | CA4: 0 | CB4: 0 | CC4: 0 | CD4: 0 | CE4: 0 | CF4: 0 | CG4: 0 | CH4: 0 | CI4: 0 | CJ4: 0 | CK4: 0 | CL4: 0 | CM4: 0 | CN4: 0 | CO4: 0 | CP4: 0 | CQ4: 0 | CR4: 0 | CS4: 0 | CT4: 0 | CU4: 0 | CV4: 31 | CW4: 23 | CX4: 22 | CY4: 1 | CZ4: 8 | DA4: 8 | DB4: 0 | DC4: 31 | DD4: 0 | DE4: 23 | DF4: 22 | DG4: 1 | DH4: 8 | DI4: 8 | DJ4: 0 | DK4: 0 | DL4: 0 | DM4: 0 | DN4: 0 | DO4: 0 | DP4: 0 | DQ4: 0 | DR4: 0 | DS4: 0 | DT4: 0 | DU4: 0 | DV4: 0 | DW4: 0 | DX4: 0 | DY4: 0 | DZ4: 0 | EA4: 0 | EB4: 0 | EC4: 0 | ED4: 0 | EE4: 0 | EF4: 0 | EG4: 0 | EH4: 0 | EI4: 0 | EJ4: 0 | EK4: 0 | EL4: 0 | EM4: 0 | EN4: 0 | EO4: 0 | EP4: 0 | EQ4: 0 | ER4: 0 | ES4: 0 | ET4: 0 | EU4: 0 | EV4: 0 | EW4: 0 | EX4: 0 | EY4: 0 | EZ4: 0 | FA4: 0 | FB4: 0
A5: 2 | B5: 成人非手术 | C5: 呼吸内科 | D5: 1492087.5 | E5: 729483 | F5: 762604.5 | G5: 2861 | H5: 66 | I5: 72 | J5: 0 | K5: 0 | L5: 31050 | M5: 198 | N5: 0 | O5: 2443922 | P5: 1900866.8 | Q5: 1825747.1 | R5: 75119.7 | S5: 543055.21 | T5: 490756.03 | U5: 52299.18 | V5: 1285888.1 | W5: 1134877.4 | X5: 1082651.9 | Y5: 52225.49 | Z5: 151010.63 | AA5: 98711.45 | AB5: 52299.18 | AC5: 538467.06 | AD5: 482354.43 | AE5: 464227.94 | AF5: 18126.49 | AG5: 56112.63 | AH5: 37531.45 | AI5: 18581.18 | AJ5: 17938 | AK5: 15387 | AL5: 14470 | AM5: 917 | AN5: 2551 | AO5: 1634 | AP5: 917 | AQ5: 641094 | AR5: 560451 | AS5: 531983 | AT5: 28468 | AU5: 80643 | AV5: 51729 | AW5: 28914 | AX5: 88389 | AY5: 76685 | AZ5: 71971 | BA5: 4714 | BB5: 11704 | BC5: 7817 | BD5: 3887 | BE5: 1158034 | BF5: 765989.4 | BG5: 743095.19 | BH5: 22894.21 | BI5: 392044.58 | BJ5: 392044.58 | BK5: 0 | BL5: 329564.42 | BM5: 231209.41 | BN5: 221831.51 | BO5: 9377.9 | BP5: 98355.01 | BQ5: 98355.01 | BR5: 0 | BS5: 65865.06 | BT5: 39661.99 | BU5: 39171.18 | BV5: 490.81 | BW5: 26203.07 | BX5: 26203.07 | BY5: 0 | BZ5: 552040 | CA5: 347870 | CB5: 342748 | CC5: 5122 | CD5: 204170 | CE5: 204170 | CF5: 0 | CG5: 210564.5 | CH5: 147248 | CI5: 139344.5 | CJ5: 7903.5 | CK5: 63316.5 | CL5: 63316.5 | CM5: 0 | CN5: -75 | CO5: 1013880.6 | CP5: 250795.93 | CQ5: 0 | CR5: 21211.5 | CS5: 0 | CT5: 0 | CU5: 0 | CV5: 2861 | CW5: 2487 | CX5: 2341 | CY5: 146 | CZ5: 374 | DA5: 242 | DB5: 132 | DC5: 2304 | DD5: 0 | DE5: 2009 | DF5: 1897 | DG5: 112 | DH5: 295 | DI5: 191 | DJ5: 104 | DK5: 505 | DL5: 433 | DM5: 403 | DN5: 30 | DO5: 72 | DP5: 44 | DQ5: 28 | DR5: 52 | DS5: 0 | DT5: 45 | DU5: 41 | DV5: 4 | DW5: 7 | DX5: 7 | DY5: 0 | DZ5: 0 | EA5: 0 | EB5: 0 | EC5: 0 | ED5: 0 | EE5: 0 | EF5: 0 | EG5: 66 | EH5: 47 | EI5: 46 | EJ5: 1 | EK5: 19 | EL5: 19 | EM5: 0 | EN5: 34 | EO5: 0 | EP5: 0 | EQ5: 34 | ER5: 0 | ES5: 0 | ET5: 0 | EU5: 0 | EV5: 0 | EW5: 0 | EX5: 0 | EY5: 0 | EZ5: 0 | FA5: 0 | FB5: 29
